Workbook
Name Print_ALL_OFFAL: "Template!A643:X648"
Name Print_BEEF: "Template!A64:X146"
Name Print_BILT_DROEWORS_BUY_IN: "Template!A611:X641"
Name Print_BILT_DROEWORS_OWN: "Template!A422:X429"
Name Print_BULK_BRAAI_PACK_HAMPERS: "Template!A583:X589"
Name Print_BUTCH_WORS_MINCE_PAT: "Template!A449:X550"
Name Print_BUTCH_WORS_MINCE_PAT_2: "Template!A682:X686"
Name Print_BUTCHERY: "Template!A4:X62"
Name Print_BUTCHERY_CHICKENS: "Template!A148:X155"
Name Print_BUTCHERY_OSTRICH: "Template!A431:X438"
Name Print_BUTCHERY_SNOEK: "Template!A440:X447"
Name Print_BUTCHERY_SPICE: "Template!A552:X581"
Name Print_CHICKEN_FRESH: "Template!A688:X783"
Name Print_CHICKEN_FROZEN: "Template!A605:X609"
Name Print_INGREDIENTS: "Template!A311:X414"
Name Print_INGREDIENTS_2: "Template!A656:X662"
Name Print_LAMB: "Template!A157:X189"
Name Print_MINCE_PATTIES: "Template!A591:X596"
Name Print_MUTTON: "Template!A191:X217"
Name Print_PET_MINCE_DROEWORS: "Template!A219:X227"
Name Print_PORK: "Template!A229:X309"
Name Print_PORK_2: "Template!A650:X654"
Name Print_SMOKED_CHICKEN: "Template!A416:X420"
Name Print_STEAK: "Template!A598:X603"
Name Print_SUB_DEPT_1132: "Template!A664:X668"
Name Print_SUB_DEPT_1143: "Template!A670:X674"
Name Print_SUB_DEPT_2327: "Template!A676:X680"
Name WeeksList: #REF!

Sheet Daily data
B1: Date | D1: 46055 | F1: 46056 | H1: 46057 | J1: 46058 | L1: 46059 | N1: 46060 | P1: 46061 | R1: 46062 | T1: 46063 | V1: 46064 | X1: 46065 | Z1: 46066 | AB1: 46067 | AD1: 46068 | AF1: 46069 | AH1: 46070 | AJ1: 46071 | AL1: 46072 | AN1: 46073 | AP1: 46074 | AR1: 46075 | AT1: 46076 | AV1: 46077 | AX1: 46078 | AZ1: 46079 | BB1: 46080 | BD1: 46081 | BF1: 46082 | BH1: 46083 | BJ1: 46084 | BL1: 46085 | BN1: 46086 | BP1: 46087 | BR1: 46088 | BT1: 46089 | BV1: 46090 | BX1: 46091 | BZ1: 46092 | CB1: 46093 | CD1: 46094 | CF1: 46095 | CH1: 46096 | CJ1: 46097 | CL1: 46098 | CN1: 46099 | CP1: 46100 | CR1: 46101 | CT1: 46102 | CV1: 46103 | CX1: 46104 | CZ1: 46105 | DB1: 46106 | DD1: 46107 | DF1: 46108 | DH1: 46109 | DJ1: 46110 | DL1: 46111 | DN1: 46112 | DP1: 46113 | DR1: 46114 | DT1: 46115 | DV1: 46116 | DX1: 46117 | DZ1: 46118 | EB1: 46119 | ED1: 46120 | EF1: 46121 | EH1: 46122 | EJ1: 46123 | EL1: 46124 | EN1: 46125 | EP1: 46126 | ER1: 46127 | ET1: 46128 | EV1: 46129 | EX1: 46130 | EZ1: 46131 | FB1: 46132 | FD1: 46133 | FF1: 46134 | FH1: 46135 | FJ1: 46136 | FL1: 46137 | FN1: 46138 | FP1: 46139 | FR1: 46140 | FT1: 46141 | FV1: 46142 | FX1: 46143 | FZ1: 46144 | GB1: 46145 | GD1: 46146 | GF1: 46147 | GH1: 46148 | GJ1: 46149 | GL1: 46150 | GN1: 46151 | GP1: 46152
B2: Week | D2: 6 | F2: 6 | H2: 6 | J2: 6 | L2: 6 | N2: 6 | P2: 6 | R2: =WEEKNUM(R1,21) -> 7 | T2: =WEEKNUM(T1,21) -> 7 | V2: =WEEKNUM(V1,21) -> 7 | X2: =WEEKNUM(X1,21) -> 7 | Z2: =WEEKNUM(Z1,21) -> 7 | AB2: =WEEKNUM(AB1,21) -> 7 | AD2: =WEEKNUM(AD1,21) -> 7 | AF2: =WEEKNUM(AF1,21) -> 8 | AH2: =WEEKNUM(AH1,21) -> 8 | AJ2: =WEEKNUM(AJ1,21) -> 8 | AL2: =WEEKNUM(AL1,21) -> 8 | AN2: =WEEKNUM(AN1,21) -> 8 | AP2: =WEEKNUM(AP1,21) -> 8 | AR2: =WEEKNUM(AR1,21) -> 8 | AT2: =WEEKNUM(AT1,21) -> 9 | AV2: =WEEKNUM(AV1,21) -> 9 | AX2: =WEEKNUM(AX1,21) -> 9 | AZ2: =WEEKNUM(AZ1,21) -> 9 | BB2: =WEEKNUM(BB1,21) -> 9 | BD2: =WEEKNUM(BD1,21) -> 9 | BF2: =WEEKNUM(BF1,21) -> 9 | BH2: =WEEKNUM(BH1,21) -> 10 | BJ2: =WEEKNUM(BJ1,21) -> 10 | BL2: =WEEKNUM(BL1,21) -> 10 | BN2: =WEEKNUM(BN1,21) -> 10 | BP2: =WEEKNUM(BP1,21) -> 10 | BR2: =WEEKNUM(BR1,21) -> 10 | BT2: =WEEKNUM(BT1,21) -> 10 | BV2: =WEEKNUM(BV1,21) -> 11 | BX2: =WEEKNUM(BX1,21) -> 11 | BZ2: =WEEKNUM(BZ1,21) -> 11 | CB2: =WEEKNUM(CB1,21) -> 11 | CD2: =WEEKNUM(CD1,21) -> 11 | CF2: =WEEKNUM(CF1,21) -> 11 | CH2: =WEEKNUM(CH1,21) -> 11 | CJ2: =WEEKNUM(CJ1,21) -> 12 | CL2: =WEEKNUM(CL1,21) -> 12 | CN2: =WEEKNUM(CN1,21) -> 12 | CP2: =WEEKNUM(CP1,21) -> 12 | CR2: =WEEKNUM(CR1,21) -> 12 | CT2: =WEEKNUM(CT1,21) -> 12 | CV2: =WEEKNUM(CV1,21) -> 12 | CX2: =WEEKNUM(CX1,21) -> 13 | CZ2: =WEEKNUM(CZ1,21) -> 13 | DB2: =WEEKNUM(DB1,21) -> 13 | DD2: =WEEKNUM(DD1,21) -> 13 | DF2: =WEEKNUM(DF1,21) -> 13 | DH2: =WEEKNUM(DH1,21) -> 13 | DJ2: =WEEKNUM(DJ1,21) -> 13 | DL2: =WEEKNUM(DL1,21) -> 14 | DN2: =WEEKNUM(DN1,21) -> 14 | DP2: =WEEKNUM(DP1,21) -> 14 | DR2: =WEEKNUM(DR1,21) -> 14 | DT2: =WEEKNUM(DT1,21) -> 14 | DV2: =WEEKNUM(DV1,21) -> 14 | DX2: =WEEKNUM(DX1,21) -> 14 | DZ2: =WEEKNUM(DZ1,21) -> 15 | EB2: =WEEKNUM(EB1,21) -> 15 | ED2: =WEEKNUM(ED1,21) -> 15 | EF2: =WEEKNUM(EF1,21) -> 15 | EH2: =WEEKNUM(EH1,21) -> 15 | EJ2: =WEEKNUM(EJ1,21) -> 15 | EL2: =WEEKNUM(EL1,21) -> 15 | EN2: =WEEKNUM(EN1,21) -> 16 | EP2: =WEEKNUM(EP1,21) -> 16 | ER2: =WEEKNUM(ER1,21) -> 16 | ET2: =WEEKNUM(ET1,21) -> 16 | EV2: =WEEKNUM(EV1,21) -> 16 | EX2: =WEEKNUM(EX1,21) -> 16 | EZ2: =WEEKNUM(EZ1,21) -> 16 | FB2: =WEEKNUM(FB1,21) -> 17 | FD2: =WEEKNUM(FD1,21) -> 17 | FF2: =WEEKNUM(FF1,21) -> 17 | FH2: =WEEKNUM(FH1,21) -> 17 | FJ2: =WEEKNUM(FJ1,21) -> 17 | FL2: =WEEKNUM(FL1,21) -> 17 | FN2: =WEEKNUM(FN1,21) -> 17 | FP2: =WEEKNUM(FP1,21) -> 18 | FR2: =WEEKNUM(FR1,21) -> 18 | FT2: =WEEKNUM(FT1,21) -> 18 | FV2: =WEEKNUM(FV1,21) -> 18 | FX2: =WEEKNUM(FX1,21) -> 18 | FZ2: =WEEKNUM(FZ1,21) -> 18 | GB2: =WEEKNUM(GB1,21) -> 18 | GD2: =WEEKNUM(GD1,21) -> 19 | GF2: =WEEKNUM(GF1,21) -> 19 | GH2: =WEEKNUM(GH1,21) -> 19 | GJ2: =WEEKNUM(GJ1,21) -> 19 | GL2: =WEEKNUM(GL1,21) -> 19 | GN2: =WEEKNUM(GN1,21) -> 19 | GP2: =WEEKNUM(GP1,21) -> 19
B3: Weekday | D3: Mo | F3: Tue | H3: We | J3: Thu | L3: Fri | N3: Sat | P3: Sun | R3: =CHOOSE(WEEKDAY(R1,2),"Mo","Tue","We","Thu","Fri","Sat","Sun") -> Mo | T3: =CHOOSE(WEEKDAY(T1,2),"Mo","Tue","We","Thu","Fri","Sat","Sun") -> Tue | V3: =CHOOSE(WEEKDAY(V1,2),"Mo","Tue","We","Thu","Fri","Sat","Sun") -> We | X3: =CHOOSE(WEEKDAY(X1,2),"Mo","Tue","We","Thu","Fri","Sat","Sun") -> Thu | Z3: =CHOOSE(WEEKDAY(Z1,2),"Mo","Tue","We","Thu","Fri","Sat","Sun") -> Fri | AB3: =CHOOSE(WEEKDAY(AB1,2),"Mo","Tue","We","Thu","Fri","Sat","Sun") -> Sat | AD3: =CHOOSE(WEEKDAY(AD1,2),"Mo","Tue","We","Thu","Fri","Sat","Sun") -> Sun | AF3: =CHOOSE(WEEKDAY(AF1,2),"Mo","Tue","We","Thu","Fri","Sat","Sun") -> Mo | AH3: =CHOOSE(WEEKDAY(AH1,2),"Mo","Tue","We","Thu","Fri","Sat","Sun") -> Tue | AJ3: =CHOOSE(WEEKDAY(AJ1,2),"Mo","Tue","We","Thu","Fri","Sat","Sun") -> We | AL3: =CHOOSE(WEEKDAY(AL1,2),"Mo","Tue","We","Thu","Fri","Sat","Sun") -> Thu | AN3: =CHOOSE(WEEKDAY(AN1,2),"Mo","Tue","We","Thu","Fri","Sat","Sun") -> Fri | AP3: =CHOOSE(WEEKDAY(AP1,2),"Mo","Tue","We","Thu","Fri","Sat","Sun") -> Sat | AR3: =CHOOSE(WEEKDAY(AR1,2),"Mo","Tue","We","Thu","Fri","Sat","Sun") -> Sun | AT3: =CHOOSE(WEEKDAY(AT1,2),"Mo","Tue","We","Thu","Fri","Sat","Sun") -> Mo | AV3: =CHOOSE(WEEKDAY(AV1,2),"Mo","Tue","We","Thu","Fri","Sat","Sun") -> Tue | AX3: =CHOOSE(WEEKDAY(AX1,2),"Mo","Tue","We","Thu","Fri","Sat","Sun") -> We | AZ3: =CHOOSE(WEEKDAY(AZ1,2),"Mo","Tue","We","Thu","Fri","Sat","Sun") -> Thu | BB3: =CHOOSE(WEEKDAY(BB1,2),"Mo","Tue","We","Thu","Fri","Sat","Sun") -> Fri | BD3: =CHOOSE(WEEKDAY(BD1,2),"Mo","Tue","We","Thu","Fri","Sat","Sun") -> Sat | BF3: =CHOOSE(WEEKDAY(BF1,2),"Mo","Tue","We","Thu","Fri","Sat","Sun") -> Sun | BH3: =CHOOSE(WEEKDAY(BH1,2),"Mo","Tue","We","Thu","Fri","Sat","Sun") -> Mo | BJ3: =CHOOSE(WEEKDAY(BJ1,2),"Mo","Tue","We","Thu","Fri","Sat","Sun") -> Tue | BL3: =CHOOSE(WEEKDAY(BL1,2),"Mo","Tue","We","Thu","Fri","Sat","Sun") -> We | BN3: =CHOOSE(WEEKDAY(BN1,2),"Mo","Tue","We","Thu","Fri","Sat","Sun") -> Thu | BP3: =CHOOSE(WEEKDAY(BP1,2),"Mo","Tue","We","Thu","Fri","Sat","Sun") -> Fri | BR3: =CHOOSE(WEEKDAY(BR1,2),"Mo","Tue","We","Thu","Fri","Sat","Sun") -> Sat | BT3: =CHOOSE(WEEKDAY(BT1,2),"Mo","Tue","We","Thu","Fri","Sat","Sun") -> Sun | BV3: =CHOOSE(WEEKDAY(BV1,2),"Mo","Tue","We","Thu","Fri","Sat","Sun") -> Mo | BX3: =CHOOSE(WEEKDAY(BX1,2),"Mo","Tue","We","Thu","Fri","Sat","Sun") -> Tue | BZ3: =CHOOSE(WEEKDAY(BZ1,2),"Mo","Tue","We","Thu","Fri","Sat","Sun") -> We | CB3: =CHOOSE(WEEKDAY(CB1,2),"Mo","Tue","We","Thu","Fri","Sat","Sun") -> Thu | CD3: =CHOOSE(WEEKDAY(CD1,2),"Mo","Tue","We","Thu","Fri","Sat","Sun") -> Fri | CF3: =CHOOSE(WEEKDAY(CF1,2),"Mo","Tue","We","Thu","Fri","Sat","Sun") -> Sat | CH3: =CHOOSE(WEEKDAY(CH1,2),"Mo","Tue","We","Thu","Fri","Sat","Sun") -> Sun | CJ3: =CHOOSE(WEEKDAY(CJ1,2),"Mo","Tue","We","Thu","Fri","Sat","Sun") -> Mo | CL3: =CHOOSE(WEEKDAY(CL1,2),"Mo","Tue","We","Thu","Fri","Sat","Sun") -> Tue | CN3: =CHOOSE(WEEKDAY(CN1,2),"Mo","Tue","We","Thu","Fri","Sat","Sun") -> We | CP3: =CHOOSE(WEEKDAY(CP1,2),"Mo","Tue","We","Thu","Fri","Sat","Sun") -> Thu | CR3: =CHOOSE(WEEKDAY(CR1,2),"Mo","Tue","We","Thu","Fri","Sat","Sun") -> Fri | CT3: =CHOOSE(WEEKDAY(CT1,2),"Mo","Tue","We","Thu","Fri","Sat","Sun") -> Sat | CV3: =CHOOSE(WEEKDAY(CV1,2),"Mo","Tue","We","Thu","Fri","Sat","Sun") -> Sun | CX3: =CHOOSE(WEEKDAY(CX1,2),"Mo","Tue","We","Thu","Fri","Sat","Sun") -> Mo | CZ3: =CHOOSE(WEEKDAY(CZ1,2),"Mo","Tue","We","Thu","Fri","Sat","Sun") -> Tue | DB3: =CHOOSE(WEEKDAY(DB1,2),"Mo","Tue","We","Thu","Fri","Sat","Sun") -> We | DD3: =CHOOSE(WEEKDAY(DD1,2),"Mo","Tue","We","Thu","Fri","Sat","Sun") -> Thu | DF3: =CHOOSE(WEEKDAY(DF1,2),"Mo","Tue","We","Thu","Fri","Sat","Sun") -> Fri | DH3: =CHOOSE(WEEKDAY(DH1,2),"Mo","Tue","We","Thu","Fri","Sat","Sun") -> Sat | DJ3: =CHOOSE(WEEKDAY(DJ1,2),"Mo","Tue","We","Thu","Fri","Sat","Sun") -> Sun | DL3: =CHOOSE(WEEKDAY(DL1,2),"Mo","Tue","We","Thu","Fri","Sat","Sun") -> Mo | DN3: =CHOOSE(WEEKDAY(DN1,2),"Mo","Tue","We","Thu","Fri","Sat","Sun") -> Tue | DP3: =CHOOSE(WEEKDAY(DP1,2),"Mo","Tue","We","Thu","Fri","Sat","Sun") -> We | DR3: =CHOOSE(WEEKDAY(DR1,2),"Mo","Tue","We","Thu","Fri","Sat","Sun") -> Thu | DT3: =CHOOSE(WEEKDAY(DT1,2),"Mo","Tue","We","Thu","Fri","Sat","Sun") -> Fri | DV3: =CHOOSE(WEEKDAY(DV1,2),"Mo","Tue","We","Thu","Fri","Sat","Sun") -> Sat | DX3: =CHOOSE(WEEKDAY(DX1,2),"Mo","Tue","We","Thu","Fri","Sat","Sun") -> Sun | DZ3: =CHOOSE(WEEKDAY(DZ1,2),"Mo","Tue","We","Thu","Fri","Sat","Sun") -> Mo | EB3: =CHOOSE(WEEKDAY(EB1,2),"Mo","Tue","We","Thu","Fri","Sat","Sun") -> Tue | ED3: =CHOOSE(WEEKDAY(ED1,2),"Mo","Tue","We","Thu","Fri","Sat","Sun") -> We | EF3: =CHOOSE(WEEKDAY(EF1,2),"Mo","Tue","We","Thu","Fri","Sat","Sun") -> Thu | EH3: =CHOOSE(WEEKDAY(EH1,2),"Mo","Tue","We","Thu","Fri","Sat","Sun") -> Fri | EJ3: =CHOOSE(WEEKDAY(EJ1,2),"Mo","Tue","We","Thu","Fri","Sat","Sun") -> Sat | EL3: =CHOOSE(WEEKDAY(EL1,2),"Mo","Tue","We","Thu","Fri","Sat","Sun") -> Sun | EN3: =CHOOSE(WEEKDAY(EN1,2),"Mo","Tue","We","Thu","Fri","Sat","Sun") -> Mo | EP3: =CHOOSE(WEEKDAY(EP1,2),"Mo","Tue","We","Thu","Fri","Sat","Sun") -> Tue | ER3: =CHOOSE(WEEKDAY(ER1,2),"Mo","Tue","We","Thu","Fri","Sat","Sun") -> We | ET3: =CHOOSE(WEEKDAY(ET1,2),"Mo","Tue","We","Thu","Fri","Sat","Sun") -> Thu | EV3: =CHOOSE(WEEKDAY(EV1,2),"Mo","Tue","We","Thu","Fri","Sat","Sun") -> Fri | EX3: =CHOOSE(WEEKDAY(EX1,2),"Mo","Tue","We","Thu","Fri","Sat","Sun") -> Sat | EZ3: =CHOOSE(WEEKDAY(EZ1,2),"Mo","Tue","We","Thu","Fri","Sat","Sun") -> Sun | FB3: =CHOOSE(WEEKDAY(FB1,2),"Mo","Tue","We","Thu","Fri","Sat","Sun") -> Mo | FD3: =CHOOSE(WEEKDAY(FD1,2),"Mo","Tue","We","Thu","Fri","Sat","Sun") -> Tue | FF3: =CHOOSE(WEEKDAY(FF1,2),"Mo","Tue","We","Thu","Fri","Sat","Sun") -> We | FH3: =CHOOSE(WEEKDAY(FH1,2),"Mo","Tue","We","Thu","Fri","Sat","Sun") -> Thu | FJ3: =CHOOSE(WEEKDAY(FJ1,2),"Mo","Tue","We","Thu","Fri","Sat","Sun") -> Fri | FL3: =CHOOSE(WEEKDAY(FL1,2),"Mo","Tue","We","Thu","Fri","Sat","Sun") -> Sat | FN3: =CHOOSE(WEEKDAY(FN1,2),"Mo","Tue","We","Thu","Fri","Sat","Sun") -> Sun | FP3: =CHOOSE(WEEKDAY(FP1,2),"Mo","Tue","We","Thu","Fri","Sat","Sun") -> Mo | FR3: =CHOOSE(WEEKDAY(FR1,2),"Mo","Tue","We","Thu","Fri","Sat","Sun") -> Tue | FT3: =CHOOSE(WEEKDAY(FT1,2),"Mo","Tue","We","Thu","Fri","Sat","Sun") -> We | FV3: =CHOOSE(WEEKDAY(FV1,2),"Mo","Tue","We","Thu","Fri","Sat","Sun") -> Thu | FX3: =CHOOSE(WEEKDAY(FX1,2),"Mo","Tue","We","Thu","Fri","Sat","Sun") -> Fri | FZ3: =CHOOSE(WEEKDAY(FZ1,2),"Mo","Tue","We","Thu","Fri","Sat","Sun") -> Sat | GB3: =CHOOSE(WEEKDAY(GB1,2),"Mo","Tue","We","Thu","Fri","Sat","Sun") -> Sun | GD3: =CHOOSE(WEEKDAY(GD1,2),"Mo","Tue","We","Thu","Fri","Sat","Sun") -> Mo | GF3: =CHOOSE(WEEKDAY(GF1,2),"Mo","Tue","We","Thu","Fri","Sat","Sun") -> Tue | GH3: =CHOOSE(WEEKDAY(GH1,2),"Mo","Tue","We","Thu","Fri","Sat","Sun") -> We | GJ3: =CHOOSE(WEEKDAY(GJ1,2),"Mo","Tue","We","Thu","Fri","Sat","Sun") -> Thu | GL3: =CHOOSE(WEEKDAY(GL1,2),"Mo","Tue","We","Thu","Fri","Sat","Sun") -> Fri | GN3: =CHOOSE(WEEKDAY(GN1,2),"Mo","Tue","We","Thu","Fri","Sat","Sun") -> Sat | GP3: =CHOOSE(WEEKDAY(GP1,2),"Mo","Tue","We","Thu","Fri","Sat","Sun") -> Sun
A4: Sub-Department | B4: Product Description | C4: Department | D4: Sales Excl | E4: QTY | F4: Sales Excl | G4: QTY | H4: Sales Excl | I4: QTY | J4: Sales Excl | K4: QTY | L4: Sales Excl | M4: QTY | N4: Sales Excl | O4: QTY | P4: Sales Excl | Q4: QTY | R4: Sales Excl | S4: QTY | T4: Sales Excl | U4: QTY | V4: Sales Excl | W4: QTY | X4: Sales Excl | Y4: QTY | Z4: Sales Excl | AA4: QTY | AB4: Sales Excl | AC4: QTY | AD4: Sales Excl | AE4: QTY | AF4: Sales Excl | AG4: QTY | AH4: Sales Excl | AI4: QTY | AJ4: Sales Excl | AK4: QTY | AL4: Sales Excl | AM4: QTY | AN4: Sales Excl | AO4: QTY | AP4: Sales Excl | AQ4: QTY | AR4: Sales Excl | AS4: QTY | AT4: Sales Excl | AU4: QTY | AV4: Sales Excl | AW4: QTY | AX4: Sales Excl | AY4: QTY | AZ4: Sales Excl | BA4: QTY | BB4: Sales Excl | BC4: QTY | BD4: Sales Excl | BE4: QTY | BF4: Sales Excl | BG4: QTY | BH4: Sales Excl | BI4: QTY | BJ4: Sales Excl | BK4: QTY | BL4: Sales Excl | BM4: QTY | BN4: Sales Excl | BO4: QTY | BP4: Sales Excl | BQ4: QTY | BR4: Sales Excl | BS4: QTY | BT4: Sales Excl | BU4: QTY | BV4: Sales Excl | BW4: QTY | BX4: Sales Excl | BY4: QTY | BZ4: Sales Excl | CA4: QTY | CB4: Sales Excl | CC4: QTY | CD4: Sales Excl | CE4: QTY | CF4: Sales Excl | CG4: QTY | CH4: Sales Excl | CI4: QTY | CJ4: Sales Excl | CK4: QTY | CL4: Sales Excl | CM4: QTY | CN4: Sales Excl | CO4: QTY | CP4: Sales Excl | CQ4: QTY | CR4: Sales Excl | CS4: QTY | CT4: Sales Excl | CU4: QTY | CV4: Sales Excl | CW4: QTY | CX4: Sales Excl | CY4: QTY | CZ4: Sales Excl | DA4: QTY | DB4: Sales Excl | DC4: QTY | DD4: Sales Excl | DE4: QTY | DF4: Sales Excl | DG4: QTY | DH4: Sales Excl | DI4: QTY | DJ4: Sales Excl | DK4: QTY | DL4: Sales Excl | DM4: QTY | DN4: Sales Excl | DO4: QTY | DP4: Sales Excl | DQ4: QTY | DR4: Sales Excl | DS4: QTY | DT4: Sales Excl | DU4: QTY | DV4: Sales Excl | DW4: QTY | DX4: Sales Excl | DY4: QTY | DZ4: Sales Excl | EA4: QTY | EB4: Sales Excl | EC4: QTY | ED4: Sales Excl | EE4: QTY | EF4: Sales Excl | EG4: QTY | EH4: Sales Excl | EI4: QTY | EJ4: Sales Excl | EK4: QTY | EL4: Sales Excl | EM4: QTY | EN4: Sales Excl | EO4: QTY | EP4: Sales Excl | EQ4: QTY | ER4: Sales Excl | ES4: QTY | ET4: Sales Excl | EU4: QTY | EV4: Sales Excl | EW4: QTY | EX4: Sales Excl | EY4: QTY | EZ4: Sales Excl | FA4: QTY | FB4: Sales Excl | FC4: QTY | FD4: Sales Excl | FE4: QTY | FF4: Sales Excl | FG4: QTY | FH4: Sales Excl | FI4: QTY | FJ4: Sales Excl | FK4: QTY | FL4: Sales Excl | FM4: QTY | FN4: Sales Excl | FO4: QTY | FP4: Sales Excl | FQ4: QTY | FR4: Sales Excl | FS4: QTY | FT4: Sales Excl | FU4: QTY | FV4: Sales Excl | FW4: QTY | FX4: Sales Excl | FY4: QTY | FZ4: Sales Excl | GA4: QTY | GB4: Sales Excl | GC4: QTY | GD4: Sales Excl | GE4: QTY | GF4: Sales Excl | GG4: QTY | GH4: Sales Excl | GI4: QTY | GJ4: Sales Excl | GK4: QTY | GL4: Sales Excl | GM4: QTY | GN4: Sales Excl | GO4: QTY | GP4: Sales Excl | GQ4: QTY
A5: 216 | B5: SPAR SPICE WORS FARMHOUSE | C5: 2 | D5: 0 | E5: 0 | F5: 0 | G5: 0 | H5: 0 | I5: 0 | J5: 0 | K5: 0 | L5: 0 | M5: 0 | N5: 0 | O5: 0 | P5: 0 | Q5: 0 | R5: 0 | S5: 0 | T5: 0 | U5: 0 | V5: 0 | W5: 0 | X5: 0 | Y5: 0 | Z5: 0 | AA5: 0 | AB5: 0 | AC5: 0 | AD5: 0 | AE5: 0 | AF5: 0 | AG5: 0 | AH5: 0 | AI5: 0 | AJ5: 0 | AK5: 0 | AL5: 0 | AM5: 0 | AN5: 0 | AO5: 0 | AP5: 0 | AQ5: 0 | AR5: 0 | AS5: 0 | AT5: 0 | AU5: 0 | AV5: 0 | AW5: 0 | AX5: 0 | AY5: 0 | AZ5: 0 | BA5: 0 | BB5: 0 | BC5: 0 | BD5: 0 | BE5: 0 | BF5: 0 | BG5: 0 | BH5: 0 | BI5: 0 | BJ5: 0 | BK5: 0 | BL5: 0 | BM5: 0 | BN5: 0 | BO5: 0 | BP5: 0 | BQ5: 0 | BR5: 0 | BS5: 0 | BT5: 0 | BU5: 0 | BV5: 0 | BW5: 0 | BX5: 0 | BY5: 0 | BZ5: 0 | CA5: 0 | CB5: 0 | CC5: 0 | CD5: 0 | CE5: 0 | CF5: 0 | CG5: 0 | CH5: 0 | CI5: 0 | CJ5: 0 | CK5: 0 | CL5: 0 | CM5: 0 | CN5: 0 | CO5: 0 | CP5: 0 | CQ5: 0 | CR5: 0 | CS5: 0 | CT5: 0 | CU5: 0 | CV5: 0 | CW5: 0 | CX5: 0 | CY5: 0 | CZ5: 0 | DA5: 0 | DB5: 0 | DC5: 0 | DD5: 0 | DE5: 0 | DF5: 0 | DG5: 0 | DH5: 0 | DI5: 0 | DJ5: 0 | DK5: 0 | DL5: 0 | DM5: 0 | DN5: 0 | DO5: 0 | DP5: 0 | DQ5: 0 | DR5: 0 | DS5: 0 | DT5: 0 | DU5: 0 | DV5: 0 | DW5: 0 | DX5: 0 | DY5: 0 | DZ5: 0 | EA5: 0 | EB5: 0 | EC5: 0 | ED5: 0 | EE5: 0 | EF5: 0 | EG5: 0 | EH5: 0 | EI5: 0 | EJ5: 0 | EK5: 0 | EL5: 0 | EM5: 0 | EN5: 0 | EO5: 0 | EP5: 0 | EQ5: 0 | ER5: 0 | ES5: 0 | ET5: 0 | EU5: 0 | EV5: 0 | EW5: 0 | EX5: 0 | EY5: 0 | EZ5: 0 | FA5: 0 | FB5: 0 | FC5: 0 | FD5: 0 | FE5: 0 | FF5: 0 | FG5: 0 | FH5: 0 | FI5: 0 | FJ5: 0 | FK5: 0 | FL5: 0 | FM5: 0 | FN5: 0 | FO5: 0 | FP5: 0 | FQ5: 0 | FR5: 0 | FS5: 0 | FT5: 0 | FU5: 0 | FV5: 0 | FW5: 0 | FX5: 0 | FY5: 0 | FZ5: 0 | GA5: 0 | GB5: 0 | GC5: 0 | GD5: 0 | GE5: 0 | GF5: 0 | GG5: 0 | GH5: 0 | GI5: 0 | GJ5: 0 | GK5: 0 | GL5: 0 | GM5: 0 | GN5: 0 | GO5: 0 | GP5: 0 | GQ5: 0
A6: 216 | B6: SPAR SPICE B/WORS KALAHAR | C6: 2 | D6: 0 | E6: 0 | F6: 0 | G6: 0 | H6: 0 | I6: 0 | J6: 0 | K6: 0 | L6: 0 | M6: 0 | N6: 0 | O6: 0 | P6: 0 | Q6: 0 | R6: 0 | S6: 0 | T6: 0 | U6: 0 | V6: 0 | W6: 0 | X6: 0 | Y6: 0 | Z6: 0 | AA6: 0 | AB6: 0 | AC6: 0 | AD6: 0 | AE6: 0 | AF6: 0 | AG6: 0 | AH6: 0 | AI6: 0 | AJ6: 0 | AK6: 0 | AL6: 0 | AM6: 0 | AN6: 0 | AO6: 0 | AP6: 0 | AQ6: 0 | AR6: 0 | AS6: 0 | AT6: 0 | AU6: 0 | AV6: 0 | AW6: 0 | AX6: 0 | AY6: 0 | AZ6: 0 | BA6: 0 | BB6: 0 | BC6: 0 | BD6: 0 | BE6: 0 | BF6: 0 | BG6: 0 | BH6: 0 | BI6: 0 | BJ6: 0 | BK6: 0 | BL6: 0 | BM6: 0 | BN6: 0 | BO6: 0 | BP6: 0 | BQ6: 0 | BR6: 0 | BS6: 0 | BT6: 0 | BU6: 0 | BV6: 0 | BW6: 0 | BX6: 0 | BY6: 0 | BZ6: 0 | CA6: 0 | CB6: 0 | CC6: 0 | CD6: 0 | CE6: 0 | CF6: 0 | CG6: 0 | CH6: 0 | CI6: 0 | CJ6: 0 | CK6: 0 | CL6: 0 | CM6: 0 | CN6: 0 | CO6: 0 | CP6: 0 | CQ6: 0 | CR6: 0 | CS6: 0 | CT6: 0 | CU6: 0 | CV6: 0 | CW6: 0 | CX6: 0 | CY6: 0 | CZ6: 0 | DA6: 0 | DB6: 0 | DC6: 0 | DD6: 0 | DE6: 0 | DF6: 0 | DG6: 0 | DH6: 0 | DI6: 0 | DJ6: 0 | DK6: 0 | DL6: 0 | DM6: 0 | DN6: 0 | DO6: 0 | DP6: 0 | DQ6: 0 | DR6: 0 | DS6: 0 | DT6: 0 | DU6: 0 | DV6: 0 | DW6: 0 | DX6: 0 | DY6: 0 | DZ6: 0 | EA6: 0 | EB6: 0 | EC6: 0 | ED6: 0 | EE6: 0 | EF6: 0 | EG6: 0 | EH6: 0 | EI6: 0 | EJ6: 0 | EK6: 0 | EL6: 0 | EM6: 0 | EN6: 0 | EO6: 0 | EP6: 0 | EQ6: 0 | ER6: 0 | ES6: 0 | ET6: 0 | EU6: 0 | EV6: 0 | EW6: 0 | EX6: 0 | EY6: 0 | EZ6: 0 | FA6: 0 | FB6: 0 | FC6: 0 | FD6: 0 | FE6: 0 | FF6: 0 | FG6: 0 | FH6: 0 | FI6: 0 | FJ6: 0 | FK6: 0 | FL6: 0 | FM6: 0 | FN6: 0 | FO6: 0 | FP6: 0 | FQ6: 0 | FR6: 0 | FS6: 0 | FT6: 0 | FU6: 0 | FV6: 0 | FW6: 0 | FX6: 0 | FY6: 0 | FZ6: 0 | GA6: 0 | GB6: 0 | GC6: 0 | GD6: 0 | GE6: 0 | GF6: 0 | GG6: 0 | GH6: 0 | GI6: 0 | GJ6: 0 | GK6: 0 | GL6: 0 | GM6: 0 | GN6: 0 | GO6: 0 | GP6: 0 | GQ6: 0
A7: 216 | B7: SPAR SPICE B/WORS OUKRANS | C7: 2 | D7: 0 | E7: 0 | F7: 0 | G7: 0 | H7: 0 | I7: 0 | J7: 0 | K7: 0 | L7: 0 | M7: 0 | N7: 0 | O7: 0 | P7: 0 | Q7: 0 | R7: 0 | S7: 0 | T7: 0 | U7: 0 | V7: 0 | W7: 0 | X7: 0 | Y7: 0 | Z7: 0 | AA7: 0 | AB7: 0 | AC7: 0 | AD7: 0 | AE7: 0 | AF7: 0 | AG7: 0 | AH7: 0 | AI7: 0 | AJ7: 0 | AK7: 0 | AL7: 0 | AM7: 0 | AN7: 0 | AO7: 0 | AP7: 0 | AQ7: 0 | AR7: 0 | AS7: 0 | AT7: 0 | AU7: 0 | AV7: 0 | AW7: 0 | AX7: 0 | AY7: 0 | AZ7: 0 | BA7: 0 | BB7: 0 | BC7: 0 | BD7: 0 | BE7: 0 | BF7: 0 | BG7: 0 | BH7: 0 | BI7: 0 | BJ7: 0 | BK7: 0 | BL7: 0 | BM7: 0 | BN7: 0 | BO7: 0 | BP7: 0 | BQ7: 0 | BR7: 0 | BS7: 0 | BT7: 0 | BU7: 0 | BV7: 0 | BW7: 0 | BX7: 0 | BY7: 0 | BZ7: 0 | CA7: 0 | CB7: 0 | CC7: 0 | CD7: 0 | CE7: 0 | CF7: 0 | CG7: 0 | CH7: 0 | CI7: 0 | CJ7: 0 | CK7: 0 | CL7: 0 | CM7: 0 | CN7: 0 | CO7: 0 | CP7: 0 | CQ7: 0 | CR7: 0 | CS7: 0 | CT7: 0 | CU7: 0 | CV7: 0 | CW7: 0 | CX7: 0 | CY7: 0 | CZ7: 0 | DA7: 0 | DB7: 0 | DC7: 0 | DD7: 0 | DE7: 0 | DF7: 0 | DG7: 0 | DH7: 0 | DI7: 0 | DJ7: 0 | DK7: 0 | DL7: 0 | DM7: 0 | DN7: 0 | DO7: 0 | DP7: 0 | DQ7: 0 | DR7: 0 | DS7: 0 | DT7: 0 | DU7: 0 | DV7: 0 | DW7: 0 | DX7: 0 | DY7: 0 | DZ7: 0 | EA7: 0 | EB7: 0 | EC7: 0 | ED7: 0 | EE7: 0 | EF7: 0 | EG7: 0 | EH7: 0 | EI7: 0 | EJ7: 0 | EK7: 0 | EL7: 0 | EM7: 0 | EN7: 0 | EO7: 0 | EP7: 0 | EQ7: 0 | ER7: 0 | ES7: 0 | ET7: 0 | EU7: 0 | EV7: 0 | EW7: 0 | EX7: 0 | EY7: 0 | EZ7: 0 | FA7: 0 | FB7: 0 | FC7: 0 | FD7: 0 | FE7: 0 | FF7: 0 | FG7: 0 | FH7: 0 | FI7: 0 | FJ7: 0 | FK7: 0 | FL7: 0 | FM7: 0 | FN7: 0 | FO7: 0 | FP7: 0 | FQ7: 0 | FR7: 0 | FS7: 0 | FT7: 0 | FU7: 0 | FV7: 0 | FW7: 0 | FX7: 0 | FY7: 0 | FZ7: 0 | GA7: 0 | GB7: 0 | GC7: 0 | GD7: 0 | GE7: 0 | GF7: 0 | GG7: 0 | GH7: 0 | GI7: 0 | GJ7: 0 | GK7: 0 | GL7: 0 | GM7: 0 | GN7: 0 | GO7: 0 | GP7: 0 | GQ7: 0
A8: 216 | B8: SPAR SPICE B/WORS ROOIBRG | C8: 2 | D8: 0 | E8: 0 | F8: 0 | G8: 0 | H8: 0 | I8: 0 | J8: 0 | K8: 0 | L8: 0 | M8: 0 | N8: 0 | O8: 0 | P8: 0 | Q8: 0 | R8: 0 | S8: 0 | T8: 0 | U8: 0 | V8: 0 | W8: 0 | X8: 0 | Y8: 0 | Z8: 0 | AA8: 0 | AB8: 0 | AC8: 0 | AD8: 0 | AE8: 0 | AF8: 0 | AG8: 0 | AH8: 0 | AI8: 0 | AJ8: 0 | AK8: 0 | AL8: 0 | AM8: 0 | AN8: 0 | AO8: 0 | AP8: 0 | AQ8: 0 | AR8: 0 | AS8: 0 | AT8: 0 | AU8: 0 | AV8: 0 | AW8: 0 | AX8: 0 | AY8: 0 | AZ8: 0 | BA8: 0 | BB8: 0 | BC8: 0 | BD8: 0 | BE8: 0 | BF8: 0 | BG8: 0 | BH8: 0 | BI8: 0 | BJ8: 0 | BK8: 0 | BL8: 0 | BM8: 0 | BN8: 0 | BO8: 0 | BP8: 0 | BQ8: 0 | BR8: 0 | BS8: 0 | BT8: 0 | BU8: 0 | BV8: 0 | BW8: 0 | BX8: 0 | BY8: 0 | BZ8: 0 | CA8: 0 | CB8: 0 | CC8: 0 | CD8: 0 | CE8: 0 | CF8: 0 | CG8: 0 | CH8: 0 | CI8: 0 | CJ8: 0 | CK8: 0 | CL8: 0 | CM8: 0 | CN8: 0 | CO8: 0 | CP8: 0 | CQ8: 0 | CR8: 0 | CS8: 0 | CT8: 0 | CU8: 0 | CV8: 0 | CW8: 0 | CX8: 0 | CY8: 0 | CZ8: 0 | DA8: 0 | DB8: 0 | DC8: 0 | DD8: 0 | DE8: 0 | DF8: 0 | DG8: 0 | DH8: 0 | DI8: 0 | DJ8: 0 | DK8: 0 | DL8: 0 | DM8: 0 | DN8: 0 | DO8: 0 | DP8: 0 | DQ8: 0 | DR8: 0 | DS8: 0 | DT8: 0 | DU8: 0 | DV8: 0 | DW8: 0 | DX8: 0 | DY8: 0 | DZ8: 0 | EA8: 0 | EB8: 0 | EC8: 0 | ED8: 0 | EE8: 0 | EF8: 0 | EG8: 0 | EH8: 0 | EI8: 0 | EJ8: 0 | EK8: 0 | EL8: 0 | EM8: 0 | EN8: 0 | EO8: 0 | EP8: 0 | EQ8: 0 | ER8: 0 | ES8: 0 | ET8: 0 | EU8: 0 | EV8: 0 | EW8: 0 | EX8: 0 | EY8: 0 | EZ8: 0 | FA8: 0 | FB8: 0 | FC8: 0 | FD8: 0 | FE8: 0 | FF8: 0 | FG8: 0 | FH8: 0 | FI8: 0 | FJ8: 0 | FK8: 0 | FL8: 0 | FM8: 0 | FN8: 0 | FO8: 0 | FP8: 0 | FQ8: 0 | FR8: 0 | FS8: 0 | FT8: 0 | FU8: 0 | FV8: 0 | FW8: 0 | FX8: 0 | FY8: 0 | FZ8: 0 | GA8: 0 | GB8: 0 | GC8: 0 | GD8: 0 | GE8: 0 | GF8: 0 | GG8: 0 | GH8: 0 | GI8: 0 | GJ8: 0 | GK8: 0 | GL8: 0 | GM8: 0 | GN8: 0 | GO8: 0 | GP8: 0 | GQ8: 0
A9: 202 | B9: SPAR SPICE CHGRILL BURGER | C9: 2 | D9: 0 | E9: 0 | F9: 0 | G9: 0 | H9: 0 | I9: 0 | J9: 0 | K9: 0 | L9: 0 | M9: 0 | N9: 0 | O9: 0 | P9: 0 | Q9: 0 | R9: 0 | S9: 0 | T9: 0 | U9: 0 | V9: 0 | W9: 0 | X9: 0 | Y9: 0 | Z9: 0 | AA9: 0 | AB9: 0 | AC9: 0 | AD9: 0 | AE9: 0 | AF9: 0 | AG9: 0 | AH9: 0 | AI9: 0 | AJ9: 0 | AK9: 0 | AL9: 0 | AM9: 0 | AN9: 0 | AO9: 0 | AP9: 0 | AQ9: 0 | AR9: 0 | AS9: 0 | AT9: 0 | AU9: 0 | AV9: 0 | AW9: 0 | AX9: 0 | AY9: 0 | AZ9: 0 | BA9: 0 | BB9: 0 | BC9: 0 | BD9: 0 | BE9: 0 | BF9: 0 | BG9: 0 | BH9: 0 | BI9: 0 | BJ9: 0 | BK9: 0 | BL9: 0 | BM9: 0 | BN9: 0 | BO9: 0 | BP9: 0 | BQ9: 0 | BR9: 0 | BS9: 0 | BT9: 0 | BU9: 0 | BV9: 0 | BW9: 0 | BX9: 0 | BY9: 0 | BZ9: 0 | CA9: 0 | CB9: 0 | CC9: 0 | CD9: 0 | CE9: 0 | CF9: 0 | CG9: 0 | CH9: 0 | CI9: 0 | CJ9: 0 | CK9: 0 | CL9: 0 | CM9: 0 | CN9: 0 | CO9: 0 | CP9: 0 | CQ9: 0 | CR9: 0 | CS9: 0 | CT9: 0 | CU9: 0 | CV9: 0 | CW9: 0 | CX9: 0 | CY9: 0 | CZ9: 0 | DA9: 0 | DB9: 0 | DC9: 0 | DD9: 0 | DE9: 0 | DF9: 0 | DG9: 0 | DH9: 0 | DI9: 0 | DJ9: 0 | DK9: 0 | DL9: 0 | DM9: 0 | DN9: 0 | DO9: 0 | DP9: 0 | DQ9: 0 | DR9: 0 | DS9: 0 | DT9: 0 | DU9: 0 | DV9: 0 | DW9: 0 | DX9: 0 | DY9: 0 | DZ9: 0 | EA9: 0 | EB9: 0 | EC9: 0 | ED9: 0 | EE9: 0 | EF9: 0 | EG9: 0 | EH9: 0 | EI9: 0 | EJ9: 0 | EK9: 0 | EL9: 0 | EM9: 0 | EN9: 0 | EO9: 0 | EP9: 0 | EQ9: 0 | ER9: 0 | ES9: 0 | ET9: 0 | EU9: 0 | EV9: 0 | EW9: 0 | EX9: 0 | EY9: 0 | EZ9: 0 | FA9: 0 | FB9: 0 | FC9: 0 | FD9: 0 | FE9: 0 | FF9: 0 | FG9: 0 | FH9: 0 | FI9: 0 | FJ9: 0 | FK9: 0 | FL9: 0 | FM9: 0 | FN9: 0 | FO9: 0 | FP9: 0 | FQ9: 0 | FR9: 0 | FS9: 0 | FT9: 0 | FU9: 0 | FV9: 0 | FW9: 0 | FX9: 0 | FY9: 0 | FZ9: 0 | GA9: 0 | GB9: 0 | GC9: 0 | GD9: 0 | GE9: 0 | GF9: 0 | GG9: 0 | GH9: 0 | GI9: 0 | GJ9: 0 | GK9: 0 | GL9: 0 | GM9: 0 | GN9: 0 | GO9: 0 | GP9: 0 | GQ9: 0
A10: 210 | B10: SPAR SPICE BEEF SAUSAGE | C10: 2 | D10: 0 | E10: 0 | F10: 0 | G10: 0 | H10: 0 | I10: 0 | J10: 0 | K10: 0 | L10: 0 | M10: 0 | N10: 0 | O10: 0 | P10: 0 | Q10: 0 | R10: 0 | S10: 0 | T10: 0 | U10: 0 | V10: 0 | W10: 0 | X10: 0 | Y10: 0 | Z10: 0 | AA10: 0 | AB10: 0 | AC10: 0 | AD10: 0 | AE10: 0 | AF10: 0 | AG10: 0 | AH10: 0 | AI10: 0 | AJ10: 0 | AK10: 0 | AL10: 0 | AM10: 0 | AN10: 0 | AO10: 0 | AP10: 0 | AQ10: 0 | AR10: 0 | AS10: 0 | AT10: 0 | AU10: 0 | AV10: 0 | AW10: 0 | AX10: 0 | AY10: 0 | AZ10: 0 | BA10: 0 | BB10: 0 | BC10: 0 | BD10: 0 | BE10: 0 | BF10: 0 | BG10: 0 | BH10: 0 | BI10: 0 | BJ10: 0 | BK10: 0 | BL10: 0 | BM10: 0 | BN10: 0 | BO10: 0 | BP10: 0 | BQ10: 0 | BR10: 0 | BS10: 0 | BT10: 0 | BU10: 0 | BV10: 0 | BW10: 0 | BX10: 0 | BY10: 0 | BZ10: 0 | CA10: 0 | CB10: 0 | CC10: 0 | CD10: 0 | CE10: 0 | CF10: 0 | CG10: 0 | CH10: 0 | CI10: 0 | CJ10: 0 | CK10: 0 | CL10: 0 | CM10: 0 | CN10: 0 | CO10: 0 | CP10: 0 | CQ10: 0 | CR10: 0 | CS10: 0 | CT10: 0 | CU10: 0 | CV10: 0 | CW10: 0 | CX10: 0 | CY10: 0 | CZ10: 0 | DA10: 0 | DB10: 0 | DC10: 0 | DD10: 0 | DE10: 0 | DF10: 0 | DG10: 0 | DH10: 0 | DI10: 0 | DJ10: 0 | DK10: 0 | DL10: 0 | DM10: 0 | DN10: 0 | DO10: 0 | DP10: 0 | DQ10: 0 | DR10: 0 | DS10: 0 | DT10: 0 | DU10: 0 | DV10: 0 | DW10: 0 | DX10: 0 | DY10: 0 | DZ10: 0 | EA10: 0 | EB10: 0 | EC10: 0 | ED10: 0 | EE10: 0 | EF10: 0 | EG10: 0 | EH10: 0 | EI10: 0 | EJ10: 0 | EK10: 0 | EL10: 0 | EM10: 0 | EN10: 0 | EO10: 0 | EP10: 0 | EQ10: 0 | ER10: 0 | ES10: 0 | ET10: 0 | EU10: 0 | EV10: 0 | EW10: 0 | EX10: 0 | EY10: 0 | EZ10: 0 | FA10: 0 | FB10: 0 | FC10: 0 | FD10: 0 | FE10: 0 | FF10: 0 | FG10: 0 | FH10: 0 | FI10: 0 | FJ10: 0 | FK10: 0 | FL10: 0 | FM10: 0 | FN10: 0 | FO10: 0 | FP10: 0 | FQ10: 0 | FR10: 0 | FS10: 0 | FT10: 0 | FU10: 0 | FV10: 0 | FW10: 0 | FX10: 0 | FY10: 0 | FZ10: 0 | GA10: 0 | GB10: 0 | GC10: 0 | GD10: 0 | GE10: 0 | GF10: 0 | GG10: 0 | GH10: 0 | GI10: 0 | GJ10: 0 | GK10: 0 | GL10: 0 | GM10: 0 | GN10: 0 | GO10: 0 | GP10: 0 | GQ10: 0
A11: 207 | B11: SPAR SLT PORK LEG B/IN | C11: 2 | D11: 0 | E11: 0 | F11: 0 | G11: 0 | H11: 0 | I11: 0 | J11: 0 | K11: 0 | L11: 0 | M11: 0 | N11: 0 | O11: 0 | P11: 0 | Q11: 0 | R11: 0 | S11: 0 | T11: 0 | U11: 0 | V11: 0 | W11: 0 | X11: 0 | Y11: 0 | Z11: 0 | AA11: 0 | AB11: 0 | AC11: 0 | AD11: 0 | AE11: 0 | AF11: 0 | AG11: 0 | AH11: 0 | AI11: 0 | AJ11: 0 | AK11: 0 | AL11: 0 | AM11: 0 | AN11: 0 | AO11: 0 | AP11: 0 | AQ11: 0 | AR11: 0 | AS11: 0 | AT11: 0 | AU11: 0 | AV11: 0 | AW11: 0 | AX11: 0 | AY11: 0 | AZ11: 0 | BA11: 0 | BB11: 0 | BC11: 0 | BD11: 0 | BE11: 0 | BF11: 0 | BG11: 0 | BH11: 0 | BI11: 0 | BJ11: 0 | BK11: 0 | BL11: 0 | BM11: 0 | BN11: 0 | BO11: 0 | BP11: 0 | BQ11: 0 | BR11: 0 | BS11: 0 | BT11: 0 | BU11: 0 | BV11: 0 | BW11: 0 | BX11: 0 | BY11: 0 | BZ11: 0 | CA11: 0 | CB11: 0 | CC11: 0 | CD11: 0 | CE11: 0 | CF11: 0 | CG11: 0 | CH11: 0 | CI11: 0 | CJ11: 0 | CK11: 0 | CL11: 0 | CM11: 0 | CN11: 0 | CO11: 0 | CP11: 0 | CQ11: 0 | CR11: 0 | CS11: 0 | CT11: 0 | CU11: 0 | CV11: 0 | CW11: 0 | CX11: 0 | CY11: 0 | CZ11: 0 | DA11: 0 | DB11: 0 | DC11: 0 | DD11: 0 | DE11: 0 | DF11: 0 | DG11: 0 | DH11: 0 | DI11: 0 | DJ11: 0 | DK11: 0 | DL11: 0 | DM11: 0 | DN11: 0 | DO11: 0 | DP11: 0 | DQ11: 0 | DR11: 0 | DS11: 0 | DT11: 0 | DU11: 0 | DV11: 0 | DW11: 0 | DX11: 0 | DY11: 0 | DZ11: 0 | EA11: 0 | EB11: 0 | EC11: 0 | ED11: 0 | EE11: 0 | EF11: 0 | EG11: 0 | EH11: 0 | EI11: 0 | EJ11: 0 | EK11: 0 | EL11: 0 | EM11: 0 | EN11: 0 | EO11: 0 | EP11: 0 | EQ11: 0 | ER11: 0 | ES11: 0 | ET11: 0 | EU11: 0 | EV11: 0 | EW11: 0 | EX11: 0 | EY11: 0 | EZ11: 0 | FA11: 0 | FB11: 0 | FC11: 0 | FD11: 0 | FE11: 0 | FF11: 0 | FG11: 0 | FH11: 0 | FI11: 0 | FJ11: 0 | FK11: 0 | FL11: 0 | FM11: 0 | FN11: 0 | FO11: 0 | FP11: 0 | FQ11: 0 | FR11: 0 | FS11: 0 | FT11: 0 | FU11: 0 | FV11: 0 | FW11: 0 | FX11: 0 | FY11: 0 | FZ11: 0 | GA11: 0 | GB11: 0 | GC11: 0 | GD11: 0 | GE11: 0 | GF11: 0 | GG11: 0 | GH11: 0 | GI11: 0 | GJ11: 0 | GK11: 0 | GL11: 0 | GM11: 0 | GN11: 0 | GO11: 0 | GP11: 0 | GQ11: 0
A12: 207 | B12: YB PORK SHLDR B/IN | C12: 2 | D12: 0 | E12: 0 | F12: 0 | G12: 0 | H12: 0 | I12: 0 | J12: 0 | K12: 0 | L12: 0 | M12: 0 | N12: 0 | O12: 0 | P12: 0 | Q12: 0 | R12: 0 | S12: 0 | T12: 0 | U12: 0 | V12: 0 | W12: 0 | X12: 0 | Y12: 0 | Z12: 0 | AA12: 0 | AB12: 0 | AC12: 0 | AD12: 0 | AE12: 0 | AF12: 0 | AG12: 0 | AH12: 0 | AI12: 0 | AJ12: 0 | AK12: 0 | AL12: 0 | AM12: 0 | AN12: 0 | AO12: 0 | AP12: 0 | AQ12: 0 | AR12: 0 | AS12: 0 | AT12: 0 | AU12: 0 | AV12: 0 | AW12: 0 | AX12: 0 | AY12: 0 | AZ12: 0 | BA12: 0 | BB12: 0 | BC12: 0 | BD12: 0 | BE12: 0 | BF12: 0 | BG12: 0 | BH12: 0 | BI12: 0 | BJ12: 0 | BK12: 0 | BL12: 0 | BM12: 0 | BN12: 0 | BO12: 0 | BP12: 0 | BQ12: 0 | BR12: 0 | BS12: 0 | BT12: 0 | BU12: 0 | BV12: 0 | BW12: 0 | BX12: 0 | BY12: 0 | BZ12: 0 | CA12: 0 | CB12: 0 | CC12: 0 | CD12: 0 | CE12: 0 | CF12: 0 | CG12: 0 | CH12: 0 | CI12: 0 | CJ12: 0 | CK12: 0 | CL12: 0 | CM12: 0 | CN12: 0 | CO12: 0 | CP12: 0 | CQ12: 0 | CR12: 0 | CS12: 0 | CT12: 0 | CU12: 0 | CV12: 0 | CW12: 0 | CX12: 0 | CY12: 0 | CZ12: 0 | DA12: 0 | DB12: 0 | DC12: 0 | DD12: 0 | DE12: 0 | DF12: 0 | DG12: 0 | DH12: 0 | DI12: 0 | DJ12: 0 | DK12: 0 | DL12: 0 | DM12: 0 | DN12: 0 | DO12: 0 | DP12: 0 | DQ12: 0 | DR12: 0 | DS12: 0 | DT12: 0 | DU12: 0 | DV12: 0 | DW12: 0 | DX12: 0 | DY12: 0 | DZ12: 0 | EA12: 0 | EB12: 0 | EC12: 0 | ED12: 0 | EE12: 0 | EF12: 0 | EG12: 0 | EH12: 0 | EI12: 0 | EJ12: 0 | EK12: 0 | EL12: 0 | EM12: 0 | EN12: 0 | EO12: 0 | EP12: 0 | EQ12: 0 | ER12: 0 | ES12: 0 | ET12: 0 | EU12: 0 | EV12: 0 | EW12: 0 | EX12: 0 | EY12: 0 | EZ12: 0 | FA12: 0 | FB12: 0 | FC12: 0 | FD12: 0 | FE12: 0 | FF12: 0 | FG12: 0 | FH12: 0 | FI12: 0 | FJ12: 0 | FK12: 0 | FL12: 0 | FM12: 0 | FN12: 0 | FO12: 0 | FP12: 0 | FQ12: 0 | FR12: 0 | FS12: 0 | FT12: 0 | FU12: 0 | FV12: 0 | FW12: 0 | FX12: 0 | FY12: 0 | FZ12: 0 | GA12: 0 | GB12: 0 | GC12: 0 | GD12: 0 | GE12: 0 | GF12: 0 | GG12: 0 | GH12: 0 | GI12: 0 | GJ12: 0 | GK12: 0 | GL12: 0 | GM12: 0 | GN12: 0 | GO12: 0 | GP12: 0 | GQ12: 0
A13: 207 | B13: SPAR YB PORK LION WHOLE | C13: 2 | D13: 0 | E13: 0 | F13: 0 | G13: 0 | H13: 0 | I13: 0 | J13: 0 | K13: 0 | L13: 0 | M13: 0 | N13: 0 | O13: 0 | P13: 0 | Q13: 0 | R13: 0 | S13: 0 | T13: 0 | U13: 0 | V13: 0 | W13: 0 | X13: 0 | Y13: 0 | Z13: 0 | AA13: 0 | AB13: 0 | AC13: 0 | AD13: 0 | AE13: 0 | AF13: 0 | AG13: 0 | AH13: 0 | AI13: 0 | AJ13: 0 | AK13: 0 | AL13: 0 | AM13: 0 | AN13: 0 | AO13: 0 | AP13: 0 | AQ13: 0 | AR13: 0 | AS13: 0 | AT13: 0 | AU13: 0 | AV13: 0 | AW13: 0 | AX13: 0 | AY13: 0 | AZ13: 0 | BA13: 0 | BB13: 0 | BC13: 0 | BD13: 0 | BE13: 0 | BF13: 0 | BG13: 0 | BH13: 0 | BI13: 0 | BJ13: 0 | BK13: 0 | BL13: 0 | BM13: 0 | BN13: 0 | BO13: 0 | BP13: 0 | BQ13: 0 | BR13: 0 | BS13: 0 | BT13: 0 | BU13: 0 | BV13: 0 | BW13: 0 | BX13: 0 | BY13: 0 | BZ13: 0 | CA13: 0 | CB13: 0 | CC13: 0 | CD13: 0 | CE13: 0 | CF13: 0 | CG13: 0 | CH13: 0 | CI13: 0 | CJ13: 0 | CK13: 0 | CL13: 0 | CM13: 0 | CN13: 0 | CO13: 0 | CP13: 0 | CQ13: 0 | CR13: 0 | CS13: 0 | CT13: 0 | CU13: 0 | CV13: 0 | CW13: 0 | CX13: 0 | CY13: 0 | CZ13: 0 | DA13: 0 | DB13: 0 | DC13: 0 | DD13: 0 | DE13: 0 | DF13: 0 | DG13: 0 | DH13: 0 | DI13: 0 | DJ13: 0 | DK13: 0 | DL13: 0 | DM13: 0 | DN13: 0 | DO13: 0 | DP13: 0 | DQ13: 0 | DR13: 0 | DS13: 0 | DT13: 0 | DU13: 0 | DV13: 0 | DW13: 0 | DX13: 0 | DY13: 0 | DZ13: 0 | EA13: 0 | EB13: 0 | EC13: 0 | ED13: 0 | EE13: 0 | EF13: 0 | EG13: 0 | EH13: 0 | EI13: 0 | EJ13: 0 | EK13: 0 | EL13: 0 | EM13: 0 | EN13: 0 | EO13: 0 | EP13: 0 | EQ13: 0 | ER13: 0 | ES13: 0 | ET13: 0 | EU13: 0 | EV13: 0 | EW13: 0 | EX13: 0 | EY13: 0 | EZ13: 0 | FA13: 0 | FB13: 0 | FC13: 0 | FD13: 0 | FE13: 0 | FF13: 0 | FG13: 0 | FH13: 0 | FI13: 0 | FJ13: 0 | FK13: 0 | FL13: 0 | FM13: 0 | FN13: 0 | FO13: 0 | FP13: 0 | FQ13: 0 | FR13: 0 | FS13: 0 | FT13: 0 | FU13: 0 | FV13: 0 | FW13: 0 | FX13: 0 | FY13: 0 | FZ13: 0 | GA13: 0 | GB13: 0 | GC13: 0 | GD13: 0 | GE13: 0 | GF13: 0 | GG13: 0 | GH13: 0 | GI13: 0 | GJ13: 0 | GK13: 0 | GL13: 0 | GM13: 0 | GN13: 0 | GO13: 0 | GP13: 0 | GQ13: 0
A14: 207 | B14: BULK PORK NECK STEAK | C14: 2 | D14: 0 | E14: 0 | F14: 0 | G14: 0 | H14: 0 | I14: 0 | J14: 0 | K14: 0 | L14: 0 | M14: 0 | N14: 0 | O14: 0 | P14: 0 | Q14: 0 | R14: 0 | S14: 0 | T14: 0 | U14: 0 | V14: 0 | W14: 0 | X14: 0 | Y14: 0 | Z14: 0 | AA14: 0 | AB14: 0 | AC14: 0 | AD14: 0 | AE14: 0 | AF14: 0 | AG14: 0 | AH14: 0 | AI14: 0 | AJ14: 0 | AK14: 0 | AL14: 0 | AM14: 0 | AN14: 0 | AO14: 0 | AP14: 0 | AQ14: 0 | AR14: 0 | AS14: 0 | AT14: 0 | AU14: 0 | AV14: 0 | AW14: 0 | AX14: 0 | AY14: 0 | AZ14: 0 | BA14: 0 | BB14: 0 | BC14: 0 | BD14: 0 | BE14: 0 | BF14: 0 | BG14: 0 | BH14: 0 | BI14: 0 | BJ14: 0 | BK14: 0 | BL14: 0 | BM14: 0 | BN14: 0 | BO14: 0 | BP14: 0 | BQ14: 0 | BR14: 0 | BS14: 0 | BT14: 0 | BU14: 0 | BV14: 0 | BW14: 0 | BX14: 0 | BY14: 0 | BZ14: 0 | CA14: 0 | CB14: 0 | CC14: 0 | CD14: 0 | CE14: 0 | CF14: 0 | CG14: 0 | CH14: 0 | CI14: 0 | CJ14: 0 | CK14: 0 | CL14: 0 | CM14: 0 | CN14: 0 | CO14: 0 | CP14: 0 | CQ14: 0 | CR14: 0 | CS14: 0 | CT14: 0 | CU14: 0 | CV14: 0 | CW14: 0 | CX14: 0 | CY14: 0 | CZ14: 0 | DA14: 0 | DB14: 0 | DC14: 0 | DD14: 0 | DE14: 0 | DF14: 0 | DG14: 0 | DH14: 0 | DI14: 0 | DJ14: 0 | DK14: 0 | DL14: 0 | DM14: 0 | DN14: 0 | DO14: 0 | DP14: 0 | DQ14: 0 | DR14: 0 | DS14: 0 | DT14: 0 | DU14: 0 | DV14: 0 | DW14: 0 | DX14: 0 | DY14: 0 | DZ14: 0 | EA14: 0 | EB14: 0 | EC14: 0 | ED14: 0 | EE14: 0 | EF14: 0 | EG14: 0 | EH14: 0 | EI14: 0 | EJ14: 0 | EK14: 0 | EL14: 0 | EM14: 0 | EN14: 0 | EO14: 0 | EP14: 0 | EQ14: 0 | ER14: 0 | ES14: 0 | ET14: 0 | EU14: 0 | EV14: 0 | EW14: 0 | EX14: 0 | EY14: 0 | EZ14: 0 | FA14: 0 | FB14: 0 | FC14: 0 | FD14: 0 | FE14: 0 | FF14: 0 | FG14: 0 | FH14: 0 | FI14: 0 | FJ14: 0 | FK14: 0 | FL14: 0 | FM14: 0 | FN14: 0 | FO14: 0 | FP14: 0 | FQ14: 0 | FR14: 0 | FS14: 0 | FT14: 0 | FU14: 0 | FV14: 0 | FW14: 0 | FX14: 0 | FY14: 0 | FZ14: 0 | GA14: 0 | GB14: 0 | GC14: 0 | GD14: 0 | GE14: 0 | GF14: 0 | GG14: 0 | GH14: 0 | GI14: 0 | GJ14: 0 | GK14: 0 | GL14: 0 | GM14: 0 | GN14: 0 | GO14: 0 | GP14: 0 | GQ14: 0
A15: 207 | B15: PORK HOCKS STEW | C15: 2 | D15: 0 | E15: 0 | F15: 0 | G15: 0 | H15: 0 | I15: 0 | J15: 0 | K15: 0 | L15: 0 | M15: 0 | N15: 0 | O15: 0 | P15: 0 | Q15: 0 | R15: 0 | S15: 0 | T15: 0 | U15: 0 | V15: 0 | W15: 0 | X15: 0 | Y15: 0 | Z15: 0 | AA15: 0 | AB15: 0 | AC15: 0 | AD15: 0 | AE15: 0 | AF15: 0 | AG15: 0 | AH15: 0 | AI15: 0 | AJ15: 0 | AK15: 0 | AL15: 0 | AM15: 0 | AN15: 0 | AO15: 0 | AP15: 0 | AQ15: 0 | AR15: 0 | AS15: 0 | AT15: 0 | AU15: 0 | AV15: 0 | AW15: 0 | AX15: 0 | AY15: 0 | AZ15: 0 | BA15: 0 | BB15: 0 | BC15: 0 | BD15: 0 | BE15: 0 | BF15: 0 | BG15: 0 | BH15: 0 | BI15: 0 | BJ15: 0 | BK15: 0 | BL15: 0 | BM15: 0 | BN15: 0 | BO15: 0 | BP15: 0 | BQ15: 0 | BR15: 0 | BS15: 0 | BT15: 0 | BU15: 0 | BV15: 0 | BW15: 0 | BX15: 0 | BY15: 0 | BZ15: 0 | CA15: 0 | CB15: 0 | CC15: 0 | CD15: 0 | CE15: 0 | CF15: 0 | CG15: 0 | CH15: 0 | CI15: 0 | CJ15: 0 | CK15: 0 | CL15: 0 | CM15: 0 | CN15: 0 | CO15: 0 | CP15: 0 | CQ15: 0 | CR15: 0 | CS15: 0 | CT15: 0 | CU15: 0 | CV15: 0 | CW15: 0 | CX15: 0 | CY15: 0 | CZ15: 0 | DA15: 0 | DB15: 0 | DC15: 0 | DD15: 0 | DE15: 0 | DF15: 0 | DG15: 0 | DH15: 0 | DI15: 0 | DJ15: 0 | DK15: 0 | DL15: 0 | DM15: 0 | DN15: 0 | DO15: 0 | DP15: 0 | DQ15: 0 | DR15: 0 | DS15: 0 | DT15: 0 | DU15: 0 | DV15: 0 | DW15: 0 | DX15: 0 | DY15: 0 | DZ15: 0 | EA15: 0 | EB15: 0 | EC15: 0 | ED15: 0 | EE15: 0 | EF15: 0 | EG15: 0 | EH15: 0 | EI15: 0 | EJ15: 0 | EK15: 0 | EL15: 0 | EM15: 0 | EN15: 0 | EO15: 0 | EP15: 0 | EQ15: 0 | ER15: 0 | ES15: 0 | ET15: 0 | EU15: 0 | EV15: 0 | EW15: 0 | EX15: 0 | EY15: 0 | EZ15: 0 | FA15: 0 | FB15: 0 | FC15: 0 | FD15: 0 | FE15: 0 | FF15: 0 | FG15: 0 | FH15: 0 | FI15: 0 | FJ15: 0 | FK15: 0 | FL15: 0 | FM15: 0 | FN15: 0 | FO15: 0 | FP15: 0 | FQ15: 0 | FR15: 0 | FS15: 0 | FT15: 0 | FU15: 0 | FV15: 0 | FW15: 0 | FX15: 0 | FY15: 0 | FZ15: 0 | GA15: 0 | GB15: 0 | GC15: 0 | GD15: 0 | GE15: 0 | GF15: 0 | GG15: 0 | GH15: 0 | GI15: 0 | GJ15: 0 | GK15: 0 | GL15: 0 | GM15: 0 | GN15: 0 | GO15: 0 | GP15: 0 | GQ15: 0
A16: 210 | B16: SPAR YB BELLY B/IN | C16: 2 | D16: 0 | E16: 0 | F16: 0 | G16: 0 | H16: 0 | I16: 0 | J16: 0 | K16: 0 | L16: 0 | M16: 0 | N16: 0 | O16: 0 | P16: 0 | Q16: 0 | R16: 0 | S16: 0 | T16: 0 | U16: 0 | V16: 0 | W16: 0 | X16: 0 | Y16: 0 | Z16: 0 | AA16: 0 | AB16: 0 | AC16: 0 | AD16: 0 | AE16: 0 | AF16: 0 | AG16: 0 | AH16: 0 | AI16: 0 | AJ16: 0 | AK16: 0 | AL16: 0 | AM16: 0 | AN16: 0 | AO16: 0 | AP16: 0 | AQ16: 0 | AR16: 0 | AS16: 0 | AT16: 0 | AU16: 0 | AV16: 0 | AW16: 0 | AX16: 0 | AY16: 0 | AZ16: 0 | BA16: 0 | BB16: 0 | BC16: 0 | BD16: 0 | BE16: 0 | BF16: 0 | BG16: 0 | BH16: 0 | BI16: 0 | BJ16: 0 | BK16: 0 | BL16: 0 | BM16: 0 | BN16: 0 | BO16: 0 | BP16: 0 | BQ16: 0 | BR16: 0 | BS16: 0 | BT16: 0 | BU16: 0 | BV16: 0 | BW16: 0 | BX16: 0 | BY16: 0 | BZ16: 0 | CA16: 0 | CB16: 0 | CC16: 0 | CD16: 0 | CE16: 0 | CF16: 0 | CG16: 0 | CH16: 0 | CI16: 0 | CJ16: 0 | CK16: 0 | CL16: 0 | CM16: 0 | CN16: 0 | CO16: 0 | CP16: 0 | CQ16: 0 | CR16: 0 | CS16: 0 | CT16: 0 | CU16: 0 | CV16: 0 | CW16: 0 | CX16: 0 | CY16: 0 | CZ16: 0 | DA16: 0 | DB16: 0 | DC16: 0 | DD16: 0 | DE16: 0 | DF16: 0 | DG16: 0 | DH16: 0 | DI16: 0 | DJ16: 0 | DK16: 0 | DL16: 0 | DM16: 0 | DN16: 0 | DO16: 0 | DP16: 0 | DQ16: 0 | DR16: 0 | DS16: 0 | DT16: 0 | DU16: 0 | DV16: 0 | DW16: 0 | DX16: 0 | DY16: 0 | DZ16: 0 | EA16: 0 | EB16: 0 | EC16: 0 | ED16: 0 | EE16: 0 | EF16: 0 | EG16: 0 | EH16: 0 | EI16: 0 | EJ16: 0 | EK16: 0 | EL16: 0 | EM16: 0 | EN16: 0 | EO16: 0 | EP16: 0 | EQ16: 0 | ER16: 0 | ES16: 0 | ET16: 0 | EU16: 0 | EV16: 0 | EW16: 0 | EX16: 0 | EY16: 0 | EZ16: 0 | FA16: 0 | FB16: 0 | FC16: 0 | FD16: 0 | FE16: 0 | FF16: 0 | FG16: 0 | FH16: 0 | FI16: 0 | FJ16: 0 | FK16: 0 | FL16: 0 | FM16: 0 | FN16: 0 | FO16: 0 | FP16: 0 | FQ16: 0 | FR16: 0 | FS16: 0 | FT16: 0 | FU16: 0 | FV16: 0 | FW16: 0 | FX16: 0 | FY16: 0 | FZ16: 0 | GA16: 0 | GB16: 0 | GC16: 0 | GD16: 0 | GE16: 0 | GF16: 0 | GG16: 0 | GH16: 0 | GI16: 0 | GJ16: 0 | GK16: 0 | GL16: 0 | GM16: 0 | GN16: 0 | GO16: 0 | GP16: 0 | GQ16: 0
... A97: 216 | B97: ROOIBERG B/WORS | C97: 2 | D97: 189.0087 | E97: 1.976 | F97: 186.13913 | G97: 1.946 | H97: 312.78261 | I97: 3.27 | J97: 409.58261 | K97: 4.282 | L97: 941.7913 | M97: 9.847 | N97: 256.14783 | O97: 2.678 | P97: 40.556522 | Q97: 0.424 | R97: 0 | S97: 0 | T97: 43.234783 | U97: 0.366 | V97: 0 | W97: 0 | X97: 0 | Y97: 0 | Z97: 0 | AA97: 0 | AB97: 0 | AC97: 0 | AD97: 0 | AE97: 0 | AF97: 0 | AG97: 0 | AH97: 0 | AI97: 0 | AJ97: 0 | AK97: 0 | AL97: 0 | AM97: 0 | AN97: 0 | AO97: 0 | AP97: 0 | AQ97: 0 | AR97: 0 | AS97: 0 | AT97: 0 | AU97: 0 | AV97: 0 | AW97: 0 | AX97: 0 | AY97: 0 | AZ97: 0 | BA97: 0 | BB97: 0 | BC97: 0 | BD97: 0 | BE97: 0 | BF97: 0 | BG97: 0 | BH97: 0 | BI97: 0 | BJ97: 0 | BK97: 0 | BL97: 0 | BM97: 0 | BN97: 0 | BO97: 0 | BP97: 0 | BQ97: 0 | BR97: 0 | BS97: 0 | BT97: 0 | BU97: 0 | BV97: 199.91304 | BW97: 2.09 | BX97: 332.48696 | BY97: 3.476 | BZ97: 383.18261 | CA97: 4.006 | CB97: 225.35652 | CC97: 2.356 | CD97: 721.6 | CE97: 7.545 | CF97: 382.41739 | CG97: 3.998 | CH97: 73.652174 | CI97: 0.77 | CJ97: 355.63478 | CK97: 3.718 | CL97: 190.53913 | CM97: 1.992 | CN97: 174.66087 | CO97: 1.826 | CP97: 109.61739 | CQ97: 1.146 | CR97: 681.8 | CS97: 7.129 | CT97: 571.61739 | CU97: 5.977 | CV97: 440.95652 | CW97: 4.61 | CX97: 393.70435 | CY97: 4.116 | CZ97: 348.36522 | DA97: 3.642 | DB97: 507.33913 | DC97: 5.304 | DD97: 452.05217 | DE97: 4.726 | DF97: 1105.9304 | DG97: 11.563 | DH97: 1335.8783 | DI97: 13.967 | DJ97: 1157.3913 | DK97: 12.101 | DL97: 537.33043 | DM97: 5.618 | DN97: 419.08696 | DO97: 4.382 | DP97: 518.7913 | DQ97: 5.424 | DR97: 1114.3478 | DS97: 11.651 | DT97: 766.74783 | DU97: 8.017 | DV97: 841.54783 | DW97: 8.799 | DX97: 521.49565 | DY97: 5.452 | DZ97: 466.5913 | EA97: 4.878 | EB97: 29.46087 | EC97: 0.308 | ED97: 0 | EE97: 0 | EF97: 42.504348 | EG97: 0.376 | EH97: 375.53043 | EI97: 3.322 | EJ97: 279.21739 | EK97: 2.47 | EL97: 242.8087 | EM97: 2.148 | EN97: 131.35652 | EO97: 1.162 | EP97: 47.930435 | EQ97: 0.424 | ER97: 89.304348 | ES97: 0.79 | ET97: 100.6087 | EU97: 0.89 | EV97: 0 | EW97: 0 | EX97: 0 | EY97: 0 | EZ97: 46.573913 | FA97: 0.412 | FB97: 0 | FC97: 0 | FD97: 0 | FE97: 0 | FF97: 0 | FG97: 0 | FH97: 0 | FI97: 0 | FJ97: 0 | FK97: 0 | FL97: 0 | FM97: 0 | FN97: 0 | FO97: 0 | FP97: 0 | FQ97: 0 | FR97: 0 | FS97: 0 | FT97: 0 | FU97: 0 | FV97: 0 | FW97: 0 | FX97: 0 | FY97: 0 | FZ97: 0 | GA97: 0 | GB97: 0 | GC97: 0 | GD97: 0 | GE97: 0 | GF97: 0 | GG97: 0 | GH97: 0 | GI97: 0 | GJ97: 0 | GK97: 0 | GL97: 0 | GM97: 0 | GN97: 0 | GO97: 0 | GP97: 0 | GQ97: 0
A98: 204 | B98: 1 | C98: 2 | D98: 0 | E98: 0 | F98: 0 | G98: 0 | H98: 0 | I98: 0 | J98: 0 | K98: 0 | L98: 0 | M98: 0 | N98: 0 | O98: 0 | P98: 0 | Q98: 0 | R98: 0 | S98: 0 | T98: 0 | U98: 0 | V98: 0 | W98: 0 | X98: 0 | Y98: 0 | Z98: 0 | AA98: 0 | AB98: 0 | AC98: 0 | AD98: 0 | AE98: 0 | AF98: 0 | AG98: 0 | AH98: 0 | AI98: 0 | AJ98: 0 | AK98: 0 | AL98: 0 | AM98: 0 | AN98: 0 | AO98: 0 | AP98: 0 | AQ98: 0 | AR98: 0 | AS98: 0 | AT98: 0 | AU98: 0 | AV98: 0 | AW98: 0 | AX98: 366.51304 | AY98: 2.958 | AZ98: 786.9913 | BA98: 6.034 | BB98: 0 | BC98: 0 | BD98: 0 | BE98: 0 | BF98: 0 | BG98: 0 | BH98: 0 | BI98: 0 | BJ98: 0 | BK98: 0 | BL98: 0 | BM98: 0 | BN98: 0 | BO98: 0 | BP98: 0 | BQ98: 0 | BR98: 0 | BS98: 0 | BT98: 0 | BU98: 0 | BV98: 0 | BW98: 0 | BX98: 0 | BY98: 0 | BZ98: 0 | CA98: 0 | CB98: 0 | CC98: 0 | CD98: 0 | CE98: 0 | CF98: 0 | CG98: 0 | CH98: 0 | CI98: 0 | CJ98: 0 | CK98: 0 | CL98: 0 | CM98: 0 | CN98: 0 | CO98: 0 | CP98: 0 | CQ98: 0 | CR98: 0 | CS98: 0 | CT98: 0 | CU98: 0 | CV98: 0 | CW98: 0 | CX98: 0 | CY98: 0 | CZ98: 0 | DA98: 0 | DB98: 0 | DC98: 0 | DD98: 0 | DE98: 0 | DF98: 1303.7478 | DG98: 9.996 | DH98: 925.24348 | DI98: 7.094 | DJ98: 0 | DK98: 0 | DL98: 0 | DM98: 0 | DN98: 0 | DO98: 0 | DP98: 0 | DQ98: 0 | DR98: 0 | DS98: 0 | DT98: 0 | DU98: 0 | DV98: 0 | DW98: 0 | DX98: 0 | DY98: 0 | DZ98: 0 | EA98: 0 | EB98: 0 | EC98: 0 | ED98: 0 | EE98: 0 | EF98: 0 | EG98: 0 | EH98: 0 | EI98: 0 | EJ98: 0 | EK98: 0 | EL98: 389.97391 | EM98: 2.99 | EN98: 400.4087 | EO98: 3.07 | EP98: 0 | EQ98: 0 | ER98: 0 | ES98: 0 | ET98: 0 | EU98: 0 | EV98: 0 | EW98: 0 | EX98: 0 | EY98: 0 | EZ98: 0 | FA98: 0 | FB98: 0 | FC98: 0 | FD98: 0 | FE98: 0 | FF98: 1026.9391 | FG98: 8.748 | FH98: 1202.3217 | FI98: 10.242 | FJ98: 3539.113 | FK98: 30.148 | FL98: 6351.8087 | FM98: 54.108 | FN98: 2880.0783 | FO98: 24.534 | FP98: 1388.7565 | FQ98: 11.744 | FR98: 2089.513 | FS98: 17.67 | FT98: 1719.1304 | FU98: 14.692 | FV98: 3596.0522 | FW98: 30.41 | FX98: 2428.8957 | FY98: 20.54 | FZ98: 1665.4609 | GA98: 14.084 | GB98: 0 | GC98: 0 | GD98: 0 | GE98: 0 | GF98: 0 | GG98: 0 | GH98: 0 | GI98: 0 | GJ98: 0 | GK98: 0 | GL98: 0 | GM98: 0 | GN98: 0 | GO98: 0 | GP98: 0 | GQ98: 0
A99: 216 | B99: OPPIE-KOPPIE BOEREWORS | C99: 2 | D99: 0 | E99: 0 | F99: 0 | G99: 0 | H99: 0 | I99: 0 | J99: 0 | K99: 0 | L99: 0 | M99: 0 | N99: 0 | O99: 0 | P99: 0 | Q99: 0 | R99: 0 | S99: 0 | T99: 0 | U99: 0 | V99: 0 | W99: 0 | X99: 82.773913 | Y99: 0.7 | Z99: 195.5913 | AA99: 1.607 | AB99: 317.38261 | AC99: 2.607 | AD99: 219.94783 | AE99: 1.807 | AF99: 124.41739 | AG99: 1.022 | AH99: 78.4 | AI99: 0.644 | AJ99: 0 | AK99: 0 | AL99: 0 | AM99: 0 | AN99: 219.49565 | AO99: 1.942 | AP99: 240.66087 | AQ99: 2.129 | AR99: 122.53913 | AS99: 1.084 | AT99: 164.5913 | AU99: 1.456 | AV99: 160.06957 | AW99: 1.416 | AX99: 334.15652 | AY99: 2.956 | AZ99: 281.02609 | BA99: 2.486 | BB99: 814.5913 | BC99: 7.207 | BD99: 701.54783 | BE99: 6.206 | BF99: 0 | BG99: 0 | BH99: 94.730435 | BI99: 0.838 | BJ99: 161.65217 | BK99: 1.43 | BL99: 0 | BM99: 0 | BN99: 0 | BO99: 0 | BP99: 0 | BQ99: 0 | BR99: 0 | BS99: 0 | BT99: 0 | BU99: 0 | BV99: 0 | BW99: 0 | BX99: 0 | BY99: 0 | BZ99: 0 | CA99: 0 | CB99: 0 | CC99: 0 | CD99: 0 | CE99: 0 | CF99: 0 | CG99: 0 | CH99: 0 | CI99: 0 | CJ99: 0 | CK99: 0 | CL99: 0 | CM99: 0 | CN99: 0 | CO99: 0 | CP99: 0 | CQ99: 0 | CR99: 288.93913 | CS99: 2.556 | CT99: 390.67826 | CU99: 3.456 | CV99: 85.234783 | CW99: 0.754 | CX99: 95.86087 | CY99: 0.848 | CZ99: 133.16522 | DA99: 1.178 | DB99: 162.10435 | DC99: 1.434 | DD99: 130.45217 | DE99: 1.154 | DF99: 174.9913 | DG99: 1.548 | DH99: 222.46957 | DI99: 1.968 | DJ99: 0 | DK99: 0 | DL99: 50.191304 | DM99: 0.444 | DN99: 0 | DO99: 0 | DP99: 84.330435 | DQ99: 0.746 | DR99: 362.64348 | DS99: 3.208 | DT99: 415.32174 | DU99: 3.674 | DV99: 672.6087 | DW99: 5.95 | DX99: 258.41739 | DY99: 2.286 | DZ99: 205.73913 | EA99: 1.82 | EB99: 40.243478 | EC99: 0.356 | ED99: 0 | EE99: 0 | EF99: 35.947826 | EG99: 0.318 | EH99: 526.33043 | EI99: 4.656 | EJ99: 338.67826 | EK99: 2.996 | EL99: 261.58261 | EM99: 2.314 | EN99: 137.91304 | EO99: 1.22 | EP99: 47.252174 | EQ99: 0.418 | ER99: 190.13913 | ES99: 1.682 | ET99: 140.4 | EU99: 1.242 | EV99: 268.5913 | EW99: 2.376 | EX99: 275.14783 | EY99: 2.434 | EZ99: 49.286957 | FA99: 0.436 | FB99: 47.930435 | FC99: 0.424 | FD99: 0 | FE99: 0 | FF99: 43.182609 | FG99: 0.382 | FH99: 86.365217 | FI99: 0.764 | FJ99: 181.32174 | FK99: 1.604 | FL99: 629.65217 | FM99: 5.57 | FN99: 339.35652 | FO99: 3.002 | FP99: 513.66957 | FQ99: 4.544 | FR99: 139.72174 | FS99: 1.236 | FT99: 67.147826 | FU99: 0.594 | FV99: 316.97391 | FW99: 2.804 | FX99: 528.36522 | FY99: 4.674 | FZ99: 387.73913 | GA99: 3.43 | GB99: 177.70435 | GC99: 1.572 | GD99: 190.5913 | GE99: 1.686 | GF99: 131.8087 | GG99: 1.166 | GH99: 311.32174 | GI99: 2.754 | GJ99: 220.88696 | GK99: 1.954 | GL99: 414.64348 | GM99: 3.668 | GN99: 528.13913 | GO99: 4.672 | GP99: 210.71304 | GQ99: 1.864
A100: 216 | B100: OUKRANS BOEREWORS | C100: 2 | D100: 0 | E100: 0 | F100: 0 | G100: 0 | H100: 0 | I100: 0 | J100: 0 | K100: 0 | L100: 0 | M100: 0 | N100: 0 | O100: 0 | P100: 0 | Q100: 0 | R100: 0 | S100: 0 | T100: 0 | U100: 0 | V100: 0 | W100: 0 | X100: 0 | Y100: 0 | Z100: 0 | AA100: 0 | AB100: 0 | AC100: 0 | AD100: 0 | AE100: 0 | AF100: 0 | AG100: 0 | AH100: 0 | AI100: 0 | AJ100: 0 | AK100: 0 | AL100: 0 | AM100: 0 | AN100: 0 | AO100: 0 | AP100: 0 | AQ100: 0 | AR100: 0 | AS100: 0 | AT100: 0 | AU100: 0 | AV100: 0 | AW100: 0 | AX100: 0 | AY100: 0 | AZ100: 0 | BA100: 0 | BB100: 0 | BC100: 0 | BD100: 0 | BE100: 0 | BF100: 0 | BG100: 0 | BH100: 0 | BI100: 0 | BJ100: 0 | BK100: 0 | BL100: 0 | BM100: 0 | BN100: 0 | BO100: 0 | BP100: 0 | BQ100: 0 | BR100: 0 | BS100: 0 | BT100: 0 | BU100: 0 | BV100: 0 | BW100: 0 | BX100: 0 | BY100: 0 | BZ100: 0 | CA100: 0 | CB100: 0 | CC100: 0 | CD100: 0 | CE100: 0 | CF100: 0 | CG100: 0 | CH100: 0 | CI100: 0 | CJ100: 0 | CK100: 0 | CL100: 0 | CM100: 0 | CN100: 0 | CO100: 0 | CP100: 0 | CQ100: 0 | CR100: 0 | CS100: 0 | CT100: 0 | CU100: 0 | CV100: 0 | CW100: 0 | CX100: 0 | CY100: 0 | CZ100: 0 | DA100: 0 | DB100: 0 | DC100: 0 | DD100: 0 | DE100: 0 | DF100: 0 | DG100: 0 | DH100: 0 | DI100: 0 | DJ100: 0 | DK100: 0 | DL100: 0 | DM100: 0 | DN100: 0 | DO100: 0 | DP100: 0 | DQ100: 0 | DR100: 0 | DS100: 0 | DT100: 0 | DU100: 0 | DV100: 0 | DW100: 0 | DX100: 0 | DY100: 0 | DZ100: 0 | EA100: 0 | EB100: 0 | EC100: 0 | ED100: 0 | EE100: 0 | EF100: 0 | EG100: 0 | EH100: 0 | EI100: 0 | EJ100: 0 | EK100: 0 | EL100: 0 | EM100: 0 | EN100: 0 | EO100: 0 | EP100: 0 | EQ100: 0 | ER100: 0 | ES100: 0 | ET100: 0 | EU100: 0 | EV100: 0 | EW100: 0 | EX100: 660.10435 | EY100: 6.327 | EZ100: 247.09565 | FA100: 2.368 | FB100: 84.730435 | FC100: 0.812 | FD100: 87.443478 | FE100: 0.838 | FF100: 261.07826 | FG100: 2.31 | FH100: 527.93043 | FI100: 4.671 | FJ100: 699.96522 | FK100: 6.192 | FL100: 857.54783 | FM100: 7.587 | FN100: 224.73043 | FO100: 1.988 | FP100: 372.5913 | FQ100: 3.296 | FR100: 0 | FS100: 0 | FT100: 0 | FU100: 0 | FV100: 0 | FW100: 0 | FX100: 0 | FY100: 0 | FZ100: 0 | GA100: 0 | GB100: 0 | GC100: 0 | GD100: 0 | GE100: 0 | GF100: 0 | GG100: 0 | GH100: 0 | GI100: 0 | GJ100: 0 | GK100: 0 | GL100: 0 | GM100: 0 | GN100: 0 | GO100: 0 | GP100: 0 | GQ100: 0
A101: 213 | B101: BABELAS MIX | C101: 2 | D101: 0 | E101: 0 | F101: 0 | G101: 0 | H101: 0 | I101: 0 | J101: 0 | K101: 0 | L101: 0 | M101: 0 | N101: 0 | O101: 0 | P101: 0 | Q101: 0 | R101: 0 | S101: 0 | T101: 0 | U101: 0 | V101: 0 | W101: 0 | X101: 0 | Y101: 0 | Z101: 0 | AA101: 0 | AB101: 0 | AC101: 0 | AD101: 0 | AE101: 0 | AF101: 0 | AG101: 0 | AH101: 0 | AI101: 0 | AJ101: 0 | AK101: 0 | AL101: 0 | AM101: 0 | AN101: 0 | AO101: 0 | AP101: 0 | AQ101: 0 | AR101: 0 | AS101: 0 | AT101: 0 | AU101: 0 | AV101: 0 | AW101: 0 | AX101: 0 | AY101: 0 | AZ101: 0 | BA101: 0 | BB101: 0 | BC101: 0 | BD101: 0 | BE101: 0 | BF101: 0 | BG101: 0 | BH101: 0 | BI101: 0 | BJ101: 0 | BK101: 0 | BL101: 0 | BM101: 0 | BN101: 0 | BO101: 0 | BP101: 0 | BQ101: 0 | BR101: 0 | BS101: 0 | BT101: 0 | BU101: 0 | BV101: 0 | BW101: 0 | BX101: 0 | BY101: 0 | BZ101: 0 | CA101: 0 | CB101: 0 | CC101: 0 | CD101: 0 | CE101: 0 | CF101: 0 | CG101: 0 | CH101: 0 | CI101: 0 | CJ101: 0 | CK101: 0 | CL101: 0 | CM101: 0 | CN101: 0 | CO101: 0 | CP101: 0 | CQ101: 0 | CR101: 0 | CS101: 0 | CT101: 0 | CU101: 0 | CV101: 0 | CW101: 0 | CX101: 0 | CY101: 0 | CZ101: 0 | DA101: 0 | DB101: 0 | DC101: 0 | DD101: 0 | DE101: 0 | DF101: 0 | DG101: 0 | DH101: 0 | DI101: 0 | DJ101: 0 | DK101: 0 | DL101: 0 | DM101: 0 | DN101: 0 | DO101: 0 | DP101: 0 | DQ101: 0 | DR101: 0 | DS101: 0 | DT101: 0 | DU101: 0 | DV101: 0 | DW101: 0 | DX101: 0 | DY101: 0 | DZ101: 0 | EA101: 0 | EB101: 0 | EC101: 0 | ED101: 0 | EE101: 0 | EF101: 0 | EG101: 0 | EH101: 0 | EI101: 0 | EJ101: 0 | EK101: 0 | EL101: 0 | EM101: 0 | EN101: 0 | EO101: 0 | EP101: 0 | EQ101: 0 | ER101: 0 | ES101: 0 | ET101: 0 | EU101: 0 | EV101: 0 | EW101: 0 | EX101: 0 | EY101: 0 | EZ101: 0 | FA101: 0 | FB101: 0 | FC101: 0 | FD101: 0 | FE101: 0 | FF101: 0 | FG101: 0 | FH101: 0 | FI101: 0 | FJ101: 0 | FK101: 0 | FL101: 0 | FM101: 0 | FN101: 0 | FO101: 0 | FP101: 0 | FQ101: 0 | FR101: 0 | FS101: 0 | FT101: 0 | FU101: 0 | FV101: 0 | FW101: 0 | FX101: 0 | FY101: 0 | FZ101: 0 | GA101: 0 | GB101: 0 | GC101: 0 | GD101: 0 | GE101: 0 | GF101: 0 | GG101: 0 | GH101: 0 | GI101: 0 | GJ101: 0 | GK101: 0 | GL101: 0 | GM101: 0 | GN101: 0 | GO101: 0 | GP101: 0 | GQ101: 0
A102: 202 | B102: BEEF F/QUARTER | C102: 2 | D102: 0 | E102: 0 | F102: 0 | G102: 0 | H102: 0 | I102: 0 | J102: 0 | K102: 0 | L102: 0 | M102: 0 | N102: 0 | O102: 0 | P102: 0 | Q102: 0 | R102: 0 | S102: 0 | T102: 0 | U102: 0 | V102: 0 | W102: 0 | X102: 0 | Y102: 0 | Z102: 0 | AA102: 0 | AB102: 0 | AC102: 0 | AD102: 0 | AE102: 0 | AF102: 0 | AG102: 0 | AH102: 0 | AI102: 0 | AJ102: 0 | AK102: 0 | AL102: 0 | AM102: 0 | AN102: 0 | AO102: 0 | AP102: 0 | AQ102: 0 | AR102: 0 | AS102: 0 | AT102: 0 | AU102: 0 | AV102: 0 | AW102: 0 | AX102: 0 | AY102: 0 | AZ102: 0 | BA102: 0 | BB102: 0 | BC102: 0 | BD102: 0 | BE102: 0 | BF102: 0 | BG102: 0 | BH102: 0 | BI102: 0 | BJ102: 0 | BK102: 0 | BL102: 0 | BM102: 0 | BN102: 0 | BO102: 0 | BP102: 0 | BQ102: 0 | BR102: 0 | BS102: 0 | BT102: 0 | BU102: 0 | BV102: 0 | BW102: 0 | BX102: 0 | BY102: 0 | BZ102: 0 | CA102: 0 | CB102: 0 | CC102: 0 | CD102: 0 | CE102: 0 | CF102: 0 | CG102: 0 | CH102: 0 | CI102: 0 | CJ102: 0 | CK102: 0 | CL102: 0 | CM102: 0 | CN102: 0 | CO102: 0 | CP102: 0 | CQ102: 0 | CR102: 0 | CS102: 0 | CT102: 0 | CU102: 0 | CV102: 0 | CW102: 0 | CX102: 0 | CY102: 0 | CZ102: 0 | DA102: 0 | DB102: 0 | DC102: 0 | DD102: 0 | DE102: 0 | DF102: 0 | DG102: 0 | DH102: 0 | DI102: 0 | DJ102: 0 | DK102: 0 | DL102: 0 | DM102: 0 | DN102: 0 | DO102: 0 | DP102: 0 | DQ102: 0 | DR102: 0 | DS102: 0 | DT102: 0 | DU102: 0 | DV102: 0 | DW102: 0 | DX102: 0 | DY102: 0 | DZ102: 0 | EA102: 0 | EB102: 0 | EC102: 0 | ED102: 0 | EE102: 0 | EF102: 0 | EG102: 0 | EH102: 0 | EI102: 0 | EJ102: 0 | EK102: 0 | EL102: 0 | EM102: 0 | EN102: 0 | EO102: 0 | EP102: 0 | EQ102: 0 | ER102: 0 | ES102: 0 | ET102: 0 | EU102: 0 | EV102: 0 | EW102: 0 | EX102: 0 | EY102: 0 | EZ102: 0 | FA102: 0 | FB102: 0 | FC102: 0 | FD102: 0 | FE102: 0 | FF102: 0 | FG102: 0 | FH102: 0 | FI102: 0 | FJ102: 0 | FK102: 0 | FL102: 0 | FM102: 0 | FN102: 0 | FO102: 0 | FP102: 0 | FQ102: 0 | FR102: 0 | FS102: 0 | FT102: 0 | FU102: 0 | FV102: 0 | FW102: 0 | FX102: 0 | FY102: 0 | FZ102: 0 | GA102: 0 | GB102: 0 | GC102: 0 | GD102: 0 | GE102: 0 | GF102: 0 | GG102: 0 | GH102: 0 | GI102: 0 | GJ102: 0 | GK102: 0 | GL102: 0 | GM102: 0 | GN102: 0 | GO102: 0 | GP102: 0 | GQ102: 0
A103: 213 | B103: BEEF BILTONG | C103: 2 | D103: 0 | E103: 0 | F103: 0 | G103: 0 | H103: 0 | I103: 0 | J103: 0 | K103: 0 | L103: 0 | M103: 0 | N103: 0 | O103: 0 | P103: 0 | Q103: 0 | R103: 0 | S103: 0 | T103: 0 | U103: 0 | V103: 0 | W103: 0 | X103: 0 | Y103: 0 | Z103: 0 | AA103: 0 | AB103: 0 | AC103: 0 | AD103: 0 | AE103: 0 | AF103: 0 | AG103: 0 | AH103: 0 | AI103: 0 | AJ103: 0 | AK103: 0 | AL103: 0 | AM103: 0 | AN103: 0 | AO103: 0 | AP103: 0 | AQ103: 0 | AR103: 0 | AS103: 0 | AT103: 0 | AU103: 0 | AV103: 0 | AW103: 0 | AX103: 0 | AY103: 0 | AZ103: 0 | BA103: 0 | BB103: 0 | BC103: 0 | BD103: 0 | BE103: 0 | BF103: 0 | BG103: 0 | BH103: 0 | BI103: 0 | BJ103: 0 | BK103: 0 | BL103: 0 | BM103: 0 | BN103: 0 | BO103: 0 | BP103: 0 | BQ103: 0 | BR103: 0 | BS103: 0 | BT103: 0 | BU103: 0 | BV103: 0 | BW103: 0 | BX103: 0 | BY103: 0 | BZ103: 0 | CA103: 0 | CB103: 0 | CC103: 0 | CD103: 0 | CE103: 0 | CF103: 0 | CG103: 0 | CH103: 0 | CI103: 0 | CJ103: 0 | CK103: 0 | CL103: 0 | CM103: 0 | CN103: 0 | CO103: 0 | CP103: 0 | CQ103: 0 | CR103: 0 | CS103: 0 | CT103: 0 | CU103: 0 | CV103: 0 | CW103: 0 | CX103: 0 | CY103: 0 | CZ103: 0 | DA103: 0 | DB103: 0 | DC103: 0 | DD103: 0 | DE103: 0 | DF103: 0 | DG103: 0 | DH103: 0 | DI103: 0 | DJ103: 0 | DK103: 0 | DL103: 0 | DM103: 0 | DN103: 0 | DO103: 0 | DP103: 0 | DQ103: 0 | DR103: 62.817391 | DS103: 0.144 | DT103: 0 | DU103: 0 | DV103: 0 | DW103: 0 | DX103: 0 | DY103: 0 | DZ103: 0 | EA103: 0 | EB103: 0 | EC103: 0 | ED103: 0 | EE103: 0 | EF103: 0 | EG103: 0 | EH103: 0 | EI103: 0 | EJ103: 0 | EK103: 0 | EL103: 0 | EM103: 0 | EN103: 0 | EO103: 0 | EP103: 0 | EQ103: 0 | ER103: 0 | ES103: 0 | ET103: 0 | EU103: 0 | EV103: 0 | EW103: 0 | EX103: 0 | EY103: 0 | EZ103: 0 | FA103: 0 | FB103: 0 | FC103: 0 | FD103: 0 | FE103: 0 | FF103: 0 | FG103: 0 | FH103: 0 | FI103: 0 | FJ103: 0 | FK103: 0 | FL103: 0 | FM103: 0 | FN103: 0 | FO103: 0 | FP103: 0 | FQ103: 0 | FR103: 0 | FS103: 0 | FT103: 0 | FU103: 0 | FV103: 0 | FW103: 0 | FX103: 0 | FY103: 0 | FZ103: 0 | GA103: 0 | GB103: 0 | GC103: 0 | GD103: 0 | GE103: 0 | GF103: 0 | GG103: 0 | GH103: 0 | GI103: 0 | GJ103: 0 | GK103: 0 | GL103: 0 | GM103: 0 | GN103: 0 | GO103: 0 | GP103: 0 | GQ103: 0
A104: 224 | B104: BEEF BILTONG NUGGET PLAIN | C104: 2 | D104: 0 | E104: 0 | F104: 0 | G104: 0 | H104: 0 | I104: 0 | J104: 48.147826 | K104: 0.098 | L104: 0 | M104: 0 | N104: 0 | O104: 0 | P104: 0 | Q104: 0 | R104: 0 | S104: 0 | T104: 0 | U104: 0 | V104: 0 | W104: 0 | X104: 0 | Y104: 0 | Z104: 0 | AA104: 0 | AB104: 0 | AC104: 0 | AD104: 0 | AE104: 0 | AF104: 0 | AG104: 0 | AH104: 0 | AI104: 0 | AJ104: 0 | AK104: 0 | AL104: 0 | AM104: 0 | AN104: 0 | AO104: 0 | AP104: 0 | AQ104: 0 | AR104: 0 | AS104: 0 | AT104: 0 | AU104: 0 | AV104: 0 | AW104: 0 | AX104: 0 | AY104: 0 | AZ104: 0 | BA104: 0 | BB104: 0 | BC104: 0 | BD104: 0 | BE104: 0 | BF104: 0 | BG104: 0 | BH104: 0 | BI104: 0 | BJ104: 0 | BK104: 0 | BL104: 0 | BM104: 0 | BN104: 0 | BO104: 0 | BP104: 0 | BQ104: 0 | BR104: 0 | BS104: 0 | BT104: 0 | BU104: 0 | BV104: 0 | BW104: 0 | BX104: 0 | BY104: 0 | BZ104: 0 | CA104: 0 | CB104: 0 | CC104: 0 | CD104: 0 | CE104: 0 | CF104: 0 | CG104: 0 | CH104: 0 | CI104: 0 | CJ104: 0 | CK104: 0 | CL104: 0 | CM104: 0 | CN104: 0 | CO104: 0 | CP104: 0 | CQ104: 0 | CR104: 0 | CS104: 0 | CT104: 0 | CU104: 0 | CV104: 0 | CW104: 0 | CX104: 0 | CY104: 0 | CZ104: 0 | DA104: 0 | DB104: 0 | DC104: 0 | DD104: 0 | DE104: 0 | DF104: 0 | DG104: 0 | DH104: 0 | DI104: 0 | DJ104: 0 | DK104: 0 | DL104: 0 | DM104: 0 | DN104: 0 | DO104: 0 | DP104: 0 | DQ104: 0 | DR104: 0 | DS104: 0 | DT104: 0 | DU104: 0 | DV104: 0 | DW104: 0 | DX104: 0 | DY104: 0 | DZ104: 0 | EA104: 0 | EB104: 0 | EC104: 0 | ED104: 0 | EE104: 0 | EF104: 0 | EG104: 0 | EH104: 0 | EI104: 0 | EJ104: 0 | EK104: 0 | EL104: 0 | EM104: 0 | EN104: 0 | EO104: 0 | EP104: 0 | EQ104: 0 | ER104: 0 | ES104: 0 | ET104: 0 | EU104: 0 | EV104: 0 | EW104: 0 | EX104: 0 | EY104: 0 | EZ104: 0 | FA104: 0 | FB104: 0 | FC104: 0 | FD104: 0 | FE104: 0 | FF104: 0 | FG104: 0 | FH104: 0 | FI104: 0 | FJ104: 0 | FK104: 0 | FL104: 0 | FM104: 0 | FN104: 0 | FO104: 0 | FP104: 0 | FQ104: 0 | FR104: 0 | FS104: 0 | FT104: 0 | FU104: 0 | FV104: 0 | FW104: 0 | FX104: 0 | FY104: 0 | FZ104: 0 | GA104: 0 | GB104: 0 | GC104: 0 | GD104: 0 | GE104: 0 | GF104: 0 | GG104: 0 | GH104: 0 | GI104: 0 | GJ104: 0 | GK104: 0 | GL104: 0 | GM104: 0 | GN104: 0 | GO104: 0 | GP104: 0 | GQ104: 0
A105: 207 | B105: DELI CO PORK RASHER | C105: 2 | D105: 0 | E105: 0 | F105: 0 | G105: 0 | H105: 0 | I105: 0 | J105: 0 | K105: 0 | L105: 0 | M105: 0 | N105: 0 | O105: 0 | P105: 0 | Q105: 0 | R105: 0 | S105: 0 | T105: 0 | U105: 0 | V105: 0 | W105: 0 | X105: 0 | Y105: 0 | Z105: 0 | AA105: 0 | AB105: 0 | AC105: 0 | AD105: 0 | AE105: 0 | AF105: 0 | AG105: 0 | AH105: 0 | AI105: 0 | AJ105: 0 | AK105: 0 | AL105: 0 | AM105: 0 | AN105: 0 | AO105: 0 | AP105: 0 | AQ105: 0 | AR105: 0 | AS105: 0 | AT105: 0 | AU105: 0 | AV105: 0 | AW105: 0 | AX105: 0 | AY105: 0 | AZ105: 0 | BA105: 0 | BB105: 0 | BC105: 0 | BD105: 0 | BE105: 0 | BF105: 0 | BG105: 0 | BH105: 0 | BI105: 0 | BJ105: 0 | BK105: 0 | BL105: 0 | BM105: 0 | BN105: 0 | BO105: 0 | BP105: 0 | BQ105: 0 | BR105: 0 | BS105: 0 | BT105: 0 | BU105: 0 | BV105: 0 | BW105: 0 | BX105: 0 | BY105: 0 | BZ105: 0 | CA105: 0 | CB105: 0 | CC105: 0 | CD105: 0 | CE105: 0 | CF105: 0 | CG105: 0 | CH105: 0 | CI105: 0 | CJ105: 0 | CK105: 0 | CL105: 0 | CM105: 0 | CN105: 0 | CO105: 0 | CP105: 0 | CQ105: 0 | CR105: 0 | CS105: 0 | CT105: 0 | CU105: 0 | CV105: 0 | CW105: 0 | CX105: 0 | CY105: 0 | CZ105: 0 | DA105: 0 | DB105: 0 | DC105: 0 | DD105: 0 | DE105: 0 | DF105: 0 | DG105: 0 | DH105: 0 | DI105: 0 | DJ105: 0 | DK105: 0 | DL105: 0 | DM105: 0 | DN105: 0 | DO105: 0 | DP105: 0 | DQ105: 0 | DR105: 0 | DS105: 0 | DT105: 0 | DU105: 0 | DV105: 0 | DW105: 0 | DX105: 0 | DY105: 0 | DZ105: 0 | EA105: 0 | EB105: 0 | EC105: 0 | ED105: 0 | EE105: 0 | EF105: 0 | EG105: 0 | EH105: 0 | EI105: 0 | EJ105: 0 | EK105: 0 | EL105: 0 | EM105: 0 | EN105: 0 | EO105: 0 | EP105: 0 | EQ105: 0 | ER105: 0 | ES105: 0 | ET105: 0 | EU105: 0 | EV105: 0 | EW105: 0 | EX105: 0 | EY105: 0 | EZ105: 0 | FA105: 0 | FB105: 0 | FC105: 0 | FD105: 0 | FE105: 0 | FF105: 0 | FG105: 0 | FH105: 0 | FI105: 0 | FJ105: 0 | FK105: 0 | FL105: 0 | FM105: 0 | FN105: 0 | FO105: 0 | FP105: 0 | FQ105: 0 | FR105: 0 | FS105: 0 | FT105: 0 | FU105: 0 | FV105: 0 | FW105: 0 | FX105: 0 | FY105: 0 | FZ105: 0 | GA105: 0 | GB105: 0 | GC105: 0 | GD105: 0 | GE105: 0 | GF105: 0 | GG105: 0 | GH105: 0 | GI105: 0 | GJ105: 0 | GK105: 0 | GL105: 0 | GM105: 0 | GN105: 0 | GO105: 0 | GP105: 0 | GQ105: 0
