Workbook
Name WeeksList: #REF!

Sheet Data
A1: Data | E1: Average | G1: Totals | I1: 45656 | K1: 45809 | M1: 45670 | O1: 45677 | Q1: 45684 | S1: 45718 | U1: 45932 | W1: 45705 | Y1: 45712 | AA1: 45719 | AC1: 45933 | AE1: 45733 | AG1: 45740 | AI1: 45747 | AK1: 45842 | AM1: 45761 | AO1: 45768 | AQ1: 45775 | AS1: 45782 | AU1: 45996 | AW1: 45796 | AY1: 45803 | BA1: 45694 | BC1: 45906 | BE1: 45824 | BG1: 45831 | BI1: 45838 | BK1: 45845 | BM1: 45852 | BO1: 45859 | BQ1: 45866 | BS1: 45755 | BU1: 45969 | BW1: 45887 | BY1: 45894 | CA1: 45666 | CC1: 45878 | CE1: 45915 | CG1: 45922 | CI1: 45929 | CK1: 45818 | CM1: 45943 | CO1: 45950 | CQ1: 45957 | CS1: 45727 | CU1: 45941 | CW1: 45978 | CY1: 45985 | DA1: 45669 | DC1: 45881 | DE1: 46006 | DG1: 46013 | DI1: 46020 | DK1: 46027 | DM1: 46034 | DO1: 46041 | DQ1: 46048 | DS1: 46055 | DU1: 46062 | DW1: 46069 | DY1: 46076 | EA1: 46083 | EC1: 46090 | EE1: 46097 | EG1: 46104 | EI1: 46111 | EK1: 46118 | EM1: 46125 | EO1: 46132 | EQ1: 46139 | ES1: 46146
A2: > Sub-Department | C2: Product Code | D2: Product Description | E2: Sales excl. VAT | F2: Sales Quantity | G2: Sales excl. VAT | H2: Sales Quantity | I2: Sales excl. VAT | J2: Sales Quantity | K2: Sales excl. VAT | L2: Sales Quantity | M2: Sales excl. VAT | N2: Sales Quantity | O2: Sales excl. VAT | P2: Sales Quantity | Q2: Sales excl. VAT | R2: Sales Quantity | S2: Sales excl. VAT | T2: Sales Quantity | U2: Sales excl. VAT | V2: Sales Quantity | W2: Sales excl. VAT | X2: Sales Quantity | Y2: Sales excl. VAT | Z2: Sales Quantity | AA2: Sales excl. VAT | AB2: Sales Quantity | AC2: Sales excl. VAT | AD2: Sales Quantity | AE2: Sales excl. VAT | AF2: Sales Quantity | AG2: Sales excl. VAT | AH2: Sales Quantity | AI2: Sales excl. VAT | AJ2: Sales Quantity | AK2: Sales excl. VAT | AL2: Sales Quantity | AM2: Sales excl. VAT | AN2: Sales Quantity | AO2: Sales excl. VAT | AP2: Sales Quantity | AQ2: Sales excl. VAT | AR2: Sales Quantity | AS2: Sales excl. VAT | AT2: Sales Quantity | AU2: Sales excl. VAT | AV2: Sales Quantity | AW2: Sales excl. VAT | AX2: Sales Quantity | AY2: Sales excl. VAT | AZ2: Sales Quantity | BA2: Sales excl. VAT | BB2: Sales Quantity | BC2: Sales excl. VAT | BD2: Sales Quantity | BE2: Sales excl. VAT | BF2: Sales Quantity | BG2: Sales excl. VAT | BH2: Sales Quantity | BI2: Sales excl. VAT | BJ2: Sales Quantity | BK2: Sales excl. VAT | BL2: Sales Quantity | BM2: Sales excl. VAT | BN2: Sales Quantity | BO2: Sales excl. VAT | BP2: Sales Quantity | BQ2: Sales excl. VAT | BR2: Sales Quantity | BS2: Sales excl. VAT | BT2: Sales Quantity | BU2: Sales excl. VAT | BV2: Sales Quantity | BW2: Sales excl. VAT | BX2: Sales Quantity | BY2: Sales excl. VAT | BZ2: Sales Quantity | CA2: Sales excl. VAT | CB2: Sales Quantity | CC2: Sales excl. VAT | CD2: Sales Quantity | CE2: Sales excl. VAT | CF2: Sales Quantity | CG2: Sales excl. VAT | CH2: Sales Quantity | CI2: Sales excl. VAT | CJ2: Sales Quantity | CK2: Sales excl. VAT | CL2: Sales Quantity | CM2: Sales excl. VAT | CN2: Sales Quantity | CO2: Sales excl. VAT | CP2: Sales Quantity | CQ2: Sales excl. VAT | CR2: Sales Quantity | CS2: Sales excl. VAT | CT2: Sales Quantity | CU2: Sales excl. VAT | CV2: Sales Quantity | CW2: Sales excl. VAT | CX2: Sales Quantity | CY2: Sales excl. VAT | CZ2: Sales Quantity | DA2: Sales excl. VAT | DB2: Sales Quantity | DC2: Sales excl. VAT | DD2: Sales Quantity | DE2: Sales excl. VAT | DF2: Sales Quantity | DG2: Sales excl. VAT | DH2: Sales Quantity | DI2: Sales excl. VAT | DJ2: Sales Quantity | DK2: Sales excl. VAT | DL2: Sales Quantity | DM2: Sales excl. VAT | DN2: Sales Quantity | DO2: Sales excl. VAT | DP2: Sales Quantity | DQ2: Sales excl. VAT | DR2: Sales Quantity | DS2: Sales excl. VAT | DT2: Sales Quantity | DU2: Sales excl. VAT | DV2: Sales Quantity | DW2: Sales excl. VAT | DX2: Sales Quantity | DY2: Sales excl. VAT | DZ2: Sales Quantity | EA2: Sales excl. VAT | EB2: Sales Quantity | EC2: Sales excl. VAT | ED2: Sales Quantity | EE2: Sales excl. VAT | EF2: Sales Quantity | EG2: Sales excl. VAT | EH2: Sales Quantity | EI2: Sales excl. VAT | EJ2: Sales Quantity | EK2: Sales excl. VAT | EL2: Sales Quantity | EM2: Sales excl. VAT | EN2: Sales Quantity | EO2: Sales excl. VAT | EP2: Sales Quantity | EQ2: Sales excl. VAT | ER2: Sales Quantity | ES2: Sales excl. VAT | ET2: Sales Quantity
A3: 201 | B3: =LOOKUP(A3,Lookup!$A$1:$A$34,Lookup!$B$1:$B$34) -> BUTCHERY | C3: 11141 | D3: SPAR SLT PORK SPARERIB | E3: 0 | F3: 0 | G3: 0 | H3: 0 | I3: 0 | J3: 0 | K3: 0 | L3: 0 | M3: 0 | N3: 0 | O3: 0 | P3: 0 | Q3: 0 | R3: 0 | S3: 0 | T3: 0 | U3: 0 | V3: 0 | W3: 0 | X3: 0 | Y3: 0 | Z3: 0 | AA3: 0 | AB3: 0 | AC3: 0 | AD3: 0 | AE3: 0 | AF3: 0 | AG3: 0 | AH3: 0 | AI3: 0 | AJ3: 0 | AK3: 0 | AL3: 0 | AM3: 0 | AN3: 0 | AO3: 0 | AP3: 0 | AQ3: 0 | AR3: 0 | AS3: 0 | AT3: 0 | AU3: 0 | AV3: 0 | AW3: 0 | AX3: 0 | AY3: 0 | AZ3: 0 | BA3: 0 | BB3: 0 | BC3: 0 | BD3: 0 | BE3: 0 | BF3: 0 | BG3: 0 | BH3: 0 | BI3: 0 | BJ3: 0 | BK3: 0 | BL3: 0 | BM3: 0 | BN3: 0 | BO3: 0 | BP3: 0 | BQ3: 0 | BR3: 0 | BS3: 0 | BT3: 0 | BU3: 0 | BV3: 0 | BW3: 0 | BX3: 0 | BY3: 0 | BZ3: 0 | CA3: 0 | CB3: 0 | CC3: 0 | CD3: 0 | CE3: 0 | CF3: 0 | CG3: 0 | CH3: 0 | CI3: 0 | CJ3: 0 | CK3: 0 | CL3: 0 | CM3: 0 | CN3: 0 | CO3: 0 | CP3: 0 | CQ3: 0 | CR3: 0 | CS3: 0 | CT3: 0 | CU3: 0 | CV3: 0 | CW3: 0 | CX3: 0 | CY3: 0 | CZ3: 0 | DA3: 0 | DB3: 0 | DC3: 0 | DD3: 0 | DE3: 0 | DF3: 0 | DG3: 0 | DH3: 0 | DI3: 0 | DJ3: 0 | DK3: 0 | DL3: 0 | DM3: 0 | DN3: 0 | DO3: 0 | DP3: 0 | DQ3: 0 | DR3: 0 | DS3: 0 | DT3: 0 | DU3: 0 | DV3: 0 | DW3: 0 | DX3: 0 | DY3: 0 | DZ3: 0 | EA3: 0 | EB3: 0 | EC3: 0 | ED3: 0 | EE3: 0 | EF3: 0 | EG3: 0 | EH3: 0 | EI3: 0 | EJ3: 0 | EK3: 0 | EL3: 0 | EM3: 0 | EN3: 0 | EO3: 0 | EP3: 0 | EQ3: 0 | ER3: 0 | ES3: 0 | ET3: 0
A4: 201 | B4: =LOOKUP(A4,Lookup!$A$1:$A$34,Lookup!$B$1:$B$34) -> BUTCHERY | C4: 11385 | D4: ETLIN RIBS PORK SPARE FRZ | E4: 0 | F4: 0 | G4: 0 | H4: 0 | I4: 0 | J4: 0 | K4: 0 | L4: 0 | M4: 0 | N4: 0 | O4: 0 | P4: 0 | Q4: 0 | R4: 0 | S4: 0 | T4: 0 | U4: 0 | V4: 0 | W4: 0 | X4: 0 | Y4: 0 | Z4: 0 | AA4: 0 | AB4: 0 | AC4: 0 | AD4: 0 | AE4: 0 | AF4: 0 | AG4: 0 | AH4: 0 | AI4: 0 | AJ4: 0 | AK4: 0 | AL4: 0 | AM4: 0 | AN4: 0 | AO4: 0 | AP4: 0 | AQ4: 0 | AR4: 0 | AS4: 0 | AT4: 0 | AU4: 0 | AV4: 0 | AW4: 0 | AX4: 0 | AY4: 0 | AZ4: 0 | BA4: 0 | BB4: 0 | BC4: 0 | BD4: 0 | BE4: 0 | BF4: 0 | BG4: 0 | BH4: 0 | BI4: 0 | BJ4: 0 | BK4: 0 | BL4: 0 | BM4: 0 | BN4: 0 | BO4: 0 | BP4: 0 | BQ4: 0 | BR4: 0 | BS4: 0 | BT4: 0 | BU4: 0 | BV4: 0 | BW4: 0 | BX4: 0 | BY4: 0 | BZ4: 0 | CA4: 0 | CB4: 0 | CC4: 0 | CD4: 0 | CE4: 0 | CF4: 0 | CG4: 0 | CH4: 0 | CI4: 0 | CJ4: 0 | CK4: 0 | CL4: 0 | CM4: 0 | CN4: 0 | CO4: 0 | CP4: 0 | CQ4: 0 | CR4: 0 | CS4: 0 | CT4: 0 | CU4: 0 | CV4: 0 | CW4: 0 | CX4: 0 | CY4: 0 | CZ4: 0 | DA4: 0 | DB4: 0 | DC4: 0 | DD4: 0 | DE4: 0 | DF4: 0 | DG4: 0 | DH4: 0 | DI4: 0 | DJ4: 0 | DK4: 0 | DL4: 0 | DM4: 0 | DN4: 0 | DO4: 0 | DP4: 0 | DQ4: 0 | DR4: 0 | DS4: 0 | DT4: 0 | DU4: 0 | DV4: 0 | DW4: 0 | DX4: 0 | DY4: 0 | DZ4: 0 | EA4: 0 | EB4: 0 | EC4: 0 | ED4: 0 | EE4: 0 | EF4: 0 | EG4: 0 | EH4: 0 | EI4: 0 | EJ4: 0 | EK4: 0 | EL4: 0 | EM4: 0 | EN4: 0 | EO4: 0 | EP4: 0 | EQ4: 0 | ER4: 0 | ES4: 0 | ET4: 0
A5: 201 | B5: =LOOKUP(A5,Lookup!$A$1:$A$34,Lookup!$B$1:$B$34) -> BUTCHERY | C5: 11388 | D5: ETLIN CHIC SAHA MDM | E5: 0 | F5: 0 | G5: 0 | H5: 0 | I5: 0 | J5: 0 | K5: 0 | L5: 0 | M5: 0 | N5: 0 | O5: 0 | P5: 0 | Q5: 0 | R5: 0 | S5: 0 | T5: 0 | U5: 0 | V5: 0 | W5: 0 | X5: 0 | Y5: 0 | Z5: 0 | AA5: 0 | AB5: 0 | AC5: 0 | AD5: 0 | AE5: 0 | AF5: 0 | AG5: 0 | AH5: 0 | AI5: 0 | AJ5: 0 | AK5: 0 | AL5: 0 | AM5: 0 | AN5: 0 | AO5: 0 | AP5: 0 | AQ5: 0 | AR5: 0 | AS5: 0 | AT5: 0 | AU5: 0 | AV5: 0 | AW5: 0 | AX5: 0 | AY5: 0 | AZ5: 0 | BA5: 0 | BB5: 0 | BC5: 0 | BD5: 0 | BE5: 0 | BF5: 0 | BG5: 0 | BH5: 0 | BI5: 0 | BJ5: 0 | BK5: 0 | BL5: 0 | BM5: 0 | BN5: 0 | BO5: 0 | BP5: 0 | BQ5: 0 | BR5: 0 | BS5: 0 | BT5: 0 | BU5: 0 | BV5: 0 | BW5: 0 | BX5: 0 | BY5: 0 | BZ5: 0 | CA5: 0 | CB5: 0 | CC5: 0 | CD5: 0 | CE5: 0 | CF5: 0 | CG5: 0 | CH5: 0 | CI5: 0 | CJ5: 0 | CK5: 0 | CL5: 0 | CM5: 0 | CN5: 0 | CO5: 0 | CP5: 0 | CQ5: 0 | CR5: 0 | CS5: 0 | CT5: 0 | CU5: 0 | CV5: 0 | CW5: 0 | CX5: 0 | CY5: 0 | CZ5: 0 | DA5: 0 | DB5: 0 | DC5: 0 | DD5: 0 | DE5: 0 | DF5: 0 | DG5: 0 | DH5: 0 | DI5: 0 | DJ5: 0 | DK5: 0 | DL5: 0 | DM5: 0 | DN5: 0 | DO5: 0 | DP5: 0 | DQ5: 0 | DR5: 0 | DS5: 0 | DT5: 0 | DU5: 0 | DV5: 0 | DW5: 0 | DX5: 0 | DY5: 0 | DZ5: 0 | EA5: 0 | EB5: 0 | EC5: 0 | ED5: 0 | EE5: 0 | EF5: 0 | EG5: 0 | EH5: 0 | EI5: 0 | EJ5: 0 | EK5: 0 | EL5: 0 | EM5: 0 | EN5: 0 | EO5: 0 | EP5: 0 | EQ5: 0 | ER5: 0 | ES5: 0 | ET5: 0
A6: 201 | B6: =LOOKUP(A6,Lookup!$A$1:$A$34,Lookup!$B$1:$B$34) -> BUTCHERY | C6: 12151 | D6: SPAR SLT BEEF CHUCK B/IN | E6: 0 | F6: 0 | G6: 0 | H6: 0 | I6: 0 | J6: 0 | K6: 0 | L6: 0 | M6: 0 | N6: 0 | O6: 0 | P6: 0 | Q6: 0 | R6: 0 | S6: 0 | T6: 0 | U6: 0 | V6: 0 | W6: 0 | X6: 0 | Y6: 0 | Z6: 0 | AA6: 0 | AB6: 0 | AC6: 0 | AD6: 0 | AE6: 0 | AF6: 0 | AG6: 0 | AH6: 0 | AI6: 0 | AJ6: 0 | AK6: 0 | AL6: 0 | AM6: 0 | AN6: 0 | AO6: 0 | AP6: 0 | AQ6: 0 | AR6: 0 | AS6: 0 | AT6: 0 | AU6: 0 | AV6: 0 | AW6: 0 | AX6: 0 | AY6: 0 | AZ6: 0 | BA6: 0 | BB6: 0 | BC6: 0 | BD6: 0 | BE6: 0 | BF6: 0 | BG6: 0 | BH6: 0 | BI6: 0 | BJ6: 0 | BK6: 0 | BL6: 0 | BM6: 0 | BN6: 0 | BO6: 0 | BP6: 0 | BQ6: 0 | BR6: 0 | BS6: 0 | BT6: 0 | BU6: 0 | BV6: 0 | BW6: 0 | BX6: 0 | BY6: 0 | BZ6: 0 | CA6: 0 | CB6: 0 | CC6: 0 | CD6: 0 | CE6: 0 | CF6: 0 | CG6: 0 | CH6: 0 | CI6: 0 | CJ6: 0 | CK6: 0 | CL6: 0 | CM6: 0 | CN6: 0 | CO6: 0 | CP6: 0 | CQ6: 0 | CR6: 0 | CS6: 0 | CT6: 0 | CU6: 0 | CV6: 0 | CW6: 0 | CX6: 0 | CY6: 0 | CZ6: 0 | DA6: 0 | DB6: 0 | DC6: 0 | DD6: 0 | DE6: 0 | DF6: 0 | DG6: 0 | DH6: 0 | DI6: 0 | DJ6: 0 | DK6: 0 | DL6: 0 | DM6: 0 | DN6: 0 | DO6: 0 | DP6: 0 | DQ6: 0 | DR6: 0 | DS6: 0 | DT6: 0 | DU6: 0 | DV6: 0 | DW6: 0 | DX6: 0 | DY6: 0 | DZ6: 0 | EA6: 0 | EB6: 0 | EC6: 0 | ED6: 0 | EE6: 0 | EF6: 0 | EG6: 0 | EH6: 0 | EI6: 0 | EJ6: 0 | EK6: 0 | EL6: 0 | EM6: 0 | EN6: 0 | EO6: 0 | EP6: 0 | EQ6: 0 | ER6: 0 | ES6: 0 | ET6: 0
A7: 201 | B7: =LOOKUP(A7,Lookup!$A$1:$A$34,Lookup!$B$1:$B$34) -> BUTCHERY | C7: 12194 | D7: SPAR T&T GAMMON/TONGUE | E7: 6.8259645 | F7: 0.063 | G7: 484.64348 | H7: 4.459 | I7: 0 | J7: 0 | K7: 0 | L7: 0 | M7: 0 | N7: 0 | O7: 0 | P7: 0 | Q7: 0 | R7: 0 | S7: 0 | T7: 0 | U7: 0 | V7: 0 | W7: 0 | X7: 0 | Y7: 0 | Z7: 0 | AA7: 0 | AB7: 0 | AC7: 0 | AD7: 0 | AE7: 0 | AF7: 0 | AG7: 0 | AH7: 0 | AI7: 0 | AJ7: 0 | AK7: 0 | AL7: 0 | AM7: 0 | AN7: 0 | AO7: 0 | AP7: 0 | AQ7: 0 | AR7: 0 | AS7: 0 | AT7: 0 | AU7: 0 | AV7: 0 | AW7: 0 | AX7: 0 | AY7: 0 | AZ7: 0 | BA7: 0 | BB7: 0 | BC7: 0 | BD7: 0 | BE7: 0 | BF7: 0 | BG7: 0 | BH7: 0 | BI7: 0 | BJ7: 0 | BK7: 0 | BL7: 0 | BM7: 0 | BN7: 0 | BO7: 0 | BP7: 0 | BQ7: 0 | BR7: 0 | BS7: 0 | BT7: 0 | BU7: 0 | BV7: 0 | BW7: 0 | BX7: 0 | BY7: 0 | BZ7: 0 | CA7: 0 | CB7: 0 | CC7: 0 | CD7: 0 | CE7: 0 | CF7: 0 | CG7: 0 | CH7: 0 | CI7: 0 | CJ7: 0 | CK7: 0 | CL7: 0 | CM7: 0 | CN7: 0 | CO7: 0 | CP7: 0 | CQ7: 0 | CR7: 0 | CS7: 0 | CT7: 0 | CU7: 0 | CV7: 0 | CW7: 0 | CX7: 0 | CY7: 0 | CZ7: 0 | DA7: 484.64348 | DB7: 4.459 | DC7: 0 | DD7: 0 | DE7: 0 | DF7: 0 | DG7: 0 | DH7: 0 | DI7: 0 | DJ7: 0 | DK7: 0 | DL7: 0 | DM7: 0 | DN7: 0 | DO7: 0 | DP7: 0 | DQ7: 0 | DR7: 0 | DS7: 0 | DT7: 0 | DU7: 0 | DV7: 0 | DW7: 0 | DX7: 0 | DY7: 0 | DZ7: 0 | EA7: 0 | EB7: 0 | EC7: 0 | ED7: 0 | EE7: 0 | EF7: 0 | EG7: 0 | EH7: 0 | EI7: 0 | EJ7: 0 | EK7: 0 | EL7: 0 | EM7: 0 | EN7: 0 | EO7: 0 | EP7: 0 | EQ7: 0 | ER7: 0 | ES7: 0 | ET7: 0
A8: 201 | B8: =LOOKUP(A8,Lookup!$A$1:$A$34,Lookup!$B$1:$B$34) -> BUTCHERY | C8: 12314 | D8: T&T TONGUE/GAMON BOX | E8: 0 | F8: 0 | G8: 0 | H8: 0 | I8: 0 | J8: 0 | K8: 0 | L8: 0 | M8: 0 | N8: 0 | O8: 0 | P8: 0 | Q8: 0 | R8: 0 | S8: 0 | T8: 0 | U8: 0 | V8: 0 | W8: 0 | X8: 0 | Y8: 0 | Z8: 0 | AA8: 0 | AB8: 0 | AC8: 0 | AD8: 0 | AE8: 0 | AF8: 0 | AG8: 0 | AH8: 0 | AI8: 0 | AJ8: 0 | AK8: 0 | AL8: 0 | AM8: 0 | AN8: 0 | AO8: 0 | AP8: 0 | AQ8: 0 | AR8: 0 | AS8: 0 | AT8: 0 | AU8: 0 | AV8: 0 | AW8: 0 | AX8: 0 | AY8: 0 | AZ8: 0 | BA8: 0 | BB8: 0 | BC8: 0 | BD8: 0 | BE8: 0 | BF8: 0 | BG8: 0 | BH8: 0 | BI8: 0 | BJ8: 0 | BK8: 0 | BL8: 0 | BM8: 0 | BN8: 0 | BO8: 0 | BP8: 0 | BQ8: 0 | BR8: 0 | BS8: 0 | BT8: 0 | BU8: 0 | BV8: 0 | BW8: 0 | BX8: 0 | BY8: 0 | BZ8: 0 | CA8: 0 | CB8: 0 | CC8: 0 | CD8: 0 | CE8: 0 | CF8: 0 | CG8: 0 | CH8: 0 | CI8: 0 | CJ8: 0 | CK8: 0 | CL8: 0 | CM8: 0 | CN8: 0 | CO8: 0 | CP8: 0 | CQ8: 0 | CR8: 0 | CS8: 0 | CT8: 0 | CU8: 0 | CV8: 0 | CW8: 0 | CX8: 0 | CY8: 0 | CZ8: 0 | DA8: 0 | DB8: 0 | DC8: 0 | DD8: 0 | DE8: 0 | DF8: 0 | DG8: 0 | DH8: 0 | DI8: 0 | DJ8: 0 | DK8: 0 | DL8: 0 | DM8: 0 | DN8: 0 | DO8: 0 | DP8: 0 | DQ8: 0 | DR8: 0 | DS8: 0 | DT8: 0 | DU8: 0 | DV8: 0 | DW8: 0 | DX8: 0 | DY8: 0 | DZ8: 0 | EA8: 0 | EB8: 0 | EC8: 0 | ED8: 0 | EE8: 0 | EF8: 0 | EG8: 0 | EH8: 0 | EI8: 0 | EJ8: 0 | EK8: 0 | EL8: 0 | EM8: 0 | EN8: 0 | EO8: 0 | EP8: 0 | EQ8: 0 | ER8: 0 | ES8: 0 | ET8: 0
A9: 201 | B9: =LOOKUP(A9,Lookup!$A$1:$A$34,Lookup!$B$1:$B$34) -> BUTCHERY | C9: 15219 | D9: SPAR SLT LAMB LEG | E9: 0 | F9: 0 | G9: 0 | H9: 0 | I9: 0 | J9: 0 | K9: 0 | L9: 0 | M9: 0 | N9: 0 | O9: 0 | P9: 0 | Q9: 0 | R9: 0 | S9: 0 | T9: 0 | U9: 0 | V9: 0 | W9: 0 | X9: 0 | Y9: 0 | Z9: 0 | AA9: 0 | AB9: 0 | AC9: 0 | AD9: 0 | AE9: 0 | AF9: 0 | AG9: 0 | AH9: 0 | AI9: 0 | AJ9: 0 | AK9: 0 | AL9: 0 | AM9: 0 | AN9: 0 | AO9: 0 | AP9: 0 | AQ9: 0 | AR9: 0 | AS9: 0 | AT9: 0 | AU9: 0 | AV9: 0 | AW9: 0 | AX9: 0 | AY9: 0 | AZ9: 0 | BA9: 0 | BB9: 0 | BC9: 0 | BD9: 0 | BE9: 0 | BF9: 0 | BG9: 0 | BH9: 0 | BI9: 0 | BJ9: 0 | BK9: 0 | BL9: 0 | BM9: 0 | BN9: 0 | BO9: 0 | BP9: 0 | BQ9: 0 | BR9: 0 | BS9: 0 | BT9: 0 | BU9: 0 | BV9: 0 | BW9: 0 | BX9: 0 | BY9: 0 | BZ9: 0 | CA9: 0 | CB9: 0 | CC9: 0 | CD9: 0 | CE9: 0 | CF9: 0 | CG9: 0 | CH9: 0 | CI9: 0 | CJ9: 0 | CK9: 0 | CL9: 0 | CM9: 0 | CN9: 0 | CO9: 0 | CP9: 0 | CQ9: 0 | CR9: 0 | CS9: 0 | CT9: 0 | CU9: 0 | CV9: 0 | CW9: 0 | CX9: 0 | CY9: 0 | CZ9: 0 | DA9: 0 | DB9: 0 | DC9: 0 | DD9: 0 | DE9: 0 | DF9: 0 | DG9: 0 | DH9: 0 | DI9: 0 | DJ9: 0 | DK9: 0 | DL9: 0 | DM9: 0 | DN9: 0 | DO9: 0 | DP9: 0 | DQ9: 0 | DR9: 0 | DS9: 0 | DT9: 0 | DU9: 0 | DV9: 0 | DW9: 0 | DX9: 0 | DY9: 0 | DZ9: 0 | EA9: 0 | EB9: 0 | EC9: 0 | ED9: 0 | EE9: 0 | EF9: 0 | EG9: 0 | EH9: 0 | EI9: 0 | EJ9: 0 | EK9: 0 | EL9: 0 | EM9: 0 | EN9: 0 | EO9: 0 | EP9: 0 | EQ9: 0 | ER9: 0 | ES9: 0 | ET9: 0
A10: 201 | B10: =LOOKUP(A10,Lookup!$A$1:$A$34,Lookup!$B$1:$B$34) -> BUTCHERY | C10: 15227 | D10: SPAR SLT LAMB SHOULDER | E10: 0 | F10: 0 | G10: 0 | H10: 0 | I10: 0 | J10: 0 | K10: 0 | L10: 0 | M10: 0 | N10: 0 | O10: 0 | P10: 0 | Q10: 0 | R10: 0 | S10: 0 | T10: 0 | U10: 0 | V10: 0 | W10: 0 | X10: 0 | Y10: 0 | Z10: 0 | AA10: 0 | AB10: 0 | AC10: 0 | AD10: 0 | AE10: 0 | AF10: 0 | AG10: 0 | AH10: 0 | AI10: 0 | AJ10: 0 | AK10: 0 | AL10: 0 | AM10: 0 | AN10: 0 | AO10: 0 | AP10: 0 | AQ10: 0 | AR10: 0 | AS10: 0 | AT10: 0 | AU10: 0 | AV10: 0 | AW10: 0 | AX10: 0 | AY10: 0 | AZ10: 0 | BA10: 0 | BB10: 0 | BC10: 0 | BD10: 0 | BE10: 0 | BF10: 0 | BG10: 0 | BH10: 0 | BI10: 0 | BJ10: 0 | BK10: 0 | BL10: 0 | BM10: 0 | BN10: 0 | BO10: 0 | BP10: 0 | BQ10: 0 | BR10: 0 | BS10: 0 | BT10: 0 | BU10: 0 | BV10: 0 | BW10: 0 | BX10: 0 | BY10: 0 | BZ10: 0 | CA10: 0 | CB10: 0 | CC10: 0 | CD10: 0 | CE10: 0 | CF10: 0 | CG10: 0 | CH10: 0 | CI10: 0 | CJ10: 0 | CK10: 0 | CL10: 0 | CM10: 0 | CN10: 0 | CO10: 0 | CP10: 0 | CQ10: 0 | CR10: 0 | CS10: 0 | CT10: 0 | CU10: 0 | CV10: 0 | CW10: 0 | CX10: 0 | CY10: 0 | CZ10: 0 | DA10: 0 | DB10: 0 | DC10: 0 | DD10: 0 | DE10: 0 | DF10: 0 | DG10: 0 | DH10: 0 | DI10: 0 | DJ10: 0 | DK10: 0 | DL10: 0 | DM10: 0 | DN10: 0 | DO10: 0 | DP10: 0 | DQ10: 0 | DR10: 0 | DS10: 0 | DT10: 0 | DU10: 0 | DV10: 0 | DW10: 0 | DX10: 0 | DY10: 0 | DZ10: 0 | EA10: 0 | EB10: 0 | EC10: 0 | ED10: 0 | EE10: 0 | EF10: 0 | EG10: 0 | EH10: 0 | EI10: 0 | EJ10: 0 | EK10: 0 | EL10: 0 | EM10: 0 | EN10: 0 | EO10: 0 | EP10: 0 | EQ10: 0 | ER10: 0 | ES10: 0 | ET10: 0
A11: 201 | B11: =LOOKUP(A11,Lookup!$A$1:$A$34,Lookup!$B$1:$B$34) -> BUTCHERY | C11: 34176 | D11: BEEF STEAK BURGER | E11: 0 | F11: 0 | G11: 0 | H11: 0 | I11: 0 | J11: 0 | K11: 0 | L11: 0 | M11: 0 | N11: 0 | O11: 0 | P11: 0 | Q11: 0 | R11: 0 | S11: 0 | T11: 0 | U11: 0 | V11: 0 | W11: 0 | X11: 0 | Y11: 0 | Z11: 0 | AA11: 0 | AB11: 0 | AC11: 0 | AD11: 0 | AE11: 0 | AF11: 0 | AG11: 0 | AH11: 0 | AI11: 0 | AJ11: 0 | AK11: 0 | AL11: 0 | AM11: 0 | AN11: 0 | AO11: 0 | AP11: 0 | AQ11: 0 | AR11: 0 | AS11: 0 | AT11: 0 | AU11: 0 | AV11: 0 | AW11: 0 | AX11: 0 | AY11: 0 | AZ11: 0 | BA11: 0 | BB11: 0 | BC11: 0 | BD11: 0 | BE11: 0 | BF11: 0 | BG11: 0 | BH11: 0 | BI11: 0 | BJ11: 0 | BK11: 0 | BL11: 0 | BM11: 0 | BN11: 0 | BO11: 0 | BP11: 0 | BQ11: 0 | BR11: 0 | BS11: 0 | BT11: 0 | BU11: 0 | BV11: 0 | BW11: 0 | BX11: 0 | BY11: 0 | BZ11: 0 | CA11: 0 | CB11: 0 | CC11: 0 | CD11: 0 | CE11: 0 | CF11: 0 | CG11: 0 | CH11: 0 | CI11: 0 | CJ11: 0 | CK11: 0 | CL11: 0 | CM11: 0 | CN11: 0 | CO11: 0 | CP11: 0 | CQ11: 0 | CR11: 0 | CS11: 0 | CT11: 0 | CU11: 0 | CV11: 0 | CW11: 0 | CX11: 0 | CY11: 0 | CZ11: 0 | DA11: 0 | DB11: 0 | DC11: 0 | DD11: 0 | DE11: 0 | DF11: 0 | DG11: 0 | DH11: 0 | DI11: 0 | DJ11: 0 | DK11: 0 | DL11: 0 | DM11: 0 | DN11: 0 | DO11: 0 | DP11: 0 | DQ11: 0 | DR11: 0 | DS11: 0 | DT11: 0 | DU11: 0 | DV11: 0 | DW11: 0 | DX11: 0 | DY11: 0 | DZ11: 0 | EA11: 0 | EB11: 0 | EC11: 0 | ED11: 0 | EE11: 0 | EF11: 0 | EG11: 0 | EH11: 0 | EI11: 0 | EJ11: 0 | EK11: 0 | EL11: 0 | EM11: 0 | EN11: 0 | EO11: 0 | EP11: 0 | EQ11: 0 | ER11: 0 | ES11: 0 | ET11: 0
A12: 201 | B12: =LOOKUP(A12,Lookup!$A$1:$A$34,Lookup!$B$1:$B$34) -> BUTCHERY | C12: 34233 | D12: GAMMON BONELESS | E12: 0 | F12: 0 | G12: 0 | H12: 0 | I12: 0 | J12: 0 | K12: 0 | L12: 0 | M12: 0 | N12: 0 | O12: 0 | P12: 0 | Q12: 0 | R12: 0 | S12: 0 | T12: 0 | U12: 0 | V12: 0 | W12: 0 | X12: 0 | Y12: 0 | Z12: 0 | AA12: 0 | AB12: 0 | AC12: 0 | AD12: 0 | AE12: 0 | AF12: 0 | AG12: 0 | AH12: 0 | AI12: 0 | AJ12: 0 | AK12: 0 | AL12: 0 | AM12: 0 | AN12: 0 | AO12: 0 | AP12: 0 | AQ12: 0 | AR12: 0 | AS12: 0 | AT12: 0 | AU12: 0 | AV12: 0 | AW12: 0 | AX12: 0 | AY12: 0 | AZ12: 0 | BA12: 0 | BB12: 0 | BC12: 0 | BD12: 0 | BE12: 0 | BF12: 0 | BG12: 0 | BH12: 0 | BI12: 0 | BJ12: 0 | BK12: 0 | BL12: 0 | BM12: 0 | BN12: 0 | BO12: 0 | BP12: 0 | BQ12: 0 | BR12: 0 | BS12: 0 | BT12: 0 | BU12: 0 | BV12: 0 | BW12: 0 | BX12: 0 | BY12: 0 | BZ12: 0 | CA12: 0 | CB12: 0 | CC12: 0 | CD12: 0 | CE12: 0 | CF12: 0 | CG12: 0 | CH12: 0 | CI12: 0 | CJ12: 0 | CK12: 0 | CL12: 0 | CM12: 0 | CN12: 0 | CO12: 0 | CP12: 0 | CQ12: 0 | CR12: 0 | CS12: 0 | CT12: 0 | CU12: 0 | CV12: 0 | CW12: 0 | CX12: 0 | CY12: 0 | CZ12: 0 | DA12: 0 | DB12: 0 | DC12: 0 | DD12: 0 | DE12: 0 | DF12: 0 | DG12: 0 | DH12: 0 | DI12: 0 | DJ12: 0 | DK12: 0 | DL12: 0 | DM12: 0 | DN12: 0 | DO12: 0 | DP12: 0 | DQ12: 0 | DR12: 0 | DS12: 0 | DT12: 0 | DU12: 0 | DV12: 0 | DW12: 0 | DX12: 0 | DY12: 0 | DZ12: 0 | EA12: 0 | EB12: 0 | EC12: 0 | ED12: 0 | EE12: 0 | EF12: 0 | EG12: 0 | EH12: 0 | EI12: 0 | EJ12: 0 | EK12: 0 | EL12: 0 | EM12: 0 | EN12: 0 | EO12: 0 | EP12: 0 | EQ12: 0 | ER12: 0 | ES12: 0 | ET12: 0
A13: 201 | B13: =LOOKUP(A13,Lookup!$A$1:$A$34,Lookup!$B$1:$B$34) -> BUTCHERY | C13: 34234 | D13: GAMMON STEAKS | E13: 0 | F13: 0 | G13: 0 | H13: 0 | I13: 0 | J13: 0 | K13: 0 | L13: 0 | M13: 0 | N13: 0 | O13: 0 | P13: 0 | Q13: 0 | R13: 0 | S13: 0 | T13: 0 | U13: 0 | V13: 0 | W13: 0 | X13: 0 | Y13: 0 | Z13: 0 | AA13: 0 | AB13: 0 | AC13: 0 | AD13: 0 | AE13: 0 | AF13: 0 | AG13: 0 | AH13: 0 | AI13: 0 | AJ13: 0 | AK13: 0 | AL13: 0 | AM13: 0 | AN13: 0 | AO13: 0 | AP13: 0 | AQ13: 0 | AR13: 0 | AS13: 0 | AT13: 0 | AU13: 0 | AV13: 0 | AW13: 0 | AX13: 0 | AY13: 0 | AZ13: 0 | BA13: 0 | BB13: 0 | BC13: 0 | BD13: 0 | BE13: 0 | BF13: 0 | BG13: 0 | BH13: 0 | BI13: 0 | BJ13: 0 | BK13: 0 | BL13: 0 | BM13: 0 | BN13: 0 | BO13: 0 | BP13: 0 | BQ13: 0 | BR13: 0 | BS13: 0 | BT13: 0 | BU13: 0 | BV13: 0 | BW13: 0 | BX13: 0 | BY13: 0 | BZ13: 0 | CA13: 0 | CB13: 0 | CC13: 0 | CD13: 0 | CE13: 0 | CF13: 0 | CG13: 0 | CH13: 0 | CI13: 0 | CJ13: 0 | CK13: 0 | CL13: 0 | CM13: 0 | CN13: 0 | CO13: 0 | CP13: 0 | CQ13: 0 | CR13: 0 | CS13: 0 | CT13: 0 | CU13: 0 | CV13: 0 | CW13: 0 | CX13: 0 | CY13: 0 | CZ13: 0 | DA13: 0 | DB13: 0 | DC13: 0 | DD13: 0 | DE13: 0 | DF13: 0 | DG13: 0 | DH13: 0 | DI13: 0 | DJ13: 0 | DK13: 0 | DL13: 0 | DM13: 0 | DN13: 0 | DO13: 0 | DP13: 0 | DQ13: 0 | DR13: 0 | DS13: 0 | DT13: 0 | DU13: 0 | DV13: 0 | DW13: 0 | DX13: 0 | DY13: 0 | DZ13: 0 | EA13: 0 | EB13: 0 | EC13: 0 | ED13: 0 | EE13: 0 | EF13: 0 | EG13: 0 | EH13: 0 | EI13: 0 | EJ13: 0 | EK13: 0 | EL13: 0 | EM13: 0 | EN13: 0 | EO13: 0 | EP13: 0 | EQ13: 0 | ER13: 0 | ES13: 0 | ET13: 0
A14: 201 | B14: =LOOKUP(A14,Lookup!$A$1:$A$34,Lookup!$B$1:$B$34) -> BUTCHERY | C14: 34306 | D14: STEAK MINCE (EXTRA LEAN) | E14: 0 | F14: 0 | G14: 0 | H14: 0 | I14: 0 | J14: 0 | K14: 0 | L14: 0 | M14: 0 | N14: 0 | O14: 0 | P14: 0 | Q14: 0 | R14: 0 | S14: 0 | T14: 0 | U14: 0 | V14: 0 | W14: 0 | X14: 0 | Y14: 0 | Z14: 0 | AA14: 0 | AB14: 0 | AC14: 0 | AD14: 0 | AE14: 0 | AF14: 0 | AG14: 0 | AH14: 0 | AI14: 0 | AJ14: 0 | AK14: 0 | AL14: 0 | AM14: 0 | AN14: 0 | AO14: 0 | AP14: 0 | AQ14: 0 | AR14: 0 | AS14: 0 | AT14: 0 | AU14: 0 | AV14: 0 | AW14: 0 | AX14: 0 | AY14: 0 | AZ14: 0 | BA14: 0 | BB14: 0 | BC14: 0 | BD14: 0 | BE14: 0 | BF14: 0 | BG14: 0 | BH14: 0 | BI14: 0 | BJ14: 0 | BK14: 0 | BL14: 0 | BM14: 0 | BN14: 0 | BO14: 0 | BP14: 0 | BQ14: 0 | BR14: 0 | BS14: 0 | BT14: 0 | BU14: 0 | BV14: 0 | BW14: 0 | BX14: 0 | BY14: 0 | BZ14: 0 | CA14: 0 | CB14: 0 | CC14: 0 | CD14: 0 | CE14: 0 | CF14: 0 | CG14: 0 | CH14: 0 | CI14: 0 | CJ14: 0 | CK14: 0 | CL14: 0 | CM14: 0 | CN14: 0 | CO14: 0 | CP14: 0 | CQ14: 0 | CR14: 0 | CS14: 0 | CT14: 0 | CU14: 0 | CV14: 0 | CW14: 0 | CX14: 0 | CY14: 0 | CZ14: 0 | DA14: 0 | DB14: 0 | DC14: 0 | DD14: 0 | DE14: 0 | DF14: 0 | DG14: 0 | DH14: 0 | DI14: 0 | DJ14: 0 | DK14: 0 | DL14: 0 | DM14: 0 | DN14: 0 | DO14: 0 | DP14: 0 | DQ14: 0 | DR14: 0 | DS14: 0 | DT14: 0 | DU14: 0 | DV14: 0 | DW14: 0 | DX14: 0 | DY14: 0 | DZ14: 0 | EA14: 0 | EB14: 0 | EC14: 0 | ED14: 0 | EE14: 0 | EF14: 0 | EG14: 0 | EH14: 0 | EI14: 0 | EJ14: 0 | EK14: 0 | EL14: 0 | EM14: 0 | EN14: 0 | EO14: 0 | EP14: 0 | EQ14: 0 | ER14: 0 | ES14: 0 | ET14: 0
... A553: 229 | B553: =LOOKUP(A553,Lookup!$A$1:$A$34,Lookup!$B$1:$B$34) -> INGREDIENTS | C553: 63808 | D553: WILTSHIRE PORK SAUSAGE | E553: 0 | F553: 0 | G553: 0 | H553: 0 | I553: 0 | J553: 0 | K553: 0 | L553: 0 | M553: 0 | N553: 0 | O553: 0 | P553: 0 | Q553: 0 | R553: 0 | S553: 0 | T553: 0 | U553: 0 | V553: 0 | W553: 0 | X553: 0 | Y553: 0 | Z553: 0 | AA553: 0 | AB553: 0 | AC553: 0 | AD553: 0 | AE553: 0 | AF553: 0 | AG553: 0 | AH553: 0 | AI553: 0 | AJ553: 0 | AK553: 0 | AL553: 0 | AM553: 0 | AN553: 0 | AO553: 0 | AP553: 0 | AQ553: 0 | AR553: 0 | AS553: 0 | AT553: 0 | AU553: 0 | AV553: 0 | AW553: 0 | AX553: 0 | AY553: 0 | AZ553: 0 | BA553: 0 | BB553: 0 | BC553: 0 | BD553: 0 | BE553: 0 | BF553: 0 | BG553: 0 | BH553: 0 | BI553: 0 | BJ553: 0 | BK553: 0 | BL553: 0 | BM553: 0 | BN553: 0 | BO553: 0 | BP553: 0 | BQ553: 0 | BR553: 0 | BS553: 0 | BT553: 0 | BU553: 0 | BV553: 0 | BW553: 0 | BX553: 0 | BY553: 0 | BZ553: 0 | CA553: 0 | CB553: 0 | CC553: 0 | CD553: 0 | CE553: 0 | CF553: 0 | CG553: 0 | CH553: 0 | CI553: 0 | CJ553: 0 | CK553: 0 | CL553: 0 | CM553: 0 | CN553: 0 | CO553: 0 | CP553: 0 | CQ553: 0 | CR553: 0 | CS553: 0 | CT553: 0 | CU553: 0 | CV553: 0 | CW553: 0 | CX553: 0 | CY553: 0 | CZ553: 0 | DA553: 0 | DB553: 0 | DC553: 0 | DD553: 0 | DE553: 0 | DF553: 0 | DG553: 0 | DH553: 0 | DI553: 0 | DJ553: 0 | DK553: 0 | DL553: 0 | DM553: 0 | DN553: 0 | DO553: 0 | DP553: 0 | DQ553: 0 | DR553: 0 | DS553: 0 | DT553: 0 | DU553: 0 | DV553: 0 | DW553: 0 | DX553: 0 | DY553: 0 | DZ553: 0 | EA553: 0 | EB553: 0 | EC553: 0 | ED553: 0 | EE553: 0 | EF553: 0 | EG553: 0 | EH553: 0 | EI553: 0 | EJ553: 0 | EK553: 0 | EL553: 0 | EM553: 0 | EN553: 0 | EO553: 0 | EP553: 0 | EQ553: 0 | ER553: 0 | ES553: 0 | ET553: 0

Sheet 2025 vs 2026 Analysis
A1: Sub-Dept Code | B1: Sub-Department | C1: Product Code | D1: Product Description | E1: 2025 Sales (Wk1-19) | F1: 2026 Sales (Wk1-19) | G1: Sales Change | H1: Sales % Change | I1: 2025 Qty (Wk1-19) | J1: 2026 Qty (Wk1-19) | K1: Qty Change | L1: Qty % Change | M1: Trend Indicator | O1: Summary Metric | P1: Value
A2: =Data!A3 -> 201 | B2: =Data!B3 -> BUTCHERY | C2: =Data!C3 -> 11141 | D2: =Data!D3 | E2: =SUM(Data!I3,Data!K3,Data!M3,Data!O3,Data!Q3,Data!S3,Data!U3,Data!W3,Data!Y3,Data!AA3,Data!AC3,Data!AE3,Data!AG3,Data!AI3,Data!AK3,Data!AM3,Data!AO3,Data!AQ3,Data!AS3) -> 0 | F2: =SUM(Data!DI3,Data!DK3,Data!DM3,Data!DO3,Data!DQ3,Data!DS3,Data!DU3,Data!DW3,Data!DY3,Data!EA3,Data!EC3,Data!EE3,Data!EG3,Data!EI3,Data!EK3,Data!EM3,Data!EO3,Data!EQ3,Data!ES3) -> 0 | G2: =F2-E2 -> 0 | H2: =IF(E2=0,IF(F2>0,"New",0),(F2-E2)/E2) -> 0 | I2: =SUM(Data!J3,Data!L3,Data!N3,Data!P3,Data!R3,Data!T3,Data!V3,Data!X3,Data!Z3,Data!AB3,Data!AD3,Data!AF3,Data!AH3,Data!AJ3,Data!AL3,Data!AN3,Data!AP3,Data!AR3,Data!AT3) -> 0 | J2: =SUM(Data!DJ3,Data!DL3,Data!DN3,Data!DP3,Data!DR3,Data!DT3,Data!DV3,Data!DX3,Data!DZ3,Data!EB3,Data!ED3,Data!EF3,Data!EH3,Data!EJ3,Data!EL3,Data!EN3,Data!EP3,Data!ER3,Data!ET3) -> 0 | K2: =J2-I2 -> 0 | L2: =IF(I2=0,IF(J2>0,"New",0),(J2-I2)/I2) -> 0 | M2: =IF(F2=0,"No 2026 Sales",IF(E2=0,"New Product",IF(AND(ISNUMBER(H2),H2>0.1),"↑ Strong Growth",IF(AND(ISNUMBER(H2),H2>0),"↗ Growth",IF(AND(ISNUMBER(H2),H2<-0.1),"↓ Strong Decline",IF(AND(ISNUMBER(H2),H2<0),"↘ Decline","→ Stable")))))) -> No 2026 Sales | O2: Products with 2026 Sales | P2: =COUNTIF(F2:F554,">0") -> 155
A3: =Data!A4 -> 201 | B3: =Data!B4 -> BUTCHERY | C3: =Data!C4 -> 11385 | D3: =Data!D4 | E3: =SUM(Data!I4,Data!K4,Data!M4,Data!O4,Data!Q4,Data!S4,Data!U4,Data!W4,Data!Y4,Data!AA4,Data!AC4,Data!AE4,Data!AG4,Data!AI4,Data!AK4,Data!AM4,Data!AO4,Data!AQ4,Data!AS4) -> 0 | F3: =SUM(Data!DI4,Data!DK4,Data!DM4,Data!DO4,Data!DQ4,Data!DS4,Data!DU4,Data!DW4,Data!DY4,Data!EA4,Data!EC4,Data!EE4,Data!EG4,Data!EI4,Data!EK4,Data!EM4,Data!EO4,Data!EQ4,Data!ES4) -> 0 | G3: =F3-E3 -> 0 | H3: =IF(E3=0,IF(F3>0,"New",0),(F3-E3)/E3) -> 0 | I3: =SUM(Data!J4,Data!L4,Data!N4,Data!P4,Data!R4,Data!T4,Data!V4,Data!X4,Data!Z4,Data!AB4,Data!AD4,Data!AF4,Data!AH4,Data!AJ4,Data!AL4,Data!AN4,Data!AP4,Data!AR4,Data!AT4) -> 0 | J3: =SUM(Data!DJ4,Data!DL4,Data!DN4,Data!DP4,Data!DR4,Data!DT4,Data!DV4,Data!DX4,Data!DZ4,Data!EB4,Data!ED4,Data!EF4,Data!EH4,Data!EJ4,Data!EL4,Data!EN4,Data!EP4,Data!ER4,Data!ET4) -> 0 | K3: =J3-I3 -> 0 | L3: =IF(I3=0,IF(J3>0,"New",0),(J3-I3)/I3) -> 0 | M3: =IF(F3=0,"No 2026 Sales",IF(E3=0,"New Product",IF(AND(ISNUMBER(H3),H3>0.1),"↑ Strong Growth",IF(AND(ISNUMBER(H3),H3>0),"↗ Growth",IF(AND(ISNUMBER(H3),H3<-0.1),"↓ Strong Decline",IF(AND(ISNUMBER(H3),H3<0),"↘ Decline","→ Stable")))))) -> No 2026 Sales | O3: ↳ with Sales Growth | P3: =COUNTIFS(F2:F554,">0",H2:H554,">0") -> 58
A4: =Data!A5 -> 201 | B4: =Data!B5 -> BUTCHERY | C4: =Data!C5 -> 11388 | D4: =Data!D5 | E4: =SUM(Data!I5,Data!K5,Data!M5,Data!O5,Data!Q5,Data!S5,Data!U5,Data!W5,Data!Y5,Data!AA5,Data!AC5,Data!AE5,Data!AG5,Data!AI5,Data!AK5,Data!AM5,Data!AO5,Data!AQ5,Data!AS5) -> 0 | F4: =SUM(Data!DI5,Data!DK5,Data!DM5,Data!DO5,Data!DQ5,Data!DS5,Data!DU5,Data!DW5,Data!DY5,Data!EA5,Data!EC5,Data!EE5,Data!EG5,Data!EI5,Data!EK5,Data!EM5,Data!EO5,Data!EQ5,Data!ES5) -> 0 | G4: =F4-E4 -> 0 | H4: =IF(E4=0,IF(F4>0,"New",0),(F4-E4)/E4) -> 0 | I4: =SUM(Data!J5,Data!L5,Data!N5,Data!P5,Data!R5,Data!T5,Data!V5,Data!X5,Data!Z5,Data!AB5,Data!AD5,Data!AF5,Data!AH5,Data!AJ5,Data!AL5,Data!AN5,Data!AP5,Data!AR5,Data!AT5) -> 0 | J4: =SUM(Data!DJ5,Data!DL5,Data!DN5,Data!DP5,Data!DR5,Data!DT5,Data!DV5,Data!DX5,Data!DZ5,Data!EB5,Data!ED5,Data!EF5,Data!EH5,Data!EJ5,Data!EL5,Data!EN5,Data!EP5,Data!ER5,Data!ET5) -> 0 | K4: =J4-I4 -> 0 | L4: =IF(I4=0,IF(J4>0,"New",0),(J4-I4)/I4) -> 0 | M4: =IF(F4=0,"No 2026 Sales",IF(E4=0,"New Product",IF(AND(ISNUMBER(H4),H4>0.1),"↑ Strong Growth",IF(AND(ISNUMBER(H4),H4>0),"↗ Growth",IF(AND(ISNUMBER(H4),H4<-0.1),"↓ Strong Decline",IF(AND(ISNUMBER(H4),H4<0),"↘ Decline","→ Stable")))))) -> No 2026 Sales | O4: ↳ with Sales Decline | P4: =COUNTIFS(F2:F554,">0",H2:H554,"<0") -> 44
A5: =Data!A6 -> 201 | B5: =Data!B6 -> BUTCHERY | C5: =Data!C6 -> 12151 | D5: =Data!D6 | E5: =SUM(Data!I6,Data!K6,Data!M6,Data!O6,Data!Q6,Data!S6,Data!U6,Data!W6,Data!Y6,Data!AA6,Data!AC6,Data!AE6,Data!AG6,Data!AI6,Data!AK6,Data!AM6,Data!AO6,Data!AQ6,Data!AS6) -> 0 | F5: =SUM(Data!DI6,Data!DK6,Data!DM6,Data!DO6,Data!DQ6,Data!DS6,Data!DU6,Data!DW6,Data!DY6,Data!EA6,Data!EC6,Data!EE6,Data!EG6,Data!EI6,Data!EK6,Data!EM6,Data!EO6,Data!EQ6,Data!ES6) -> 0 | G5: =F5-E5 -> 0 | H5: =IF(E5=0,IF(F5>0,"New",0),(F5-E5)/E5) -> 0 | I5: =SUM(Data!J6,Data!L6,Data!N6,Data!P6,Data!R6,Data!T6,Data!V6,Data!X6,Data!Z6,Data!AB6,Data!AD6,Data!AF6,Data!AH6,Data!AJ6,Data!AL6,Data!AN6,Data!AP6,Data!AR6,Data!AT6) -> 0 | J5: =SUM(Data!DJ6,Data!DL6,Data!DN6,Data!DP6,Data!DR6,Data!DT6,Data!DV6,Data!DX6,Data!DZ6,Data!EB6,Data!ED6,Data!EF6,Data!EH6,Data!EJ6,Data!EL6,Data!EN6,Data!EP6,Data!ER6,Data!ET6) -> 0 | K5: =J5-I5 -> 0 | L5: =IF(I5=0,IF(J5>0,"New",0),(J5-I5)/I5) -> 0 | M5: =IF(F5=0,"No 2026 Sales",IF(E5=0,"New Product",IF(AND(ISNUMBER(H5),H5>0.1),"↑ Strong Growth",IF(AND(ISNUMBER(H5),H5>0),"↗ Growth",IF(AND(ISNUMBER(H5),H5<-0.1),"↓ Strong Decline",IF(AND(ISNUMBER(H5),H5<0),"↘ Decline","→ Stable")))))) -> No 2026 Sales | O5: ↳ New in 2026 | P5: =COUNTIF(H2:H554,"New") -> 53
A6: =Data!A7 -> 201 | B6: =Data!B7 -> BUTCHERY | C6: =Data!C7 -> 12194 | D6: =Data!D7 | E6: =SUM(Data!I7,Data!K7,Data!M7,Data!O7,Data!Q7,Data!S7,Data!U7,Data!W7,Data!Y7,Data!AA7,Data!AC7,Data!AE7,Data!AG7,Data!AI7,Data!AK7,Data!AM7,Data!AO7,Data!AQ7,Data!AS7) -> 0 | F6: =SUM(Data!DI7,Data!DK7,Data!DM7,Data!DO7,Data!DQ7,Data!DS7,Data!DU7,Data!DW7,Data!DY7,Data!EA7,Data!EC7,Data!EE7,Data!EG7,Data!EI7,Data!EK7,Data!EM7,Data!EO7,Data!EQ7,Data!ES7) -> 0 | G6: =F6-E6 -> 0 | H6: =IF(E6=0,IF(F6>0,"New",0),(F6-E6)/E6) -> 0 | I6: =SUM(Data!J7,Data!L7,Data!N7,Data!P7,Data!R7,Data!T7,Data!V7,Data!X7,Data!Z7,Data!AB7,Data!AD7,Data!AF7,Data!AH7,Data!AJ7,Data!AL7,Data!AN7,Data!AP7,Data!AR7,Data!AT7) -> 0 | J6: =SUM(Data!DJ7,Data!DL7,Data!DN7,Data!DP7,Data!DR7,Data!DT7,Data!DV7,Data!DX7,Data!DZ7,Data!EB7,Data!ED7,Data!EF7,Data!EH7,Data!EJ7,Data!EL7,Data!EN7,Data!EP7,Data!ER7,Data!ET7) -> 0 | K6: =J6-I6 -> 0 | L6: =IF(I6=0,IF(J6>0,"New",0),(J6-I6)/I6) -> 0 | M6: =IF(F6=0,"No 2026 Sales",IF(E6=0,"New Product",IF(AND(ISNUMBER(H6),H6>0.1),"↑ Strong Growth",IF(AND(ISNUMBER(H6),H6>0),"↗ Growth",IF(AND(ISNUMBER(H6),H6<-0.1),"↓ Strong Decline",IF(AND(ISNUMBER(H6),H6<0),"↘ Decline","→ Stable")))))) -> No 2026 Sales
A7: =Data!A8 -> 201 | B7: =Data!B8 -> BUTCHERY | C7: =Data!C8 -> 12314 | D7: =Data!D8 | E7: =SUM(Data!I8,Data!K8,Data!M8,Data!O8,Data!Q8,Data!S8,Data!U8,Data!W8,Data!Y8,Data!AA8,Data!AC8,Data!AE8,Data!AG8,Data!AI8,Data!AK8,Data!AM8,Data!AO8,Data!AQ8,Data!AS8) -> 0 | F7: =SUM(Data!DI8,Data!DK8,Data!DM8,Data!DO8,Data!DQ8,Data!DS8,Data!DU8,Data!DW8,Data!DY8,Data!EA8,Data!EC8,Data!EE8,Data!EG8,Data!EI8,Data!EK8,Data!EM8,Data!EO8,Data!EQ8,Data!ES8) -> 0 | G7: =F7-E7 -> 0 | H7: =IF(E7=0,IF(F7>0,"New",0),(F7-E7)/E7) -> 0 | I7: =SUM(Data!J8,Data!L8,Data!N8,Data!P8,Data!R8,Data!T8,Data!V8,Data!X8,Data!Z8,Data!AB8,Data!AD8,Data!AF8,Data!AH8,Data!AJ8,Data!AL8,Data!AN8,Data!AP8,Data!AR8,Data!AT8) -> 0 | J7: =SUM(Data!DJ8,Data!DL8,Data!DN8,Data!DP8,Data!DR8,Data!DT8,Data!DV8,Data!DX8,Data!DZ8,Data!EB8,Data!ED8,Data!EF8,Data!EH8,Data!EJ8,Data!EL8,Data!EN8,Data!EP8,Data!ER8,Data!ET8) -> 0 | K7: =J7-I7 -> 0 | L7: =IF(I7=0,IF(J7>0,"New",0),(J7-I7)/I7) -> 0 | M7: =IF(F7=0,"No 2026 Sales",IF(E7=0,"New Product",IF(AND(ISNUMBER(H7),H7>0.1),"↑ Strong Growth",IF(AND(ISNUMBER(H7),H7>0),"↗ Growth",IF(AND(ISNUMBER(H7),H7<-0.1),"↓ Strong Decline",IF(AND(ISNUMBER(H7),H7<0),"↘ Decline","→ Stable")))))) -> No 2026 Sales | O7: 2025 Sales (Wk1-19, products w/ 2026 sales) | P7: =SUMIF(F2:F554,">0",E2:E554) -> 1429049.1
A8: =Data!A9 -> 201 | B8: =Data!B9 -> BUTCHERY | C8: =Data!C9 -> 15219 | D8: =Data!D9 | E8: =SUM(Data!I9,Data!K9,Data!M9,Data!O9,Data!Q9,Data!S9,Data!U9,Data!W9,Data!Y9,Data!AA9,Data!AC9,Data!AE9,Data!AG9,Data!AI9,Data!AK9,Data!AM9,Data!AO9,Data!AQ9,Data!AS9) -> 0 | F8: =SUM(Data!DI9,Data!DK9,Data!DM9,Data!DO9,Data!DQ9,Data!DS9,Data!DU9,Data!DW9,Data!DY9,Data!EA9,Data!EC9,Data!EE9,Data!EG9,Data!EI9,Data!EK9,Data!EM9,Data!EO9,Data!EQ9,Data!ES9) -> 0 | G8: =F8-E8 -> 0 | H8: =IF(E8=0,IF(F8>0,"New",0),(F8-E8)/E8) -> 0 | I8: =SUM(Data!J9,Data!L9,Data!N9,Data!P9,Data!R9,Data!T9,Data!V9,Data!X9,Data!Z9,Data!AB9,Data!AD9,Data!AF9,Data!AH9,Data!AJ9,Data!AL9,Data!AN9,Data!AP9,Data!AR9,Data!AT9) -> 0 | J8: =SUM(Data!DJ9,Data!DL9,Data!DN9,Data!DP9,Data!DR9,Data!DT9,Data!DV9,Data!DX9,Data!DZ9,Data!EB9,Data!ED9,Data!EF9,Data!EH9,Data!EJ9,Data!EL9,Data!EN9,Data!EP9,Data!ER9,Data!ET9) -> 0 | K8: =J8-I8 -> 0 | L8: =IF(I8=0,IF(J8>0,"New",0),(J8-I8)/I8) -> 0 | M8: =IF(F8=0,"No 2026 Sales",IF(E8=0,"New Product",IF(AND(ISNUMBER(H8),H8>0.1),"↑ Strong Growth",IF(AND(ISNUMBER(H8),H8>0),"↗ Growth",IF(AND(ISNUMBER(H8),H8<-0.1),"↓ Strong Decline",IF(AND(ISNUMBER(H8),H8<0),"↘ Decline","→ Stable")))))) -> No 2026 Sales | O8: 2026 Sales (Wk1-19, all) | P8: =SUM(F2:F554) -> 2135325.6
A9: =Data!A10 -> 201 | B9: =Data!B10 -> BUTCHERY | C9: =Data!C10 -> 15227 | D9: =Data!D10 | E9: =SUM(Data!I10,Data!K10,Data!M10,Data!O10,Data!Q10,Data!S10,Data!U10,Data!W10,Data!Y10,Data!AA10,Data!AC10,Data!AE10,Data!AG10,Data!AI10,Data!AK10,Data!AM10,Data!AO10,Data!AQ10,Data!AS10) -> 0 | F9: =SUM(Data!DI10,Data!DK10,Data!DM10,Data!DO10,Data!DQ10,Data!DS10,Data!DU10,Data!DW10,Data!DY10,Data!EA10,Data!EC10,Data!EE10,Data!EG10,Data!EI10,Data!EK10,Data!EM10,Data!EO10,Data!EQ10,Data!ES10) -> 0 | G9: =F9-E9 -> 0 | H9: =IF(E9=0,IF(F9>0,"New",0),(F9-E9)/E9) -> 0 | I9: =SUM(Data!J10,Data!L10,Data!N10,Data!P10,Data!R10,Data!T10,Data!V10,Data!X10,Data!Z10,Data!AB10,Data!AD10,Data!AF10,Data!AH10,Data!AJ10,Data!AL10,Data!AN10,Data!AP10,Data!AR10,Data!AT10) -> 0 | J9: =SUM(Data!DJ10,Data!DL10,Data!DN10,Data!DP10,Data!DR10,Data!DT10,Data!DV10,Data!DX10,Data!DZ10,Data!EB10,Data!ED10,Data!EF10,Data!EH10,Data!EJ10,Data!EL10,Data!EN10,Data!EP10,Data!ER10,Data!ET10) -> 0 | K9: =J9-I9 -> 0 | L9: =IF(I9=0,IF(J9>0,"New",0),(J9-I9)/I9) -> 0 | M9: =IF(F9=0,"No 2026 Sales",IF(E9=0,"New Product",IF(AND(ISNUMBER(H9),H9>0.1),"↑ Strong Growth",IF(AND(ISNUMBER(H9),H9>0),"↗ Growth",IF(AND(ISNUMBER(H9),H9<-0.1),"↓ Strong Decline",IF(AND(ISNUMBER(H9),H9<0),"↘ Decline","→ Stable")))))) -> No 2026 Sales | O9: Sales Change | P9: =P8-P7 -> 706276.55
A10: =Data!A11 -> 201 | B10: =Data!B11 -> BUTCHERY | C10: =Data!C11 -> 34176 | D10: =Data!D11 | E10: =SUM(Data!I11,Data!K11,Data!M11,Data!O11,Data!Q11,Data!S11,Data!U11,Data!W11,Data!Y11,Data!AA11,Data!AC11,Data!AE11,Data!AG11,Data!AI11,Data!AK11,Data!AM11,Data!AO11,Data!AQ11,Data!AS11) -> 0 | F10: =SUM(Data!DI11,Data!DK11,Data!DM11,Data!DO11,Data!DQ11,Data!DS11,Data!DU11,Data!DW11,Data!DY11,Data!EA11,Data!EC11,Data!EE11,Data!EG11,Data!EI11,Data!EK11,Data!EM11,Data!EO11,Data!EQ11,Data!ES11) -> 0 | G10: =F10-E10 -> 0 | H10: =IF(E10=0,IF(F10>0,"New",0),(F10-E10)/E10) -> 0 | I10: =SUM(Data!J11,Data!L11,Data!N11,Data!P11,Data!R11,Data!T11,Data!V11,Data!X11,Data!Z11,Data!AB11,Data!AD11,Data!AF11,Data!AH11,Data!AJ11,Data!AL11,Data!AN11,Data!AP11,Data!AR11,Data!AT11) -> 0 | J10: =SUM(Data!DJ11,Data!DL11,Data!DN11,Data!DP11,Data!DR11,Data!DT11,Data!DV11,Data!DX11,Data!DZ11,Data!EB11,Data!ED11,Data!EF11,Data!EH11,Data!EJ11,Data!EL11,Data!EN11,Data!EP11,Data!ER11,Data!ET11) -> 0 | K10: =J10-I10 -> 0 | L10: =IF(I10=0,IF(J10>0,"New",0),(J10-I10)/I10) -> 0 | M10: =IF(F10=0,"No 2026 Sales",IF(E10=0,"New Product",IF(AND(ISNUMBER(H10),H10>0.1),"↑ Strong Growth",IF(AND(ISNUMBER(H10),H10>0),"↗ Growth",IF(AND(ISNUMBER(H10),H10<-0.1),"↓ Strong Decline",IF(AND(ISNUMBER(H10),H10<0),"↘ Decline","→ Stable")))))) -> No 2026 Sales | O10: Sales % Change | P10: =IF(P7=0,0,P9/P7) -> 0.49422834
A11: =Data!A12 -> 201 | B11: =Data!B12 -> BUTCHERY | C11: =Data!C12 -> 34233 | D11: =Data!D12 | E11: =SUM(Data!I12,Data!K12,Data!M12,Data!O12,Data!Q12,Data!S12,Data!U12,Data!W12,Data!Y12,Data!AA12,Data!AC12,Data!AE12,Data!AG12,Data!AI12,Data!AK12,Data!AM12,Data!AO12,Data!AQ12,Data!AS12) -> 0 | F11: =SUM(Data!DI12,Data!DK12,Data!DM12,Data!DO12,Data!DQ12,Data!DS12,Data!DU12,Data!DW12,Data!DY12,Data!EA12,Data!EC12,Data!EE12,Data!EG12,Data!EI12,Data!EK12,Data!EM12,Data!EO12,Data!EQ12,Data!ES12) -> 0 | G11: =F11-E11 -> 0 | H11: =IF(E11=0,IF(F11>0,"New",0),(F11-E11)/E11) -> 0 | I11: =SUM(Data!J12,Data!L12,Data!N12,Data!P12,Data!R12,Data!T12,Data!V12,Data!X12,Data!Z12,Data!AB12,Data!AD12,Data!AF12,Data!AH12,Data!AJ12,Data!AL12,Data!AN12,Data!AP12,Data!AR12,Data!AT12) -> 0 | J11: =SUM(Data!DJ12,Data!DL12,Data!DN12,Data!DP12,Data!DR12,Data!DT12,Data!DV12,Data!DX12,Data!DZ12,Data!EB12,Data!ED12,Data!EF12,Data!EH12,Data!EJ12,Data!EL12,Data!EN12,Data!EP12,Data!ER12,Data!ET12) -> 0 | K11: =J11-I11 -> 0 | L11: =IF(I11=0,IF(J11>0,"New",0),(J11-I11)/I11) -> 0 | M11: =IF(F11=0,"No 2026 Sales",IF(E11=0,"New Product",IF(AND(ISNUMBER(H11),H11>0.1),"↑ Strong Growth",IF(AND(ISNUMBER(H11),H11>0),"↗ Growth",IF(AND(ISNUMBER(H11),H11<-0.1),"↓ Strong Decline",IF(AND(ISNUMBER(H11),H11<0),"↘ Decline","→ Stable")))))) -> No 2026 Sales
A12: =Data!A13 -> 201 | B12: =Data!B13 -> BUTCHERY | C12: =Data!C13 -> 34234 | D12: =Data!D13 | E12: =SUM(Data!I13,Data!K13,Data!M13,Data!O13,Data!Q13,Data!S13,Data!U13,Data!W13,Data!Y13,Data!AA13,Data!AC13,Data!AE13,Data!AG13,Data!AI13,Data!AK13,Data!AM13,Data!AO13,Data!AQ13,Data!AS13) -> 0 | F12: =SUM(Data!DI13,Data!DK13,Data!DM13,Data!DO13,Data!DQ13,Data!DS13,Data!DU13,Data!DW13,Data!DY13,Data!EA13,Data!EC13,Data!EE13,Data!EG13,Data!EI13,Data!EK13,Data!EM13,Data!EO13,Data!EQ13,Data!ES13) -> 0 | G12: =F12-E12 -> 0 | H12: =IF(E12=0,IF(F12>0,"New",0),(F12-E12)/E12) -> 0 | I12: =SUM(Data!J13,Data!L13,Data!N13,Data!P13,Data!R13,Data!T13,Data!V13,Data!X13,Data!Z13,Data!AB13,Data!AD13,Data!AF13,Data!AH13,Data!AJ13,Data!AL13,Data!AN13,Data!AP13,Data!AR13,Data!AT13) -> 0 | J12: =SUM(Data!DJ13,Data!DL13,Data!DN13,Data!DP13,Data!DR13,Data!DT13,Data!DV13,Data!DX13,Data!DZ13,Data!EB13,Data!ED13,Data!EF13,Data!EH13,Data!EJ13,Data!EL13,Data!EN13,Data!EP13,Data!ER13,Data!ET13) -> 0 | K12: =J12-I12 -> 0 | L12: =IF(I12=0,IF(J12>0,"New",0),(J12-I12)/I12) -> 0 | M12: =IF(F12=0,"No 2026 Sales",IF(E12=0,"New Product",IF(AND(ISNUMBER(H12),H12>0.1),"↑ Strong Growth",IF(AND(ISNUMBER(H12),H12>0),"↗ Growth",IF(AND(ISNUMBER(H12),H12<-0.1),"↓ Strong Decline",IF(AND(ISNUMBER(H12),H12<0),"↘ Decline","→ Stable")))))) -> No 2026 Sales | O12: 2025 Qty (Wk1-19, products w/ 2026 sales) | P12: =SUMIF(J2:J554,">0",I2:I554) -> 20173.462
A13: =Data!A14 -> 201 | B13: =Data!B14 -> BUTCHERY | C13: =Data!C14 -> 34306 | D13: =Data!D14 | E13: =SUM(Data!I14,Data!K14,Data!M14,Data!O14,Data!Q14,Data!S14,Data!U14,Data!W14,Data!Y14,Data!AA14,Data!AC14,Data!AE14,Data!AG14,Data!AI14,Data!AK14,Data!AM14,Data!AO14,Data!AQ14,Data!AS14) -> 0 | F13: =SUM(Data!DI14,Data!DK14,Data!DM14,Data!DO14,Data!DQ14,Data!DS14,Data!DU14,Data!DW14,Data!DY14,Data!EA14,Data!EC14,Data!EE14,Data!EG14,Data!EI14,Data!EK14,Data!EM14,Data!EO14,Data!EQ14,Data!ES14) -> 0 | G13: =F13-E13 -> 0 | H13: =IF(E13=0,IF(F13>0,"New",0),(F13-E13)/E13) -> 0 | I13: =SUM(Data!J14,Data!L14,Data!N14,Data!P14,Data!R14,Data!T14,Data!V14,Data!X14,Data!Z14,Data!AB14,Data!AD14,Data!AF14,Data!AH14,Data!AJ14,Data!AL14,Data!AN14,Data!AP14,Data!AR14,Data!AT14) -> 0 | J13: =SUM(Data!DJ14,Data!DL14,Data!DN14,Data!DP14,Data!DR14,Data!DT14,Data!DV14,Data!DX14,Data!DZ14,Data!EB14,Data!ED14,Data!EF14,Data!EH14,Data!EJ14,Data!EL14,Data!EN14,Data!EP14,Data!ER14,Data!ET14) -> 0 | K13: =J13-I13 -> 0 | L13: =IF(I13=0,IF(J13>0,"New",0),(J13-I13)/I13) -> 0 | M13: =IF(F13=0,"No 2026 Sales",IF(E13=0,"New Product",IF(AND(ISNUMBER(H13),H13>0.1),"↑ Strong Growth",IF(AND(ISNUMBER(H13),H13>0),"↗ Growth",IF(AND(ISNUMBER(H13),H13<-0.1),"↓ Strong Decline",IF(AND(ISNUMBER(H13),H13<0),"↘ Decline","→ Stable")))))) -> No 2026 Sales | O13: 2026 Qty (Wk1-19, all) | P13: =SUM(J2:J554) -> 24454.402
A14: =Data!A15 -> 201 | B14: =Data!B15 -> BUTCHERY | C14: =Data!C15 -> 41246 | D14: =Data!D15 | E14: =SUM(Data!I15,Data!K15,Data!M15,Data!O15,Data!Q15,Data!S15,Data!U15,Data!W15,Data!Y15,Data!AA15,Data!AC15,Data!AE15,Data!AG15,Data!AI15,Data!AK15,Data!AM15,Data!AO15,Data!AQ15,Data!AS15) -> 0 | F14: =SUM(Data!DI15,Data!DK15,Data!DM15,Data!DO15,Data!DQ15,Data!DS15,Data!DU15,Data!DW15,Data!DY15,Data!EA15,Data!EC15,Data!EE15,Data!EG15,Data!EI15,Data!EK15,Data!EM15,Data!EO15,Data!EQ15,Data!ES15) -> 0 | G14: =F14-E14 -> 0 | H14: =IF(E14=0,IF(F14>0,"New",0),(F14-E14)/E14) -> 0 | I14: =SUM(Data!J15,Data!L15,Data!N15,Data!P15,Data!R15,Data!T15,Data!V15,Data!X15,Data!Z15,Data!AB15,Data!AD15,Data!AF15,Data!AH15,Data!AJ15,Data!AL15,Data!AN15,Data!AP15,Data!AR15,Data!AT15) -> 0 | J14: =SUM(Data!DJ15,Data!DL15,Data!DN15,Data!DP15,Data!DR15,Data!DT15,Data!DV15,Data!DX15,Data!DZ15,Data!EB15,Data!ED15,Data!EF15,Data!EH15,Data!EJ15,Data!EL15,Data!EN15,Data!EP15,Data!ER15,Data!ET15) -> 0 | K14: =J14-I14 -> 0 | L14: =IF(I14=0,IF(J14>0,"New",0),(J14-I14)/I14) -> 0 | M14: =IF(F14=0,"No 2026 Sales",IF(E14=0,"New Product",IF(AND(ISNUMBER(H14),H14>0.1),"↑ Strong Growth",IF(AND(ISNUMBER(H14),H14>0),"↗ Growth",IF(AND(ISNUMBER(H14),H14<-0.1),"↓ Strong Decline",IF(AND(ISNUMBER(H14),H14<0),"↘ Decline","→ Stable")))))) -> No 2026 Sales | O14: Qty Change | P14: =P13-P12 -> 4280.94
A15: =Data!A16 -> 201 | B15: =Data!B16 -> BUTCHERY | C15: =Data!C16 -> 49848 | D15: =Data!D16 | E15: =SUM(Data!I16,Data!K16,Data!M16,Data!O16,Data!Q16,Data!S16,Data!U16,Data!W16,Data!Y16,Data!AA16,Data!AC16,Data!AE16,Data!AG16,Data!AI16,Data!AK16,Data!AM16,Data!AO16,Data!AQ16,Data!AS16) -> 0 | F15: =SUM(Data!DI16,Data!DK16,Data!DM16,Data!DO16,Data!DQ16,Data!DS16,Data!DU16,Data!DW16,Data!DY16,Data!EA16,Data!EC16,Data!EE16,Data!EG16,Data!EI16,Data!EK16,Data!EM16,Data!EO16,Data!EQ16,Data!ES16) -> 0 | G15: =F15-E15 -> 0 | H15: =IF(E15=0,IF(F15>0,"New",0),(F15-E15)/E15) -> 0 | I15: =SUM(Data!J16,Data!L16,Data!N16,Data!P16,Data!R16,Data!T16,Data!V16,Data!X16,Data!Z16,Data!AB16,Data!AD16,Data!AF16,Data!AH16,Data!AJ16,Data!AL16,Data!AN16,Data!AP16,Data!AR16,Data!AT16) -> 0 | J15: =SUM(Data!DJ16,Data!DL16,Data!DN16,Data!DP16,Data!DR16,Data!DT16,Data!DV16,Data!DX16,Data!DZ16,Data!EB16,Data!ED16,Data!EF16,Data!EH16,Data!EJ16,Data!EL16,Data!EN16,Data!EP16,Data!ER16,Data!ET16) -> 0 | K15: =J15-I15 -> 0 | L15: =IF(I15=0,IF(J15>0,"New",0),(J15-I15)/I15) -> 0 | M15: =IF(F15=0,"No 2026 Sales",IF(E15=0,"New Product",IF(AND(ISNUMBER(H15),H15>0.1),"↑ Strong Growth",IF(AND(ISNUMBER(H15),H15>0),"↗ Growth",IF(AND(ISNUMBER(H15),H15<-0.1),"↓ Strong Decline",IF(AND(ISNUMBER(H15),H15<0),"↘ Decline","→ Stable")))))) -> No 2026 Sales | O15: Qty % Change | P15: =IF(P12=0,0,P14/P12) -> 0.21220651
A16: =Data!A17 -> 201 | B16: =Data!B17 -> BUTCHERY | C16: =Data!C17 -> 52212 | D16: =Data!D17 | E16: =SUM(Data!I17,Data!K17,Data!M17,Data!O17,Data!Q17,Data!S17,Data!U17,Data!W17,Data!Y17,Data!AA17,Data!AC17,Data!AE17,Data!AG17,Data!AI17,Data!AK17,Data!AM17,Data!AO17,Data!AQ17,Data!AS17) -> 0 | F16: =SUM(Data!DI17,Data!DK17,Data!DM17,Data!DO17,Data!DQ17,Data!DS17,Data!DU17,Data!DW17,Data!DY17,Data!EA17,Data!EC17,Data!EE17,Data!EG17,Data!EI17,Data!EK17,Data!EM17,Data!EO17,Data!EQ17,Data!ES17) -> 0 | G16: =F16-E16 -> 0 | H16: =IF(E16=0,IF(F16>0,"New",0),(F16-E16)/E16) -> 0 | I16: =SUM(Data!J17,Data!L17,Data!N17,Data!P17,Data!R17,Data!T17,Data!V17,Data!X17,Data!Z17,Data!AB17,Data!AD17,Data!AF17,Data!AH17,Data!AJ17,Data!AL17,Data!AN17,Data!AP17,Data!AR17,Data!AT17) -> 0 | J16: =SUM(Data!DJ17,Data!DL17,Data!DN17,Data!DP17,Data!DR17,Data!DT17,Data!DV17,Data!DX17,Data!DZ17,Data!EB17,Data!ED17,Data!EF17,Data!EH17,Data!EJ17,Data!EL17,Data!EN17,Data!EP17,Data!ER17,Data!ET17) -> 0 | K16: =J16-I16 -> 0 | L16: =IF(I16=0,IF(J16>0,"New",0),(J16-I16)/I16) -> 0 | M16: =IF(F16=0,"No 2026 Sales",IF(E16=0,"New Product",IF(AND(ISNUMBER(H16),H16>0.1),"↑ Strong Growth",IF(AND(ISNUMBER(H16),H16>0),"↗ Growth",IF(AND(ISNUMBER(H16),H16<-0.1),"↓ Strong Decline",IF(AND(ISNUMBER(H16),H16<0),"↘ Decline","→ Stable")))))) -> No 2026 Sales
A17: =Data!A18 -> 201 | B17: =Data!B18 -> BUTCHERY | C17: =Data!C18 -> 53975 | D17: =Data!D18 | E17: =SUM(Data!I18,Data!K18,Data!M18,Data!O18,Data!Q18,Data!S18,Data!U18,Data!W18,Data!Y18,Data!AA18,Data!AC18,Data!AE18,Data!AG18,Data!AI18,Data!AK18,Data!AM18,Data!AO18,Data!AQ18,Data!AS18) -> 0 | F17: =SUM(Data!DI18,Data!DK18,Data!DM18,Data!DO18,Data!DQ18,Data!DS18,Data!DU18,Data!DW18,Data!DY18,Data!EA18,Data!EC18,Data!EE18,Data!EG18,Data!EI18,Data!EK18,Data!EM18,Data!EO18,Data!EQ18,Data!ES18) -> 0 | G17: =F17-E17 -> 0 | H17: =IF(E17=0,IF(F17>0,"New",0),(F17-E17)/E17) -> 0 | I17: =SUM(Data!J18,Data!L18,Data!N18,Data!P18,Data!R18,Data!T18,Data!V18,Data!X18,Data!Z18,Data!AB18,Data!AD18,Data!AF18,Data!AH18,Data!AJ18,Data!AL18,Data!AN18,Data!AP18,Data!AR18,Data!AT18) -> 0 | J17: =SUM(Data!DJ18,Data!DL18,Data!DN18,Data!DP18,Data!DR18,Data!DT18,Data!DV18,Data!DX18,Data!DZ18,Data!EB18,Data!ED18,Data!EF18,Data!EH18,Data!EJ18,Data!EL18,Data!EN18,Data!EP18,Data!ER18,Data!ET18) -> 0 | K17: =J17-I17 -> 0 | L17: =IF(I17=0,IF(J17>0,"New",0),(J17-I17)/I17) -> 0 | M17: =IF(F17=0,"No 2026 Sales",IF(E17=0,"New Product",IF(AND(ISNUMBER(H17),H17>0.1),"↑ Strong Growth",IF(AND(ISNUMBER(H17),H17>0),"↗ Growth",IF(AND(ISNUMBER(H17),H17<-0.1),"↓ Strong Decline",IF(AND(ISNUMBER(H17),H17<0),"↘ Decline","→ Stable")))))) -> No 2026 Sales | O17: Trend Category | P17: Count
A18: =Data!A19 -> 201 | B18: =Data!B19 -> BUTCHERY | C18: =Data!C19 -> 55974 | D18: =Data!D19 | E18: =SUM(Data!I19,Data!K19,Data!M19,Data!O19,Data!Q19,Data!S19,Data!U19,Data!W19,Data!Y19,Data!AA19,Data!AC19,Data!AE19,Data!AG19,Data!AI19,Data!AK19,Data!AM19,Data!AO19,Data!AQ19,Data!AS19) -> 0 | F18: =SUM(Data!DI19,Data!DK19,Data!DM19,Data!DO19,Data!DQ19,Data!DS19,Data!DU19,Data!DW19,Data!DY19,Data!EA19,Data!EC19,Data!EE19,Data!EG19,Data!EI19,Data!EK19,Data!EM19,Data!EO19,Data!EQ19,Data!ES19) -> 0 | G18: =F18-E18 -> 0 | H18: =IF(E18=0,IF(F18>0,"New",0),(F18-E18)/E18) -> 0 | I18: =SUM(Data!J19,Data!L19,Data!N19,Data!P19,Data!R19,Data!T19,Data!V19,Data!X19,Data!Z19,Data!AB19,Data!AD19,Data!AF19,Data!AH19,Data!AJ19,Data!AL19,Data!AN19,Data!AP19,Data!AR19,Data!AT19) -> 0 | J18: =SUM(Data!DJ19,Data!DL19,Data!DN19,Data!DP19,Data!DR19,Data!DT19,Data!DV19,Data!DX19,Data!DZ19,Data!EB19,Data!ED19,Data!EF19,Data!EH19,Data!EJ19,Data!EL19,Data!EN19,Data!EP19,Data!ER19,Data!ET19) -> 0 | K18: =J18-I18 -> 0 | L18: =IF(I18=0,IF(J18>0,"New",0),(J18-I18)/I18) -> 0 | M18: =IF(F18=0,"No 2026 Sales",IF(E18=0,"New Product",IF(AND(ISNUMBER(H18),H18>0.1),"↑ Strong Growth",IF(AND(ISNUMBER(H18),H18>0),"↗ Growth",IF(AND(ISNUMBER(H18),H18<-0.1),"↓ Strong Decline",IF(AND(ISNUMBER(H18),H18<0),"↘ Decline","→ Stable")))))) -> No 2026 Sales | O18: ↑ Strong Growth (>10%) | P18: =COUNTIF(M2:M554,"↑ Strong Growth") -> 47
A19: =Data!A20 -> 201 | B19: =Data!B20 -> BUTCHERY | C19: =Data!C20 -> 56247 | D19: =Data!D20 | E19: =SUM(Data!I20,Data!K20,Data!M20,Data!O20,Data!Q20,Data!S20,Data!U20,Data!W20,Data!Y20,Data!AA20,Data!AC20,Data!AE20,Data!AG20,Data!AI20,Data!AK20,Data!AM20,Data!AO20,Data!AQ20,Data!AS20) -> 55919.6 | F19: =SUM(Data!DI20,Data!DK20,Data!DM20,Data!DO20,Data!DQ20,Data!DS20,Data!DU20,Data!DW20,Data!DY20,Data!EA20,Data!EC20,Data!EE20,Data!EG20,Data!EI20,Data!EK20,Data!EM20,Data!EO20,Data!EQ20,Data!ES20) -> 6837.8 | G19: =F19-E19 -> -49081.8 | H19: =IF(E19=0,IF(F19>0,"New",0),(F19-E19)/E19) -> -0.87772087 | I19: =SUM(Data!J20,Data!L20,Data!N20,Data!P20,Data!R20,Data!T20,Data!V20,Data!X20,Data!Z20,Data!AB20,Data!AD20,Data!AF20,Data!AH20,Data!AJ20,Data!AL20,Data!AN20,Data!AP20,Data!AR20,Data!AT20) -> 3188 | J19: =SUM(Data!DJ20,Data!DL20,Data!DN20,Data!DP20,Data!DR20,Data!DT20,Data!DV20,Data!DX20,Data!DZ20,Data!EB20,Data!ED20,Data!EF20,Data!EH20,Data!EJ20,Data!EL20,Data!EN20,Data!EP20,Data!ER20,Data!ET20) -> 382 | K19: =J19-I19 -> -2806 | L19: =IF(I19=0,IF(J19>0,"New",0),(J19-I19)/I19) -> -0.88017566 | M19: =IF(F19=0,"No 2026 Sales",IF(E19=0,"New Product",IF(AND(ISNUMBER(H19),H19>0.1),"↑ Strong Growth",IF(AND(ISNUMBER(H19),H19>0),"↗ Growth",IF(AND(ISNUMBER(H19),H19<-0.1),"↓ Strong Decline",IF(AND(ISNUMBER(H19),H19<0),"↘ Decline","→ Stable")))))) -> ↓ Strong Decline | O19: ↗ Growth (0-10%) | P19: =COUNTIF(M2:M554,"↗ Growth") -> 11
A20: =Data!A21 -> 201 | B20: =Data!B21 -> BUTCHERY | C20: =Data!C21 -> 58663 | D20: =Data!D21 | E20: =SUM(Data!I21,Data!K21,Data!M21,Data!O21,Data!Q21,Data!S21,Data!U21,Data!W21,Data!Y21,Data!AA21,Data!AC21,Data!AE21,Data!AG21,Data!AI21,Data!AK21,Data!AM21,Data!AO21,Data!AQ21,Data!AS21) -> 0 | F20: =SUM(Data!DI21,Data!DK21,Data!DM21,Data!DO21,Data!DQ21,Data!DS21,Data!DU21,Data!DW21,Data!DY21,Data!EA21,Data!EC21,Data!EE21,Data!EG21,Data!EI21,Data!EK21,Data!EM21,Data!EO21,Data!EQ21,Data!ES21) -> 0 | G20: =F20-E20 -> 0 | H20: =IF(E20=0,IF(F20>0,"New",0),(F20-E20)/E20) -> 0 | I20: =SUM(Data!J21,Data!L21,Data!N21,Data!P21,Data!R21,Data!T21,Data!V21,Data!X21,Data!Z21,Data!AB21,Data!AD21,Data!AF21,Data!AH21,Data!AJ21,Data!AL21,Data!AN21,Data!AP21,Data!AR21,Data!AT21) -> 0 | J20: =SUM(Data!DJ21,Data!DL21,Data!DN21,Data!DP21,Data!DR21,Data!DT21,Data!DV21,Data!DX21,Data!DZ21,Data!EB21,Data!ED21,Data!EF21,Data!EH21,Data!EJ21,Data!EL21,Data!EN21,Data!EP21,Data!ER21,Data!ET21) -> 0 | K20: =J20-I20 -> 0 | L20: =IF(I20=0,IF(J20>0,"New",0),(J20-I20)/I20) -> 0 | M20: =IF(F20=0,"No 2026 Sales",IF(E20=0,"New Product",IF(AND(ISNUMBER(H20),H20>0.1),"↑ Strong Growth",IF(AND(ISNUMBER(H20),H20>0),"↗ Growth",IF(AND(ISNUMBER(H20),H20<-0.1),"↓ Strong Decline",IF(AND(ISNUMBER(H20),H20<0),"↘ Decline","→ Stable")))))) -> No 2026 Sales | O20: → Stable | P20: =COUNTIF(M2:M554,"→ Stable") -> 0
A21: =Data!A22 -> 201 | B21: =Data!B22 -> BUTCHERY | C21: =Data!C22 -> 61370 | D21: =Data!D22 | E21: =SUM(Data!I22,Data!K22,Data!M22,Data!O22,Data!Q22,Data!S22,Data!U22,Data!W22,Data!Y22,Data!AA22,Data!AC22,Data!AE22,Data!AG22,Data!AI22,Data!AK22,Data!AM22,Data!AO22,Data!AQ22,Data!AS22) -> 0 | F21: =SUM(Data!DI22,Data!DK22,Data!DM22,Data!DO22,Data!DQ22,Data!DS22,Data!DU22,Data!DW22,Data!DY22,Data!EA22,Data!EC22,Data!EE22,Data!EG22,Data!EI22,Data!EK22,Data!EM22,Data!EO22,Data!EQ22,Data!ES22) -> 302.50435 | G21: =F21-E21 -> 302.50435 | H21: =IF(E21=0,IF(F21>0,"New",0),(F21-E21)/E21) -> New | I21: =SUM(Data!J22,Data!L22,Data!N22,Data!P22,Data!R22,Data!T22,Data!V22,Data!X22,Data!Z22,Data!AB22,Data!AD22,Data!AF22,Data!AH22,Data!AJ22,Data!AL22,Data!AN22,Data!AP22,Data!AR22,Data!AT22) -> 0 | J21: =SUM(Data!DJ22,Data!DL22,Data!DN22,Data!DP22,Data!DR22,Data!DT22,Data!DV22,Data!DX22,Data!DZ22,Data!EB22,Data!ED22,Data!EF22,Data!EH22,Data!EJ22,Data!EL22,Data!EN22,Data!EP22,Data!ER22,Data!ET22) -> 12 | K21: =J21-I21 -> 12 | L21: =IF(I21=0,IF(J21>0,"New",0),(J21-I21)/I21) -> New | M21: =IF(F21=0,"No 2026 Sales",IF(E21=0,"New Product",IF(AND(ISNUMBER(H21),H21>0.1),"↑ Strong Growth",IF(AND(ISNUMBER(H21),H21>0),"↗ Growth",IF(AND(ISNUMBER(H21),H21<-0.1),"↓ Strong Decline",IF(AND(ISNUMBER(H21),H21<0),"↘ Decline","→ Stable")))))) -> New Product | O21: ↘ Decline (0 to -10%) | P21: =COUNTIF(M2:M554,"↘ Decline") -> 12
A22: =Data!A23 -> 201 | B22: =Data!B23 -> BUTCHERY | C22: =Data!C23 -> 64127 | D22: =Data!D23 | E22: =SUM(Data!I23,Data!K23,Data!M23,Data!O23,Data!Q23,Data!S23,Data!U23,Data!W23,Data!Y23,Data!AA23,Data!AC23,Data!AE23,Data!AG23,Data!AI23,Data!AK23,Data!AM23,Data!AO23,Data!AQ23,Data!AS23) -> 0 | F22: =SUM(Data!DI23,Data!DK23,Data!DM23,Data!DO23,Data!DQ23,Data!DS23,Data!DU23,Data!DW23,Data!DY23,Data!EA23,Data!EC23,Data!EE23,Data!EG23,Data!EI23,Data!EK23,Data!EM23,Data!EO23,Data!EQ23,Data!ES23) -> 0 | G22: =F22-E22 -> 0 | H22: =IF(E22=0,IF(F22>0,"New",0),(F22-E22)/E22) -> 0 | I22: =SUM(Data!J23,Data!L23,Data!N23,Data!P23,Data!R23,Data!T23,Data!V23,Data!X23,Data!Z23,Data!AB23,Data!AD23,Data!AF23,Data!AH23,Data!AJ23,Data!AL23,Data!AN23,Data!AP23,Data!AR23,Data!AT23) -> 0 | J22: =SUM(Data!DJ23,Data!DL23,Data!DN23,Data!DP23,Data!DR23,Data!DT23,Data!DV23,Data!DX23,Data!DZ23,Data!EB23,Data!ED23,Data!EF23,Data!EH23,Data!EJ23,Data!EL23,Data!EN23,Data!EP23,Data!ER23,Data!ET23) -> 0 | K22: =J22-I22 -> 0 | L22: =IF(I22=0,IF(J22>0,"New",0),(J22-I22)/I22) -> 0 | M22: =IF(F22=0,"No 2026 Sales",IF(E22=0,"New Product",IF(AND(ISNUMBER(H22),H22>0.1),"↑ Strong Growth",IF(AND(ISNUMBER(H22),H22>0),"↗ Growth",IF(AND(ISNUMBER(H22),H22<-0.1),"↓ Strong Decline",IF(AND(ISNUMBER(H22),H22<0),"↘ Decline","→ Stable")))))) -> No 2026 Sales | O22: ↓ Strong Decline (>-10%) | P22: =COUNTIF(M2:M554,"↓ Strong Decline") -> 32
A23: =Data!A24 -> 201 | B23: =Data!B24 -> BUTCHERY | C23: =Data!C24 -> 64128 | D23: =Data!D24 | E23: =SUM(Data!I24,Data!K24,Data!M24,Data!O24,Data!Q24,Data!S24,Data!U24,Data!W24,Data!Y24,Data!AA24,Data!AC24,Data!AE24,Data!AG24,Data!AI24,Data!AK24,Data!AM24,Data!AO24,Data!AQ24,Data!AS24) -> 0 | F23: =SUM(Data!DI24,Data!DK24,Data!DM24,Data!DO24,Data!DQ24,Data!DS24,Data!DU24,Data!DW24,Data!DY24,Data!EA24,Data!EC24,Data!EE24,Data!EG24,Data!EI24,Data!EK24,Data!EM24,Data!EO24,Data!EQ24,Data!ES24) -> 0 | G23: =F23-E23 -> 0 | H23: =IF(E23=0,IF(F23>0,"New",0),(F23-E23)/E23) -> 0 | I23: =SUM(Data!J24,Data!L24,Data!N24,Data!P24,Data!R24,Data!T24,Data!V24,Data!X24,Data!Z24,Data!AB24,Data!AD24,Data!AF24,Data!AH24,Data!AJ24,Data!AL24,Data!AN24,Data!AP24,Data!AR24,Data!AT24) -> 0 | J23: =SUM(Data!DJ24,Data!DL24,Data!DN24,Data!DP24,Data!DR24,Data!DT24,Data!DV24,Data!DX24,Data!DZ24,Data!EB24,Data!ED24,Data!EF24,Data!EH24,Data!EJ24,Data!EL24,Data!EN24,Data!EP24,Data!ER24,Data!ET24) -> 0 | K23: =J23-I23 -> 0 | L23: =IF(I23=0,IF(J23>0,"New",0),(J23-I23)/I23) -> 0 | M23: =IF(F23=0,"No 2026 Sales",IF(E23=0,"New Product",IF(AND(ISNUMBER(H23),H23>0.1),"↑ Strong Growth",IF(AND(ISNUMBER(H23),H23>0),"↗ Growth",IF(AND(ISNUMBER(H23),H23<-0.1),"↓ Strong Decline",IF(AND(ISNUMBER(H23),H23<0),"↘ Decline","→ Stable")))))) -> No 2026 Sales | O23: New Products | P23: =COUNTIF(M2:M554,"New Product") -> 53
A24: =Data!A25 -> 201 | B24: =Data!B25 -> BUTCHERY | C24: =Data!C25 -> 64129 | D24: =Data!D25 | E24: =SUM(Data!I25,Data!K25,Data!M25,Data!O25,Data!Q25,Data!S25,Data!U25,Data!W25,Data!Y25,Data!AA25,Data!AC25,Data!AE25,Data!AG25,Data!AI25,Data!AK25,Data!AM25,Data!AO25,Data!AQ25,Data!AS25) -> 0 | F24: =SUM(Data!DI25,Data!DK25,Data!DM25,Data!DO25,Data!DQ25,Data!DS25,Data!DU25,Data!DW25,Data!DY25,Data!EA25,Data!EC25,Data!EE25,Data!EG25,Data!EI25,Data!EK25,Data!EM25,Data!EO25,Data!EQ25,Data!ES25) -> 0 | G24: =F24-E24 -> 0 | H24: =IF(E24=0,IF(F24>0,"New",0),(F24-E24)/E24) -> 0 | I24: =SUM(Data!J25,Data!L25,Data!N25,Data!P25,Data!R25,Data!T25,Data!V25,Data!X25,Data!Z25,Data!AB25,Data!AD25,Data!AF25,Data!AH25,Data!AJ25,Data!AL25,Data!AN25,Data!AP25,Data!AR25,Data!AT25) -> 0 | J24: =SUM(Data!DJ25,Data!DL25,Data!DN25,Data!DP25,Data!DR25,Data!DT25,Data!DV25,Data!DX25,Data!DZ25,Data!EB25,Data!ED25,Data!EF25,Data!EH25,Data!EJ25,Data!EL25,Data!EN25,Data!EP25,Data!ER25,Data!ET25) -> 0 | K24: =J24-I24 -> 0 | L24: =IF(I24=0,IF(J24>0,"New",0),(J24-I24)/I24) -> 0 | M24: =IF(F24=0,"No 2026 Sales",IF(E24=0,"New Product",IF(AND(ISNUMBER(H24),H24>0.1),"↑ Strong Growth",IF(AND(ISNUMBER(H24),H24>0),"↗ Growth",IF(AND(ISNUMBER(H24),H24<-0.1),"↓ Strong Decline",IF(AND(ISNUMBER(H24),H24<0),"↘ Decline","→ Stable")))))) -> No 2026 Sales
A25: =Data!A26 -> 201 | B25: =Data!B26 -> BUTCHERY | C25: =Data!C26 -> 64130 | D25: =Data!D26 | E25: =SUM(Data!I26,Data!K26,Data!M26,Data!O26,Data!Q26,Data!S26,Data!U26,Data!W26,Data!Y26,Data!AA26,Data!AC26,Data!AE26,Data!AG26,Data!AI26,Data!AK26,Data!AM26,Data!AO26,Data!AQ26,Data!AS26) -> 0 | F25: =SUM(Data!DI26,Data!DK26,Data!DM26,Data!DO26,Data!DQ26,Data!DS26,Data!DU26,Data!DW26,Data!DY26,Data!EA26,Data!EC26,Data!EE26,Data!EG26,Data!EI26,Data!EK26,Data!EM26,Data!EO26,Data!EQ26,Data!ES26) -> 0 | G25: =F25-E25 -> 0 | H25: =IF(E25=0,IF(F25>0,"New",0),(F25-E25)/E25) -> 0 | I25: =SUM(Data!J26,Data!L26,Data!N26,Data!P26,Data!R26,Data!T26,Data!V26,Data!X26,Data!Z26,Data!AB26,Data!AD26,Data!AF26,Data!AH26,Data!AJ26,Data!AL26,Data!AN26,Data!AP26,Data!AR26,Data!AT26) -> 0 | J25: =SUM(Data!DJ26,Data!DL26,Data!DN26,Data!DP26,Data!DR26,Data!DT26,Data!DV26,Data!DX26,Data!DZ26,Data!EB26,Data!ED26,Data!EF26,Data!EH26,Data!EJ26,Data!EL26,Data!EN26,Data!EP26,Data!ER26,Data!ET26) -> 0 | K25: =J25-I25 -> 0 | L25: =IF(I25=0,IF(J25>0,"New",0),(J25-I25)/I25) -> 0 | M25: =IF(F25=0,"No 2026 Sales",IF(E25=0,"New Product",IF(AND(ISNUMBER(H25),H25>0.1),"↑ Strong Growth",IF(AND(ISNUMBER(H25),H25>0),"↗ Growth",IF(AND(ISNUMBER(H25),H25<-0.1),"↓ Strong Decline",IF(AND(ISNUMBER(H25),H25<0),"↘ Decline","→ Stable")))))) -> No 2026 Sales | O25: Top 10 Growing Products (by Sales)
A26: =Data!A27 -> 201 | B26: =Data!B27 -> BUTCHERY | C26: =Data!C27 -> 64131 | D26: =Data!D27 | E26: =SUM(Data!I27,Data!K27,Data!M27,Data!O27,Data!Q27,Data!S27,Data!U27,Data!W27,Data!Y27,Data!AA27,Data!AC27,Data!AE27,Data!AG27,Data!AI27,Data!AK27,Data!AM27,Data!AO27,Data!AQ27,Data!AS27) -> 0 | F26: =SUM(Data!DI27,Data!DK27,Data!DM27,Data!DO27,Data!DQ27,Data!DS27,Data!DU27,Data!DW27,Data!DY27,Data!EA27,Data!EC27,Data!EE27,Data!EG27,Data!EI27,Data!EK27,Data!EM27,Data!EO27,Data!EQ27,Data!ES27) -> 0 | G26: =F26-E26 -> 0 | H26: =IF(E26=0,IF(F26>0,"New",0),(F26-E26)/E26) -> 0 | I26: =SUM(Data!J27,Data!L27,Data!N27,Data!P27,Data!R27,Data!T27,Data!V27,Data!X27,Data!Z27,Data!AB27,Data!AD27,Data!AF27,Data!AH27,Data!AJ27,Data!AL27,Data!AN27,Data!AP27,Data!AR27,Data!AT27) -> 0 | J26: =SUM(Data!DJ27,Data!DL27,Data!DN27,Data!DP27,Data!DR27,Data!DT27,Data!DV27,Data!DX27,Data!DZ27,Data!EB27,Data!ED27,Data!EF27,Data!EH27,Data!EJ27,Data!EL27,Data!EN27,Data!EP27,Data!ER27,Data!ET27) -> 0 | K26: =J26-I26 -> 0 | L26: =IF(I26=0,IF(J26>0,"New",0),(J26-I26)/I26) -> 0 | M26: =IF(F26=0,"No 2026 Sales",IF(E26=0,"New Product",IF(AND(ISNUMBER(H26),H26>0.1),"↑ Strong Growth",IF(AND(ISNUMBER(H26),H26>0),"↗ Growth",IF(AND(ISNUMBER(H26),H26<-0.1),"↓ Strong Decline",IF(AND(ISNUMBER(H26),H26<0),"↘ Decline","→ Stable")))))) -> No 2026 Sales | O26: Product | P26: 2025 Sales | Q26: 2026 Sales | R26: % Change
A27: =Data!A28 -> 201 | B27: =Data!B28 -> BUTCHERY | C27: =Data!C28 -> 64132 | D27: =Data!D28 | E27: =SUM(Data!I28,Data!K28,Data!M28,Data!O28,Data!Q28,Data!S28,Data!U28,Data!W28,Data!Y28,Data!AA28,Data!AC28,Data!AE28,Data!AG28,Data!AI28,Data!AK28,Data!AM28,Data!AO28,Data!AQ28,Data!AS28) -> 0 | F27: =SUM(Data!DI28,Data!DK28,Data!DM28,Data!DO28,Data!DQ28,Data!DS28,Data!DU28,Data!DW28,Data!DY28,Data!EA28,Data!EC28,Data!EE28,Data!EG28,Data!EI28,Data!EK28,Data!EM28,Data!EO28,Data!EQ28,Data!ES28) -> 0 | G27: =F27-E27 -> 0 | H27: =IF(E27=0,IF(F27>0,"New",0),(F27-E27)/E27) -> 0 | I27: =SUM(Data!J28,Data!L28,Data!N28,Data!P28,Data!R28,Data!T28,Data!V28,Data!X28,Data!Z28,Data!AB28,Data!AD28,Data!AF28,Data!AH28,Data!AJ28,Data!AL28,Data!AN28,Data!AP28,Data!AR28,Data!AT28) -> 0 | J27: =SUM(Data!DJ28,Data!DL28,Data!DN28,Data!DP28,Data!DR28,Data!DT28,Data!DV28,Data!DX28,Data!DZ28,Data!EB28,Data!ED28,Data!EF28,Data!EH28,Data!EJ28,Data!EL28,Data!EN28,Data!EP28,Data!ER28,Data!ET28) -> 0 | K27: =J27-I27 -> 0 | L27: =IF(I27=0,IF(J27>0,"New",0),(J27-I27)/I27) -> 0 | M27: =IF(F27=0,"No 2026 Sales",IF(E27=0,"New Product",IF(AND(ISNUMBER(H27),H27>0.1),"↑ Strong Growth",IF(AND(ISNUMBER(H27),H27>0),"↗ Growth",IF(AND(ISNUMBER(H27),H27<-0.1),"↓ Strong Decline",IF(AND(ISNUMBER(H27),H27<0),"↘ Decline","→ Stable")))))) -> No 2026 Sales | O27: BULK OPPIE-KOPPIE B/WORS | P27: 2953.1043 | Q27: 21912.748 | R27: 6.4202416
